Workbook

Sheet Sheet1
A1: MALE | J1: 1 | Q1: 2 | X1: 3 | AE1: 4
B2: N= | C2: 5262 | D2: 4628
B3: N= | C3: -1503.1838 | D3: -3860.5439 | J3: 4 | K3: 5 | L3: 6 | M3: 7 | N3: 8 | O3: 9 | Q3: 4 | R3: 5 | S3: 6 | T3: 7 | U3: 8 | V3: 9 | X3: 4 | Y3: 5 | Z3: 6 | AA3: 7 | AB3: 8 | AC3: 9 | AE3: 4 | AF3: 5 | AG3: 6 | AH3: 7 | AI3: 8 | AJ3: 9
C4: b | D4: se | E4: z | F4: pvalue
A5: trans1 | B5: sibs | C5: -0.17657367 | D5: 0.026606147 | E5: -6.6365742 | F5: 3.2105731e-11 | I5: 兄弟数 | J5: 2 | K5: 2 | L5: 2 | M5: 2 | N5: 2 | O5: 2 | Q5: 2 | R5: 2 | S5: 2 | T5: 2 | U5: 2 | V5: 2 | X5: 2 | Y5: 2 | Z5: 2 | AA5: 2 | AB5: 2 | AC5: 2 | AE5: 2 | AF5: 2 | AG5: 2 | AH5: 2 | AI5: 2 | AJ5: 2
A6: trans1 | B6: 1b.mutate_edu | C6: 0 | I6: 父中卒ref | J6: 0 | K6: 0 | L6: 0 | M6: 0 | N6: 0 | O6: 0 | Q6: 0 | R6: 0 | S6: 0 | T6: 0 | U6: 0 | V6: 0 | X6: 0 | Y6: 0 | Z6: 0 | AA6: 0 | AB6: 0 | AC6: 0 | AE6: 0 | AF6: 0 | AG6: 0 | AH6: 0 | AI6: 0 | AJ6: 0
A7: trans1 | B7: 2.mutate_edu | C7: 1.0209467 | D7: 0.13916434 | E7: 7.3362667 | F7: 2.1963411e-13 | I7: 父高卒 | J7: 0 | K7: 0 | L7: 0 | M7: 0 | N7: 0 | O7: 0 | Q7: 0 | R7: 0 | S7: 0 | T7: 0 | U7: 0 | V7: 0 | X7: 0 | Y7: 0 | Z7: 0 | AA7: 0 | AB7: 0 | AC7: 0 | AE7: 0 | AF7: 0 | AG7: 0 | AH7: 0 | AI7: 0 | AJ7: 0
A8: trans1 | B8: 3.mutate_edu | C8: 1.4487814 | D8: 0.26082107 | E8: 5.5546948 | F8: 2.7809719e-08 | I8: 父大卒 | J8: 1 | K8: 1 | L8: 1 | M8: 1 | N8: 1 | O8: 1 | Q8: 1 | R8: 1 | S8: 1 | T8: 1 | U8: 1 | V8: 1 | X8: 1 | Y8: 1 | Z8: 1 | AA8: 1 | AB8: 1 | AC8: 1 | AE8: 1 | AF8: 1 | AG8: 1 | AH8: 1 | AI8: 1 | AJ8: 1
A9: trans1 | B9: 4b.pcoh5 | C9: 0 | I9: 世代40s ref | J9: {=_xlfn.MUNIT(5)} -> 1 | K9: 0 | L9: 0 | M9: 0 | N9: 0 | Q9: {=_xlfn.MUNIT(5)} -> 1 | R9: 0 | S9: 0 | T9: 0 | U9: 0 | X9: {=_xlfn.MUNIT(5)} -> 1 | Y9: 0 | Z9: 0 | AA9: 0 | AB9: 0 | AE9: {=_xlfn.MUNIT(5)} -> 1 | AF9: 0 | AG9: 0 | AH9: 0 | AI9: 0
A10: trans1 | B10: 5.pcoh5 | C10: 1.093517 | D10: 0.1371909 | E10: 7.9707693 | F10: 1.5768966e-15 | I10: 50s | J10: 0 | K10: 1 | L10: 0 | M10: 0 | N10: 0 | Q10: 0 | R10: 1 | S10: 0 | T10: 0 | U10: 0 | X10: 0 | Y10: 1 | Z10: 0 | AA10: 0 | AB10: 0 | AE10: 0 | AF10: 1 | AG10: 0 | AH10: 0 | AI10: 0
A11: trans1 | B11: 6.pcoh5 | C11: 1.7279238 | D11: 0.22292262 | E11: 7.7512265 | F11: 9.1009155e-15 | I11: 60s | J11: 0 | K11: 0 | L11: 1 | M11: 0 | N11: 0 | Q11: 0 | R11: 0 | S11: 1 | T11: 0 | U11: 0 | X11: 0 | Y11: 0 | Z11: 1 | AA11: 0 | AB11: 0 | AE11: 0 | AF11: 0 | AG11: 1 | AH11: 0 | AI11: 0
A12: trans1 | B12: 7.pcoh5 | C12: 1.414754 | D12: 0.24014323 | E12: 5.8912927 | F12: 3.8318615e-09 | I12: 70s | J12: 0 | K12: 0 | L12: 0 | M12: 1 | N12: 0 | Q12: 0 | R12: 0 | S12: 0 | T12: 1 | U12: 0 | X12: 0 | Y12: 0 | Z12: 0 | AA12: 1 | AB12: 0 | AE12: 0 | AF12: 0 | AG12: 0 | AH12: 1 | AI12: 0
A13: trans1 | B13: 8.pcoh5 | C13: 1.3928516 | D13: 0.31337064 | E13: 4.4447419 | F13: 8.7997432e-06 | I13: 80-90s | J13: 0 | K13: 0 | L13: 0 | M13: 0 | N13: 1 | O13: 1 | Q13: 0 | R13: 0 | S13: 0 | T13: 0 | U13: 1 | V13: 1 | X13: 0 | Y13: 0 | Z13: 0 | AA13: 0 | AB13: 1 | AC13: 1 | AE13: 0 | AF13: 0 | AG13: 0 | AH13: 0 | AI13: 1 | AJ13: 1
A14: trans1 | B14: o.pcoh5 | C14: 0
A15: trans1 | B15: 1.fegp4 | C15: 2.0403543 | D15: 1.2015181 | E15: 1.698147 | F15: 0.089480016 | I15: EGP I+II | J15: 1 | K15: 1 | L15: 1 | M15: 1 | N15: 1 | O15: 1 | Q15: 0 | R15: 0 | S15: 0 | T15: 0 | U15: 0 | V15: 0 | X15: 0 | Y15: 0 | Z15: 0 | AA15: 0 | AB15: 0 | AC15: 0 | AE15: 0 | AF15: 0 | AG15: 0 | AH15: 0 | AI15: 0 | AJ15: 0
A16: trans1 | B16: 2.fegp4 | C16: 0.77730875 | D16: 0.8516183 | E16: 0.91274312 | F16: 0.36137766 | I16: IIIab | J16: 0 | K16: 0 | L16: 0 | M16: 0 | N16: 0 | O16: 0 | Q16: 1 | R16: 1 | S16: 1 | T16: 1 | U16: 1 | V16: 1 | X16: 0 | Y16: 0 | Z16: 0 | AA16: 0 | AB16: 0 | AC16: 0 | AE16: 0 | AF16: 0 | AG16: 0 | AH16: 0 | AI16: 0 | AJ16: 0
A17: trans1 | B17: 3.fegp4 | C17: 0.89381078 | D17: 0.55103665 | E17: 1.6220533 | F17: 0.10479195 | I17: IVab | J17: 0 | K17: 0 | L17: 0 | M17: 0 | N17: 0 | O17: 0 | Q17: 0 | R17: 0 | S17: 0 | T17: 0 | U17: 0 | V17: 0 | X17: 1 | Y17: 1 | Z17: 1 | AA17: 1 | AB17: 1 | AC17: 1 | AE17: 0 | AF17: 0 | AG17: 0 | AH17: 0 | AI17: 0 | AJ17: 0
A18: trans1 | B18: 4b.fegp4 | C18: 0 | I18: V+VI+VIIab+IVc | J18: 0 | K18: 0 | L18: 0 | M18: 0 | N18: 0 | O18: 0 | Q18: 0 | R18: 0 | S18: 0 | T18: 0 | U18: 0 | V18: 0 | X18: 0 | Y18: 0 | Z18: 0 | AA18: 0 | AB18: 0 | AC18: 0 | AE18: 1 | AF18: 1 | AG18: 1 | AH18: 1 | AI18: 1 | AJ18: 1
A19: trans1 | B19: 5.fegp4 | C19: 0.51918745 | D19: 0.55331871 | E19: 0.93831536 | F19: 0.34808237 | I19: job+abs | J19: 0 | K19: 0 | L19: 0 | M19: 0 | N19: 0 | O19: 0 | Q19: 0 | R19: 0 | S19: 0 | T19: 0 | U19: 0 | V19: 0 | X19: 0 | Y19: 0 | Z19: 0 | AA19: 0 | AB19: 0 | AC19: 0 | AE19: 0 | AF19: 0 | AG19: 0 | AH19: 0 | AI19: 0 | AJ19: 0
A20: trans1 | B20: 1.fegp4#c.pcoh5 | C20: 0.0015010449 | D20: 0.2520353 | E20: 0.0059556931 | F20: 0.99524807 | I20: 世代× I+II | J20: =J15*J$3 -> 4 | K20: =K15*K$3 -> 5 | L20: =L15*L$3 -> 6 | M20: =M15*M$3 -> 7 | N20: =N15*N$3 -> 8 | O20: =O15*O$3 -> 9 | Q20: =Q15*Q$3 -> 0 | R20: =R15*R$3 -> 0 | S20: =S15*S$3 -> 0 | T20: =T15*T$3 -> 0 | U20: =U15*U$3 -> 0 | V20: =V15*V$3 -> 0 | X20: =X15*X$3 -> 0 | Y20: =Y15*Y$3 -> 0 | Z20: =Z15*Z$3 -> 0 | AA20: =AA15*AA$3 -> 0 | AB20: =AB15*AB$3 -> 0 | AC20: =AC15*AC$3 -> 0 | AE20: =AE15*AE$3 -> 0 | AF20: =AF15*AF$3 -> 0 | AG20: =AG15*AG$3 -> 0 | AH20: =AH15*AH$3 -> 0 | AI20: =AI15*AI$3 -> 0 | AJ20: =AJ15*AJ$3 -> 0
A21: trans1 | B21: 2.fegp4#c.pcoh5 | C21: 0.0021275155 | D21: 0.1718968 | E21: 0.012376702 | F21: 0.99012507 | I21: IIIab | J21: =J16*J$3 -> 0 | K21: =K16*K$3 -> 0 | L21: =L16*L$3 -> 0 | M21: =M16*M$3 -> 0 | N21: =N16*N$3 -> 0 | O21: =O16*O$3 -> 0 | Q21: =Q16*Q$3 -> 4 | R21: =R16*R$3 -> 5 | S21: =S16*S$3 -> 6 | T21: =T16*T$3 -> 7 | U21: =U16*U$3 -> 8 | V21: =V16*V$3 -> 9 | X21: =X16*X$3 -> 0 | Y21: =Y16*Y$3 -> 0 | Z21: =Z16*Z$3 -> 0 | AA21: =AA16*AA$3 -> 0 | AB21: =AB16*AB$3 -> 0 | AC21: =AC16*AC$3 -> 0 | AE21: =AE16*AE$3 -> 0 | AF21: =AF16*AF$3 -> 0 | AG21: =AG16*AG$3 -> 0 | AH21: =AH16*AH$3 -> 0 | AI21: =AI16*AI$3 -> 0 | AJ21: =AJ16*AJ$3 -> 0
A22: trans1 | B22: 3.fegp4#c.pcoh5 | C22: -0.079721918 | D22: 0.11689916 | E22: -0.6819717 | F22: 0.49525684 | I22: IVab | J22: =J17*J$3 -> 0 | K22: =K17*K$3 -> 0 | L22: =L17*L$3 -> 0 | M22: =M17*M$3 -> 0 | N22: =N17*N$3 -> 0 | O22: =O17*O$3 -> 0 | Q22: =Q17*Q$3 -> 0 | R22: =R17*R$3 -> 0 | S22: =S17*S$3 -> 0 | T22: =T17*T$3 -> 0 | U22: =U17*U$3 -> 0 | V22: =V17*V$3 -> 0 | X22: =X17*X$3 -> 4 | Y22: =Y17*Y$3 -> 5 | Z22: =Z17*Z$3 -> 6 | AA22: =AA17*AA$3 -> 7 | AB22: =AB17*AB$3 -> 8 | AC22: =AC17*AC$3 -> 9 | AE22: =AE17*AE$3 -> 0 | AF22: =AF17*AF$3 -> 0 | AG22: =AG17*AG$3 -> 0 | AH22: =AH17*AH$3 -> 0 | AI22: =AI17*AI$3 -> 0 | AJ22: =AJ17*AJ$3 -> 0
A23: trans1 | B23: 4b.fegp4#co.pcoh5 | C23: 0 | I23: V+VI+VIIab+IVc | J23: =J18*J$3 -> 0 | K23: =K18*K$3 -> 0 | L23: =L18*L$3 -> 0 | M23: =M18*M$3 -> 0 | N23: =N18*N$3 -> 0 | O23: =O18*O$3 -> 0 | Q23: =Q18*Q$3 -> 0 | R23: =R18*R$3 -> 0 | S23: =S18*S$3 -> 0 | T23: =T18*T$3 -> 0 | U23: =U18*U$3 -> 0 | V23: =V18*V$3 -> 0 | X23: =X18*X$3 -> 0 | Y23: =Y18*Y$3 -> 0 | Z23: =Z18*Z$3 -> 0 | AA23: =AA18*AA$3 -> 0 | AB23: =AB18*AB$3 -> 0 | AC23: =AC18*AC$3 -> 0 | AE23: =AE18*AE$3 -> 4 | AF23: =AF18*AF$3 -> 5 | AG23: =AG18*AG$3 -> 6 | AH23: =AH18*AH$3 -> 7 | AI23: =AI18*AI$3 -> 8 | AJ23: =AJ18*AJ$3 -> 9
A24: trans1 | B24: 5.fegp4#c.pcoh5 | C24: -0.18077756 | D24: 0.11559942 | E24: -1.5638276 | F24: 0.11785806 | I24: job+abs | J24: =J19*J$3 -> 0 | K24: =K19*K$3 -> 0 | L24: =L19*L$3 -> 0 | M24: =M19*M$3 -> 0 | N24: =N19*N$3 -> 0 | O24: =O19*O$3 -> 0 | Q24: =Q19*Q$3 -> 0 | R24: =R19*R$3 -> 0 | S24: =S19*S$3 -> 0 | T24: =T19*T$3 -> 0 | U24: =U19*U$3 -> 0 | V24: =V19*V$3 -> 0 | X24: =X19*X$3 -> 0 | Y24: =Y19*Y$3 -> 0 | Z24: =Z19*Z$3 -> 0 | AA24: =AA19*AA$3 -> 0 | AB24: =AB19*AB$3 -> 0 | AC24: =AC19*AC$3 -> 0 | AE24: =AE19*AE$3 -> 0 | AF24: =AF19*AF$3 -> 0 | AG24: =AG19*AG$3 -> 0 | AH24: =AH19*AH$3 -> 0 | AI24: =AI19*AI$3 -> 0 | AJ24: =AJ19*AJ$3 -> 0
A25: trans1 | B25: _cons | C25: 1.3523075 | D25: 0.14742024 | E25: 9.173147 | F25: 4.5940725e-20 | I25: 定数 | J25: 1 | K25: 1 | L25: 1 | M25: 1 | N25: 1 | O25: 1 | Q25: 1 | R25: 1 | S25: 1 | T25: 1 | U25: 1 | V25: 1 | X25: 1 | Y25: 1 | Z25: 1 | AA25: 1 | AB25: 1 | AC25: 1 | AE25: 1 | AF25: 1 | AG25: 1 | AH25: 1 | AI25: 1 | AJ25: 1
A26: Jrcol_Tech | B26: sibs | C26: -0.16612969 | D26: 0.045885341 | E26: -3.6205396 | F26: 0.0002939893 | I26: {=I$5:I$25} -> 兄弟数 | J26: {=J$5:O$25} -> 2 | K26: 2 | L26: 2 | M26: 2 | N26: 2 | O26: 2 | Q26: {=Q$5:V$25} -> 2 | R26: 2 | S26: 2 | T26: 2 | U26: 2 | V26: 2 | X26: {=X$5:AC$25} -> 2 | Y26: 2 | Z26: 2 | AA26: 2 | AB26: 2 | AC26: 2 | AE26: {=AE$5:AJ$25} -> 2 | AF26: 2 | AG26: 2 | AH26: 2 | AI26: 2 | AJ26: 2
A27: Jrcol_Tech | B27: 1b.mutate_edu | C27: 0 | I27: 父中卒ref | J27: 0 | K27: 0 | L27: 0 | M27: 0 | N27: 0 | O27: 0 | Q27: 0 | R27: 0 | S27: 0 | T27: 0 | U27: 0 | V27: 0 | X27: 0 | Y27: 0 | Z27: 0 | AA27: 0 | AB27: 0 | AC27: 0 | AE27: 0 | AF27: 0 | AG27: 0 | AH27: 0 | AI27: 0 | AJ27: 0
A28: Jrcol_Tech | B28: 2.mutate_edu | C28: 0.56594149 | D28: 0.11840064 | E28: 4.7798853 | F28: 1.7539526e-06 | I28: 父高卒 | J28: 0 | K28: 0 | L28: 0 | M28: 0 | N28: 0 | O28: 0 | Q28: 0 | R28: 0 | S28: 0 | T28: 0 | U28: 0 | V28: 0 | X28: 0 | Y28: 0 | Z28: 0 | AA28: 0 | AB28: 0 | AC28: 0 | AE28: 0 | AF28: 0 | AG28: 0 | AH28: 0 | AI28: 0 | AJ28: 0
A29: Jrcol_Tech | B29: 3.mutate_edu | C29: 0.7440434 | D29: 0.17269405 | E29: 4.3084483 | F29: 1.6440392e-05 | I29: 父大卒 | J29: 1 | K29: 1 | L29: 1 | M29: 1 | N29: 1 | O29: 1 | Q29: 1 | R29: 1 | S29: 1 | T29: 1 | U29: 1 | V29: 1 | X29: 1 | Y29: 1 | Z29: 1 | AA29: 1 | AB29: 1 | AC29: 1 | AE29: 1 | AF29: 1 | AG29: 1 | AH29: 1 | AI29: 1 | AJ29: 1
A30: Jrcol_Tech | B30: 4b.pcoh5 | C30: 0 | I30: 世代40s ref | J30: 1 | K30: 0 | L30: 0 | M30: 0 | N30: 0 | O30: 0 | Q30: 1 | R30: 0 | S30: 0 | T30: 0 | U30: 0 | V30: 0 | X30: 1 | Y30: 0 | Z30: 0 | AA30: 0 | AB30: 0 | AC30: 0 | AE30: 1 | AF30: 0 | AG30: 0 | AH30: 0 | AI30: 0 | AJ30: 0
A31: Jrcol_Tech | B31: 5.pcoh5 | C31: 0.37266023 | D31: 0.18364854 | E31: 2.0292034 | F31: 0.042437581 | I31: 50s | J31: 0 | K31: 1 | L31: 0 | M31: 0 | N31: 0 | O31: 0 | Q31: 0 | R31: 1 | S31: 0 | T31: 0 | U31: 0 | V31: 0 | X31: 0 | Y31: 1 | Z31: 0 | AA31: 0 | AB31: 0 | AC31: 0 | AE31: 0 | AF31: 1 | AG31: 0 | AH31: 0 | AI31: 0 | AJ31: 0
A32: Jrcol_Tech | B32: 6.pcoh5 | C32: 0.54588425 | D32: 0.19755832 | E32: 2.763155 | F32: 0.0057245574 | I32: 60s | J32: 0 | K32: 0 | L32: 1 | M32: 0 | N32: 0 | O32: 0 | Q32: 0 | R32: 0 | S32: 1 | T32: 0 | U32: 0 | V32: 0 | X32: 0 | Y32: 0 | Z32: 1 | AA32: 0 | AB32: 0 | AC32: 0 | AE32: 0 | AF32: 0 | AG32: 1 | AH32: 0 | AI32: 0 | AJ32: 0
A33: Jrcol_Tech | B33: 7.pcoh5 | C33: 1.0132469 | D33: 0.21654653 | E33: 4.6791185 | F33: 2.881109e-06 | I33: 70s | J33: 0 | K33: 0 | L33: 0 | M33: 1 | N33: 0 | O33: 0 | Q33: 0 | R33: 0 | S33: 0 | T33: 1 | U33: 0 | V33: 0 | X33: 0 | Y33: 0 | Z33: 0 | AA33: 1 | AB33: 0 | AC33: 0 | AE33: 0 | AF33: 0 | AG33: 0 | AH33: 1 | AI33: 0 | AJ33: 0
A34: Jrcol_Tech | B34: 8.pcoh5 | C34: 0.97928249 | D34: 0.26351671 | E34: 3.7162064 | F34: 0.00020223637 | I34: 80-90s | J34: 0 | K34: 0 | L34: 0 | M34: 0 | N34: 1 | O34: 1 | Q34: 0 | R34: 0 | S34: 0 | T34: 0 | U34: 1 | V34: 1 | X34: 0 | Y34: 0 | Z34: 0 | AA34: 0 | AB34: 1 | AC34: 1 | AE34: 0 | AF34: 0 | AG34: 0 | AH34: 0 | AI34: 1 | AJ34: 1
A35: Jrcol_Tech | B35: o.pcoh5 | C35: 0 | I35: 0 | J35: 0 | K35: 0 | L35: 0 | M35: 0 | N35: 0 | O35: 0 | Q35: 0 | R35: 0 | S35: 0 | T35: 0 | U35: 0 | V35: 0 | X35: 0 | Y35: 0 | Z35: 0 | AA35: 0 | AB35: 0 | AC35: 0 | AE35: 0 | AF35: 0 | AG35: 0 | AH35: 0 | AI35: 0 | AJ35: 0
A36: Jrcol_Tech | B36: 1.fegp4 | C36: -0.2113159 | D36: 0.71347626 | E36: -0.2961779 | F36: 0.76709422 | I36: EGP I+II | J36: 1 | K36: 1 | L36: 1 | M36: 1 | N36: 1 | O36: 1 | Q36: 0 | R36: 0 | S36: 0 | T36: 0 | U36: 0 | V36: 0 | X36: 0 | Y36: 0 | Z36: 0 | AA36: 0 | AB36: 0 | AC36: 0 | AE36: 0 | AF36: 0 | AG36: 0 | AH36: 0 | AI36: 0 | AJ36: 0
A37: Jrcol_Tech | B37: 2.fegp4 | C37: -1.4226978 | D37: 0.85600177 | E37: -1.6620268 | F37: 0.09650741 | I37: IIIab | J37: 0 | K37: 0 | L37: 0 | M37: 0 | N37: 0 | O37: 0 | Q37: 1 | R37: 1 | S37: 1 | T37: 1 | U37: 1 | V37: 1 | X37: 0 | Y37: 0 | Z37: 0 | AA37: 0 | AB37: 0 | AC37: 0 | AE37: 0 | AF37: 0 | AG37: 0 | AH37: 0 | AI37: 0 | AJ37: 0
A38: Jrcol_Tech | B38: 3.fegp4 | C38: -0.34830373 | D38: 0.61350463 | E38: -0.56772795 | F38: 0.57021971 | I38: IVab | J38: 0 | K38: 0 | L38: 0 | M38: 0 | N38: 0 | O38: 0 | Q38: 0 | R38: 0 | S38: 0 | T38: 0 | U38: 0 | V38: 0 | X38: 1 | Y38: 1 | Z38: 1 | AA38: 1 | AB38: 1 | AC38: 1 | AE38: 0 | AF38: 0 | AG38: 0 | AH38: 0 | AI38: 0 | AJ38: 0
A39: Jrcol_Tech | B39: 4b.fegp4 | C39: 0 | I39: V+VI+VIIab+IVc | J39: 0 | K39: 0 | L39: 0 | M39: 0 | N39: 0 | O39: 0 | Q39: 0 | R39: 0 | S39: 0 | T39: 0 | U39: 0 | V39: 0 | X39: 0 | Y39: 0 | Z39: 0 | AA39: 0 | AB39: 0 | AC39: 0 | AE39: 1 | AF39: 1 | AG39: 1 | AH39: 1 | AI39: 1 | AJ39: 1
A40: Jrcol_Tech | B40: 5.fegp4 | C40: -1.0735331 | D40: 0.86308419 | E40: -1.2438336 | F40: 0.21356081 | I40: job+abs | J40: 0 | K40: 0 | L40: 0 | M40: 0 | N40: 0 | O40: 0 | Q40: 0 | R40: 0 | S40: 0 | T40: 0 | U40: 0 | V40: 0 | X40: 0 | Y40: 0 | Z40: 0 | AA40: 0 | AB40: 0 | AC40: 0 | AE40: 0 | AF40: 0 | AG40: 0 | AH40: 0 | AI40: 0 | AJ40: 0
...

Sheet table
J2: Sequential Logit regression (Viri)
K3: T1(high school) | O3: T2(Jr./Tech collage) | S3: T3(4-year collage/University)
K4: coef. | L4: s.e. | O4: coef. | P4: s.e. | S4: coef. | T4: s.e.
D5: {=Sheet1!I5:I25} -> 兄弟数 | E5: {=_xlfn.CHOOSECOLS(Sheet1!C5:F67,1,2,4)} -> -0.17657367 | F5: 0.026606147 | G5: 3.2105731e-11 | H5: {=_xlfn.IFS(G5:G67=0,"",G5:G67<0.01,"**",G5:G67<0.05,"*",G5:G67<0.1,"†",G5:G67>=0.1,"")} -> ** | J5: sibs | K5: {=E5:F25} -> -0.17657367 | L5: 0.026606147 | M5: {=H5:H25} -> ** | O5: {=E26:F46} -> -0.16612969 | P5: 0.045885341 | Q5: {=H26:H46} -> ** | S5: {=E47:F67} -> -0.21835343 | T5: 0.029855602 | U5: {=H47:H67} -> **
D6: 父中卒ref | E6: 0 | F6: 0 | G6: 0 | J6: father's educ (ref. compulsory) | K6: 0 | L6: 0 | O6: 0 | P6: 0 | S6: 0 | T6: 0
D7: 父高卒 | E7: 1.0209467 | F7: 0.13916434 | G7: 2.1963411e-13 | H7: ** | J7: Jr.high | K7: 1.0209467 | L7: 0.13916434 | M7: ** | O7: 0.56594149 | P7: 0.11840064 | Q7: ** | S7: 0.65960381 | T7: 0.085628791 | U7: **
D8: 父大卒 | E8: 1.4487814 | F8: 0.26082107 | G8: 2.7809719e-08 | H8: ** | J8: Tertially | K8: 1.4487814 | L8: 0.26082107 | M8: ** | O8: 0.7440434 | P8: 0.17269405 | Q8: ** | S8: 1.6218877 | T8: 0.11722198 | U8: **
D9: 世代40s ref | E9: 0 | F9: 0 | G9: 0 | J9: Birth cohort (ref. 1940s) | K9: 0 | L9: 0 | O9: 0 | P9: 0 | S9: 0 | T9: 0
D10: 50s | E10: 1.093517 | F10: 0.1371909 | G10: 1.5768966e-15 | H10: ** | J10: 1950s | K10: 1.093517 | L10: 0.1371909 | M10: ** | O10: 0.37266023 | P10: 0.18364854 | Q10: * | S10: 0.42517031 | T10: 0.11613569 | U10: **
D11: 60s | E11: 1.7279238 | F11: 0.22292262 | G11: 9.1009155e-15 | H11: ** | J11: 1960s | K11: 1.7279238 | L11: 0.22292262 | M11: ** | O11: 0.54588425 | P11: 0.19755832 | Q11: ** | S11: 0.14424888 | T11: 0.14094054
D12: 70s | E12: 1.414754 | F12: 0.24014323 | G12: 3.8318615e-09 | H12: ** | J12: 1970s | K12: 1.414754 | L12: 0.24014323 | M12: ** | O12: 1.0132469 | P12: 0.21654653 | Q12: ** | S12: 0.12454658 | T12: 0.1689726
D13: 80-90s | E13: 1.3928516 | F13: 0.31337064 | G13: 8.7997432e-06 | H13: ** | J13: 1980s~ | K13: 1.3928516 | L13: 0.31337064 | M13: ** | O13: 0.97928249 | P13: 0.26351671 | Q13: ** | S13: 0.54162193 | T13: 0.20363104 | U13: **
D14: 0 | E14: 0 | F14: 0 | G14: 0 | K14: 0 | L14: 0 | O14: 0 | P14: 0 | S14: 0 | T14: 0
D15: EGP I+II | E15: 2.0403543 | F15: 1.2015181 | G15: 0.089480016 | H15: † | J15: Father's EGP I+II | K15: 2.0403543 | L15: 1.2015181 | M15: † | O15: -0.2113159 | P15: 0.71347626 | S15: 2.2740228 | T15: 0.4385975 | U15: **
D16: IIIab | E16: 0.77730875 | F16: 0.8516183 | G16: 0.36137766 | J16: IIIab | K16: 0.77730875 | L16: 0.8516183 | O16: -1.4226978 | P16: 0.85600177 | Q16: † | S16: 1.2566698 | T16: 0.50893937 | U16: *
D17: IVab | E17: 0.89381078 | F17: 0.55103665 | G17: 0.10479195 | J17: Ivab | K17: 0.89381078 | L17: 0.55103665 | O17: -0.34830373 | P17: 0.61350463 | S17: 1.9474305 | T17: 0.41242541 | U17: **
D18: V+VI+VIIab+IVc | E18: 0 | F18: 0 | G18: 0 | J18: V+VI+VIIab (ref.) | K18: 0 | L18: 0 | O18: 0 | P18: 0 | S18: 0 | T18: 0
D19: job+abs | E19: 0.51918745 | F19: 0.55331871 | G19: 0.34808237 | J19: nojob,abs | K19: 0.51918745 | L19: 0.55331871 | O19: -1.0735331 | P19: 0.86308419 | S19: 0.22585526 | T19: 0.53795616
D20: 世代× I+II | E20: 0.0015010449 | F20: 0.2520353 | G20: 0.99524807 | J20: cohort * I+II | K20: 0.0015010449 | L20: 0.2520353 | O20: 0.11023919 | P20: 0.1137197 | S20: -0.10221947 | T20: 0.075579931
D21: IIIab | E21: 0.0021275155 | F21: 0.1718968 | G21: 0.99012507 | J21: cohort * IIIab | K21: 0.0021275155 | L21: 0.1718968 | O21: 0.28357109 | P21: 0.1307719 | Q21: * | S21: -0.041039885 | T21: 0.085381942
D22: IVab | E22: -0.079721918 | F22: 0.11689916 | G22: 0.49525684 | J22: cohort *Ivab | K22: -0.079721918 | L22: 0.11689916 | O22: 0.083826232 | P22: 0.098736615 | S22: -0.24176994 | T22: 0.072342891 | U22: **
D23: V+VI+VIIab+IVc | E23: 0 | F23: 0 | G23: 0 | J23: cohort *V+VI+VIIab (ref.) | K23: 0 | L23: 0 | O23: 0 | P23: 0 | S23: 0 | T23: 0
D24: job+abs | E24: -0.18077756 | F24: 0.11559942 | G24: 0.11785806 | J24: cohort* nojob,abs | K24: -0.18077756 | L24: 0.11559942 | O24: 0.12887377 | P24: 0.13919432 | S24: -0.013008357 | T24: 0.094562283
D25: 定数 | E25: 1.3523075 | F25: 0.14742024 | G25: 4.5940725e-20 | H25: ** | J25: _cons | K25: 1.3523075 | L25: 0.14742024 | M25: ** | O25: -1.841533 | P25: 0.24283121 | Q25: ** | S25: -0.8990675 | T25: 0.16178035 | U25: **
D26: {=Sheet1!I26:I46} -> 兄弟数 | E26: -0.16612969 | F26: 0.045885341 | G26: 0.0002939893 | H26: ** | J26: N of First Transition | L26: =Sheet1!C2 -> 5262
D27: 父中卒ref | E27: 0 | F27: 0 | G27: 0 | J27: N of Second Transition | L27: =Sheet1!D2 -> 4628
D28: 父高卒 | E28: 0.56594149 | F28: 0.11840064 | G28: 1.7539526e-06 | H28: ** | J28: Log-likelihood | L28: =Sheet1!C3+Sheet1!D3 -> -5363.7277
D29: 父大卒 | E29: 0.7440434 | F29: 0.17269405 | G29: 1.6440392e-05 | H29: ** | J29: BIC | L29: =L28*-2+LN(L27+L26) -> 10736.655
D30: 世代40s ref | E30: 0 | F30: 0 | G30: 0
D31: 50s | E31: 0.37266023 | F31: 0.18364854 | G31: 0.042437581 | H31: *
D32: 60s | E32: 0.54588425 | F32: 0.19755832 | G32: 0.0057245574 | H32: **
D33: 70s | E33: 1.0132469 | F33: 0.21654653 | G33: 2.881109e-06 | H33: **
D34: 80-90s | E34: 0.97928249 | F34: 0.26351671 | G34: 0.00020223637 | H34: **
D35: 0 | E35: 0 | F35: 0 | G35: 0
D36: EGP I+II | E36: -0.2113159 | F36: 0.71347626 | G36: 0.76709422
D37: IIIab | E37: -1.4226978 | F37: 0.85600177 | G37: 0.09650741 | H37: †
D38: IVab | E38: -0.34830373 | F38: 0.61350463 | G38: 0.57021971
D39: V+VI+VIIab+IVc | E39: 0 | F39: 0 | G39: 0
D40: job+abs | E40: -1.0735331 | F40: 0.86308419 | G40: 0.21356081
D41: 世代× I+II | E41: 0.11023919 | F41: 0.1137197 | G41: 0.3323487
...

Sheet decomp
G1: =_xlfn.TEXTJOIN("",TRUE,G3:G4) -> I+II1950s | H1: =_xlfn.TEXTJOIN("",TRUE,H3:H4) -> IIIab1950s | I1: =_xlfn.TEXTJOIN("",TRUE,I3:I4) -> IVab1950s | J1: =_xlfn.TEXTJOIN("",TRUE,J3:J4) -> V+VI+VIIab1950s | K1: =_xlfn.TEXTJOIN("",TRUE,K3:K4) | L1: =_xlfn.TEXTJOIN("",TRUE,L3:L4) -> I+II1960s | M1: =_xlfn.TEXTJOIN("",TRUE,M3:M4) -> IIIab1960s | N1: =_xlfn.TEXTJOIN("",TRUE,N3:N4) -> IVab1960s | ... Y1: =_xlfn.TEXTJOIN("",TRUE,Y3:Y4) -> V+VI+VIIab1980s
G3: I+II | H3: IIIab | I3: IVab | J3: V+VI+VIIab | L3: I+II | M3: IIIab | N3: IVab | O3: V+VI+VIIab | Q3: I+II | R3: IIIab | S3: IVab | T3: V+VI+VIIab | V3: I+II | W3: IIIab | X3: IVab | Y3: V+VI+VIIab
G4: 1950s | H4: 1950s | I4: 1950s | J4: 1950s | L4: 1960s | M4: 1960s | N4: 1960s | O4: 1960s | Q4: 1970s | R4: 1970s | S4: 1970s | T4: 1970s | V4: 1980s | W4: 1980s | X4: 1980s | Y4: 1980s
E8: Men | G8: 1950s | L8: 1960s | Q8: 1970s | V8: 1980s
G9: I+II | H9: IIIab | I9: IVab | J9: V+VI+VIIab | L9: I+II | M9: IIIab | N9: IVab | O9: V+VI+VIIab | Q9: I+II | R9: IIIab | S9: IVab | T9: V+VI+VIIab | V9: I+II | W9: IIIab | X9: IVab | Y9: V+VI+VIIab
A10: =_xlfn.TEXTJOIN("",TRUE,B10:C10) -> T1lambda | B10: T1 | C10: lambda | E10: T1 | F10: coefficient | G10: =INDEX(Sheet1!$E$69:$AJ$150,MATCH($A10,Sheet1!$E$69:$E$150,0),MATCH(G$1,Sheet1!$E$69:$AJ$69,0)) -> 2.0478596 | H10: =INDEX(Sheet1!$E$69:$AJ$150,MATCH($A10,Sheet1!$E$69:$E$150,0),MATCH(H$1,Sheet1!$E$69:$AJ$69,0)) -> 0.78794632 | I10: =INDEX(Sheet1!$E$69:$AJ$150,MATCH($A10,Sheet1!$E$69:$E$150,0),MATCH(I$1,Sheet1!$E$69:$AJ$69,0)) -> 0.49520119 | J10: =INDEX(Sheet1!$E$69:$AJ$150,MATCH($A10,Sheet1!$E$69:$E$150,0),MATCH(J$1,Sheet1!$E$69:$AJ$69,0)) -> 0 | L10: =INDEX(Sheet1!$E$69:$AJ$150,MATCH($A10,Sheet1!$E$69:$E$150,0),MATCH(L$1,Sheet1!$E$69:$AJ$69,0)) -> 2.0493606 | M10: =INDEX(Sheet1!$E$69:$AJ$150,MATCH($A10,Sheet1!$E$69:$E$150,0),MATCH(M$1,Sheet1!$E$69:$AJ$69,0)) -> 0.79007384 | N10: =INDEX(Sheet1!$E$69:$AJ$150,MATCH($A10,Sheet1!$E$69:$E$150,0),MATCH(N$1,Sheet1!$E$69:$AJ$69,0)) -> 0.41547928 | O10: =INDEX(Sheet1!$E$69:$AJ$150,MATCH($A10,Sheet1!$E$69:$E$150,0),MATCH(O$1,Sheet1!$E$69:$AJ$69,0)) -> 0 | Q10: =INDEX(Sheet1!$E$69:$AJ$150,MATCH($A10,Sheet1!$E$69:$E$150,0),MATCH(Q$1,Sheet1!$E$69:$AJ$69,0)) -> 2.0508617 | R10: =INDEX(Sheet1!$E$69:$AJ$150,MATCH($A10,Sheet1!$E$69:$E$150,0),MATCH(R$1,Sheet1!$E$69:$AJ$69,0)) -> 0.79220135 | S10: =INDEX(Sheet1!$E$69:$AJ$150,MATCH($A10,Sheet1!$E$69:$E$150,0),MATCH(S$1,Sheet1!$E$69:$AJ$69,0)) -> 0.33575736 | T10: =INDEX(Sheet1!$E$69:$AJ$150,MATCH($A10,Sheet1!$E$69:$E$150,0),MATCH(T$1,Sheet1!$E$69:$AJ$69,0)) -> 0 | V10: =INDEX(Sheet1!$E$69:$AJ$150,MATCH($A10,Sheet1!$E$69:$E$150,0),MATCH(V$1,Sheet1!$E$69:$AJ$69,0)) -> 2.0523627 | W10: =INDEX(Sheet1!$E$69:$AJ$150,MATCH($A10,Sheet1!$E$69:$E$150,0),MATCH(W$1,Sheet1!$E$69:$AJ$69,0)) -> 0.79432887 | X10: =INDEX(Sheet1!$E$69:$AJ$150,MATCH($A10,Sheet1!$E$69:$E$150,0),MATCH(X$1,Sheet1!$E$69:$AJ$69,0)) -> 0.25603544 | Y10: =INDEX(Sheet1!$E$69:$AJ$150,MATCH($A10,Sheet1!$E$69:$E$150,0),MATCH(Y$1,Sheet1!$E$69:$AJ$69,0)) -> 0
A11: =_xlfn.TEXTJOIN("",TRUE,B11:C11) -> T1e^lambda-1 | B11: T1 | C11: e^lambda-1 | F11: Effect | G11: =INDEX(Sheet1!$E$69:$AJ$150,MATCH($A11,Sheet1!$E$69:$E$150,0),MATCH(G$1,Sheet1!$E$69:$AJ$69,0)) -> 6.7512922 | H11: =INDEX(Sheet1!$E$69:$AJ$150,MATCH($A11,Sheet1!$E$69:$E$150,0),MATCH(H$1,Sheet1!$E$69:$AJ$69,0)) -> 1.198876 | I11: =INDEX(Sheet1!$E$69:$AJ$150,MATCH($A11,Sheet1!$E$69:$E$150,0),MATCH(I$1,Sheet1!$E$69:$AJ$69,0)) -> 0.64082833 | J11: =INDEX(Sheet1!$E$69:$AJ$150,MATCH($A11,Sheet1!$E$69:$E$150,0),MATCH(J$1,Sheet1!$E$69:$AJ$69,0)) -> 0 | L11: =INDEX(Sheet1!$E$69:$AJ$150,MATCH($A11,Sheet1!$E$69:$E$150,0),MATCH(L$1,Sheet1!$E$69:$AJ$69,0)) -> 6.7629359 | M11: =INDEX(Sheet1!$E$69:$AJ$150,MATCH($A11,Sheet1!$E$69:$E$150,0),MATCH(M$1,Sheet1!$E$69:$AJ$69,0)) -> 1.2035591 | N11: =INDEX(Sheet1!$E$69:$AJ$150,MATCH($A11,Sheet1!$E$69:$E$150,0),MATCH(N$1,Sheet1!$E$69:$AJ$69,0)) -> 0.51509672 | O11: =INDEX(Sheet1!$E$69:$AJ$150,MATCH($A11,Sheet1!$E$69:$E$150,0),MATCH(O$1,Sheet1!$E$69:$AJ$69,0)) -> 0 | Q11: =INDEX(Sheet1!$E$69:$AJ$150,MATCH($A11,Sheet1!$E$69:$E$150,0),MATCH(Q$1,Sheet1!$E$69:$AJ$69,0)) -> 6.7745972 | R11: =INDEX(Sheet1!$E$69:$AJ$150,MATCH($A11,Sheet1!$E$69:$E$150,0),MATCH(R$1,Sheet1!$E$69:$AJ$69,0)) -> 1.2082522 | S11: =INDEX(Sheet1!$E$69:$AJ$150,MATCH($A11,Sheet1!$E$69:$E$150,0),MATCH(S$1,Sheet1!$E$69:$AJ$69,0)) -> 0.39899953 | T11: =INDEX(Sheet1!$E$69:$AJ$150,MATCH($A11,Sheet1!$E$69:$E$150,0),MATCH(T$1,Sheet1!$E$69:$AJ$69,0)) -> 0 | V11: =INDEX(Sheet1!$E$69:$AJ$150,MATCH($A11,Sheet1!$E$69:$E$150,0),MATCH(V$1,Sheet1!$E$69:$AJ$69,0)) -> 6.786276 | W11: =INDEX(Sheet1!$E$69:$AJ$150,MATCH($A11,Sheet1!$E$69:$E$150,0),MATCH(W$1,Sheet1!$E$69:$AJ$69,0)) -> 1.2129553 | X11: =INDEX(Sheet1!$E$69:$AJ$150,MATCH($A11,Sheet1!$E$69:$E$150,0),MATCH(X$1,Sheet1!$E$69:$AJ$69,0)) -> 0.29179851 | Y11: =INDEX(Sheet1!$E$69:$AJ$150,MATCH($A11,Sheet1!$E$69:$E$150,0),MATCH(Y$1,Sheet1!$E$69:$AJ$69,0)) -> 0
A12: =_xlfn.TEXTJOIN("",TRUE,B12:C12) -> T1R | B12: T1 | C12: R | F12: At Risk | G12: =INDEX(Sheet1!$E$69:$AJ$150,MATCH($A12,Sheet1!$E$69:$E$150,0),MATCH(G$1,Sheet1!$E$69:$AJ$69,0)) -> 1 | H12: =INDEX(Sheet1!$E$69:$AJ$150,MATCH($A12,Sheet1!$E$69:$E$150,0),MATCH(H$1,Sheet1!$E$69:$AJ$69,0)) -> 1 | I12: =INDEX(Sheet1!$E$69:$AJ$150,MATCH($A12,Sheet1!$E$69:$E$150,0),MATCH(I$1,Sheet1!$E$69:$AJ$69,0)) -> 1 | J12: =INDEX(Sheet1!$E$69:$AJ$150,MATCH($A12,Sheet1!$E$69:$E$150,0),MATCH(J$1,Sheet1!$E$69:$AJ$69,0)) -> 1 | L12: =INDEX(Sheet1!$E$69:$AJ$150,MATCH($A12,Sheet1!$E$69:$E$150,0),MATCH(L$1,Sheet1!$E$69:$AJ$69,0)) -> 1 | M12: =INDEX(Sheet1!$E$69:$AJ$150,MATCH($A12,Sheet1!$E$69:$E$150,0),MATCH(M$1,Sheet1!$E$69:$AJ$69,0)) -> 1 | N12: =INDEX(Sheet1!$E$69:$AJ$150,MATCH($A12,Sheet1!$E$69:$E$150,0),MATCH(N$1,Sheet1!$E$69:$AJ$69,0)) -> 1 | O12: =INDEX(Sheet1!$E$69:$AJ$150,MATCH($A12,Sheet1!$E$69:$E$150,0),MATCH(O$1,Sheet1!$E$69:$AJ$69,0)) -> 1 | Q12: =INDEX(Sheet1!$E$69:$AJ$150,MATCH($A12,Sheet1!$E$69:$E$150,0),MATCH(Q$1,Sheet1!$E$69:$AJ$69,0)) -> 1 | R12: =INDEX(Sheet1!$E$69:$AJ$150,MATCH($A12,Sheet1!$E$69:$E$150,0),MATCH(R$1,Sheet1!$E$69:$AJ$69,0)) -> 1 | S12: =INDEX(Sheet1!$E$69:$AJ$150,MATCH($A12,Sheet1!$E$69:$E$150,0),MATCH(S$1,Sheet1!$E$69:$AJ$69,0)) -> 1 | T12: =INDEX(Sheet1!$E$69:$AJ$150,MATCH($A12,Sheet1!$E$69:$E$150,0),MATCH(T$1,Sheet1!$E$69:$AJ$69,0)) -> 1 | V12: =INDEX(Sheet1!$E$69:$AJ$150,MATCH($A12,Sheet1!$E$69:$E$150,0),MATCH(V$1,Sheet1!$E$69:$AJ$69,0)) -> 1 | W12: =INDEX(Sheet1!$E$69:$AJ$150,MATCH($A12,Sheet1!$E$69:$E$150,0),MATCH(W$1,Sheet1!$E$69:$AJ$69,0)) -> 1 | X12: =INDEX(Sheet1!$E$69:$AJ$150,MATCH($A12,Sheet1!$E$69:$E$150,0),MATCH(X$1,Sheet1!$E$69:$AJ$69,0)) -> 1 | Y12: =INDEX(Sheet1!$E$69:$AJ$150,MATCH($A12,Sheet1!$E$69:$E$150,0),MATCH(Y$1,Sheet1!$E$69:$AJ$69,0)) -> 1
A13: =_xlfn.TEXTJOIN("",TRUE,B13:C13) -> T1D | B13: T1 | C13: D | F13: Differenciate | G13: =INDEX(Sheet1!$E$69:$AJ$150,MATCH($A13,Sheet1!$E$69:$E$150,0),MATCH(G$1,Sheet1!$E$69:$AJ$69,0)) -> 0.003618817 | H13: =INDEX(Sheet1!$E$69:$AJ$150,MATCH($A13,Sheet1!$E$69:$E$150,0),MATCH(H$1,Sheet1!$E$69:$AJ$69,0)) -> 0.012637918 | I13: =INDEX(Sheet1!$E$69:$AJ$150,MATCH($A13,Sheet1!$E$69:$E$150,0),MATCH(I$1,Sheet1!$E$69:$AJ$69,0)) -> 0.016861516 | J13: =INDEX(Sheet1!$E$69:$AJ$150,MATCH($A13,Sheet1!$E$69:$E$150,0),MATCH(J$1,Sheet1!$E$69:$AJ$69,0)) -> 0.027362625 | L13: =INDEX(Sheet1!$E$69:$AJ$150,MATCH($A13,Sheet1!$E$69:$E$150,0),MATCH(L$1,Sheet1!$E$69:$AJ$69,0)) -> 0.0019450882 | M13: =INDEX(Sheet1!$E$69:$AJ$150,MATCH($A13,Sheet1!$E$69:$E$150,0),MATCH(M$1,Sheet1!$E$69:$AJ$69,0)) -> 0.0068183928 | N13: =INDEX(Sheet1!$E$69:$AJ$150,MATCH($A13,Sheet1!$E$69:$E$150,0),MATCH(N$1,Sheet1!$E$69:$AJ$69,0)) -> 0.0098855827 | O13: =INDEX(Sheet1!$E$69:$AJ$150,MATCH($A13,Sheet1!$E$69:$E$150,0),MATCH(O$1,Sheet1!$E$69:$AJ$69,0)) -> 0.014900574 | Q13: =INDEX(Sheet1!$E$69:$AJ$150,MATCH($A13,Sheet1!$E$69:$E$150,0),MATCH(Q$1,Sheet1!$E$69:$AJ$69,0)) -> 0.0026398062 | R13: =INDEX(Sheet1!$E$69:$AJ$150,MATCH($A13,Sheet1!$E$69:$E$150,0),MATCH(R$1,Sheet1!$E$69:$AJ$69,0)) -> 0.0092312529 | S13: =INDEX(Sheet1!$E$69:$AJ$150,MATCH($A13,Sheet1!$E$69:$E$150,0),MATCH(S$1,Sheet1!$E$69:$AJ$69,0)) -> 0.014492069 | T13: =INDEX(Sheet1!$E$69:$AJ$150,MATCH($A13,Sheet1!$E$69:$E$150,0),MATCH(T$1,Sheet1!$E$69:$AJ$69,0)) -> 0.020155404 | V13: =INDEX(Sheet1!$E$69:$AJ$150,MATCH($A13,Sheet1!$E$69:$E$150,0),MATCH(V$1,Sheet1!$E$69:$AJ$69,0)) -> 0.0026928381 | W13: =INDEX(Sheet1!$E$69:$AJ$150,MATCH($A13,Sheet1!$E$69:$E$150,0),MATCH(W$1,Sheet1!$E$69:$AJ$69,0)) -> 0.0094095569 | X13: =INDEX(Sheet1!$E$69:$AJ$150,MATCH($A13,Sheet1!$E$69:$E$150,0),MATCH(X$1,Sheet1!$E$69:$AJ$69,0)) -> 0.016009604 | Y13: =INDEX(Sheet1!$E$69:$AJ$150,MATCH($A13,Sheet1!$E$69:$E$150,0),MATCH(Y$1,Sheet1!$E$69:$AJ$69,0)) -> 0.020582963
A14: =_xlfn.TEXTJOIN("",TRUE,B14:C14) -> T1G | B14: T1 | C14: G | F14: Gain | G14: =INDEX(Sheet1!$E$69:$AJ$150,MATCH($A14,Sheet1!$E$69:$E$150,0),MATCH(G$1,Sheet1!$E$69:$AJ$69,0)) -> 6.1200887 | H14: =INDEX(Sheet1!$E$69:$AJ$150,MATCH($A14,Sheet1!$E$69:$E$150,0),MATCH(H$1,Sheet1!$E$69:$AJ$69,0)) -> 5.9793457 | I14: =INDEX(Sheet1!$E$69:$AJ$150,MATCH($A14,Sheet1!$E$69:$E$150,0),MATCH(I$1,Sheet1!$E$69:$AJ$69,0)) -> 5.885244 | J14: =INDEX(Sheet1!$E$69:$AJ$150,MATCH($A14,Sheet1!$E$69:$E$150,0),MATCH(J$1,Sheet1!$E$69:$AJ$69,0)) -> 5.6126374 | L14: =INDEX(Sheet1!$E$69:$AJ$150,MATCH($A14,Sheet1!$E$69:$E$150,0),MATCH(L$1,Sheet1!$E$69:$AJ$69,0)) -> 5.9104174 | M14: =INDEX(Sheet1!$E$69:$AJ$150,MATCH($A14,Sheet1!$E$69:$E$150,0),MATCH(M$1,Sheet1!$E$69:$AJ$69,0)) -> 5.7410038 | N14: =INDEX(Sheet1!$E$69:$AJ$150,MATCH($A14,Sheet1!$E$69:$E$150,0),MATCH(N$1,Sheet1!$E$69:$AJ$69,0)) -> 5.5631686 | O14: =INDEX(Sheet1!$E$69:$AJ$150,MATCH($A14,Sheet1!$E$69:$E$150,0),MATCH(O$1,Sheet1!$E$69:$AJ$69,0)) -> 5.3644967 | Q14: =INDEX(Sheet1!$E$69:$AJ$150,MATCH($A14,Sheet1!$E$69:$E$150,0),MATCH(Q$1,Sheet1!$E$69:$AJ$69,0)) -> 5.8218214 | R14: =INDEX(Sheet1!$E$69:$AJ$150,MATCH($A14,Sheet1!$E$69:$E$150,0),MATCH(R$1,Sheet1!$E$69:$AJ$69,0)) -> 5.6455082 | S14: =INDEX(Sheet1!$E$69:$AJ$150,MATCH($A14,Sheet1!$E$69:$E$150,0),MATCH(S$1,Sheet1!$E$69:$AJ$69,0)) -> 5.4103789 | T14: =INDEX(Sheet1!$E$69:$AJ$150,MATCH($A14,Sheet1!$E$69:$E$150,0),MATCH(T$1,Sheet1!$E$69:$AJ$69,0)) -> 5.3206736 | V14: =INDEX(Sheet1!$E$69:$AJ$150,MATCH($A14,Sheet1!$E$69:$E$150,0),MATCH(V$1,Sheet1!$E$69:$AJ$69,0)) -> 6.059021 | W14: =INDEX(Sheet1!$E$69:$AJ$150,MATCH($A14,Sheet1!$E$69:$E$150,0),MATCH(W$1,Sheet1!$E$69:$AJ$69,0)) -> 5.906987 | X14: =INDEX(Sheet1!$E$69:$AJ$150,MATCH($A14,Sheet1!$E$69:$E$150,0),MATCH(X$1,Sheet1!$E$69:$AJ$69,0)) -> 5.6422424 | Y14: =INDEX(Sheet1!$E$69:$AJ$150,MATCH($A14,Sheet1!$E$69:$E$150,0),MATCH(Y$1,Sheet1!$E$69:$AJ$69,0)) -> 5.6562952
A15: =_xlfn.TEXTJOIN("",TRUE,B15:C15) -> T1Weight | B15: T1 | C15: Weight | F15: Weight | G15: =INDEX(Sheet1!$E$69:$AJ$150,MATCH($A15,Sheet1!$E$69:$E$150,0),MATCH(G$1,Sheet1!$E$69:$AJ$69,0)) -> 0.022147481 | H15: =INDEX(Sheet1!$E$69:$AJ$150,MATCH($A15,Sheet1!$E$69:$E$150,0),MATCH(H$1,Sheet1!$E$69:$AJ$69,0)) -> 0.075566482 | I15: =INDEX(Sheet1!$E$69:$AJ$150,MATCH($A15,Sheet1!$E$69:$E$150,0),MATCH(I$1,Sheet1!$E$69:$AJ$69,0)) -> 0.099234136 | J15: =INDEX(Sheet1!$E$69:$AJ$150,MATCH($A15,Sheet1!$E$69:$E$150,0),MATCH(J$1,Sheet1!$E$69:$AJ$69,0)) -> 0.15357649 | L15: =INDEX(Sheet1!$E$69:$AJ$150,MATCH($A15,Sheet1!$E$69:$E$150,0),MATCH(L$1,Sheet1!$E$69:$AJ$69,0)) -> 0.011496283 | M15: =INDEX(Sheet1!$E$69:$AJ$150,MATCH($A15,Sheet1!$E$69:$E$150,0),MATCH(M$1,Sheet1!$E$69:$AJ$69,0)) -> 0.039144419 | N15: =INDEX(Sheet1!$E$69:$AJ$150,MATCH($A15,Sheet1!$E$69:$E$150,0),MATCH(N$1,Sheet1!$E$69:$AJ$69,0)) -> 0.054995163 | O15: =INDEX(Sheet1!$E$69:$AJ$150,MATCH($A15,Sheet1!$E$69:$E$150,0),MATCH(O$1,Sheet1!$E$69:$AJ$69,0)) -> 0.079934081 | Q15: =INDEX(Sheet1!$E$69:$AJ$150,MATCH($A15,Sheet1!$E$69:$E$150,0),MATCH(Q$1,Sheet1!$E$69:$AJ$69,0)) -> 0.01536848 | R15: =INDEX(Sheet1!$E$69:$AJ$150,MATCH($A15,Sheet1!$E$69:$E$150,0),MATCH(R$1,Sheet1!$E$69:$AJ$69,0)) -> 0.052115114 | S15: =INDEX(Sheet1!$E$69:$AJ$150,MATCH($A15,Sheet1!$E$69:$E$150,0),MATCH(S$1,Sheet1!$E$69:$AJ$69,0)) -> 0.078407587 | T15: =INDEX(Sheet1!$E$69:$AJ$150,MATCH($A15,Sheet1!$E$69:$E$150,0),MATCH(T$1,Sheet1!$E$69:$AJ$69,0)) -> 0.10724033 | V15: =INDEX(Sheet1!$E$69:$AJ$150,MATCH($A15,Sheet1!$E$69:$E$150,0),MATCH(V$1,Sheet1!$E$69:$AJ$69,0)) -> 0.016315963 | W15: =INDEX(Sheet1!$E$69:$AJ$150,MATCH($A15,Sheet1!$E$69:$E$150,0),MATCH(W$1,Sheet1!$E$69:$AJ$69,0)) -> 0.055582131 | X15: =INDEX(Sheet1!$E$69:$AJ$150,MATCH($A15,Sheet1!$E$69:$E$150,0),MATCH(X$1,Sheet1!$E$69:$AJ$69,0)) -> 0.090330067 | Y15: =INDEX(Sheet1!$E$69:$AJ$150,MATCH($A15,Sheet1!$E$69:$E$150,0),MATCH(Y$1,Sheet1!$E$69:$AJ$69,0)) -> 0.11642331
A16: =_xlfn.TEXTJOIN("",TRUE,B16:C16) -> T1p | B16: T1 | C16: p | F16: p | G16: =INDEX(Sheet1!$E$69:$AJ$150,MATCH($A16,Sheet1!$E$69:$E$150,0),MATCH(G$1,Sheet1!$E$69:$AJ$69,0)) -> 0.99627634 | H16: =INDEX(Sheet1!$E$69:$AJ$150,MATCH($A16,Sheet1!$E$69:$E$150,0),MATCH(H$1,Sheet1!$E$69:$AJ$69,0)) -> 0.98699595 | I16: =INDEX(Sheet1!$E$69:$AJ$150,MATCH($A16,Sheet1!$E$69:$E$150,0),MATCH(I$1,Sheet1!$E$69:$AJ$69,0)) -> 0.98264999 | J16: =INDEX(Sheet1!$E$69:$AJ$150,MATCH($A16,Sheet1!$E$69:$E$150,0),MATCH(J$1,Sheet1!$E$69:$AJ$69,0)) -> 0.97184465 | L16: =INDEX(Sheet1!$E$69:$AJ$150,MATCH($A16,Sheet1!$E$69:$E$150,0),MATCH(L$1,Sheet1!$E$69:$AJ$69,0)) -> 0.99802503 | M16: =INDEX(Sheet1!$E$69:$AJ$150,MATCH($A16,Sheet1!$E$69:$E$150,0),MATCH(M$1,Sheet1!$E$69:$AJ$69,0)) -> 0.99307686 | N16: =INDEX(Sheet1!$E$69:$AJ$150,MATCH($A16,Sheet1!$E$69:$E$150,0),MATCH(N$1,Sheet1!$E$69:$AJ$69,0)) -> 0.98996256 | O16: =INDEX(Sheet1!$E$69:$AJ$150,MATCH($A16,Sheet1!$E$69:$E$150,0),MATCH(O$1,Sheet1!$E$69:$AJ$69,0)) -> 0.98487052 | Q16: =INDEX(Sheet1!$E$69:$AJ$150,MATCH($A16,Sheet1!$E$69:$E$150,0),MATCH(Q$1,Sheet1!$E$69:$AJ$69,0)) -> 0.99730473 | R16: =INDEX(Sheet1!$E$69:$AJ$150,MATCH($A16,Sheet1!$E$69:$E$150,0),MATCH(R$1,Sheet1!$E$69:$AJ$69,0)) -> 0.99057479 | S16: =INDEX(Sheet1!$E$69:$AJ$150,MATCH($A16,Sheet1!$E$69:$E$150,0),MATCH(S$1,Sheet1!$E$69:$AJ$69,0)) -> 0.98520343 | T16: =INDEX(Sheet1!$E$69:$AJ$150,MATCH($A16,Sheet1!$E$69:$E$150,0),MATCH(T$1,Sheet1!$E$69:$AJ$69,0)) -> 0.9794211 | V16: =INDEX(Sheet1!$E$69:$AJ$150,MATCH($A16,Sheet1!$E$69:$E$150,0),MATCH(V$1,Sheet1!$E$69:$AJ$69,0)) -> 0.99724933 | W16: =INDEX(Sheet1!$E$69:$AJ$150,MATCH($A16,Sheet1!$E$69:$E$150,0),MATCH(W$1,Sheet1!$E$69:$AJ$69,0)) -> 0.99038836 | X16: =INDEX(Sheet1!$E$69:$AJ$150,MATCH($A16,Sheet1!$E$69:$E$150,0),MATCH(X$1,Sheet1!$E$69:$AJ$69,0)) -> 0.98364656 | Y16: =INDEX(Sheet1!$E$69:$AJ$150,MATCH($A16,Sheet1!$E$69:$E$150,0),MATCH(Y$1,Sheet1!$E$69:$AJ$69,0)) -> 0.97897499
A17: =_xlfn.TEXTJOIN("",TRUE,B17:C17) -> T2lambda | B17: T2 | C17: lambda | E17: T2 | F17: coefficient | G17: =INDEX(Sheet1!$E$69:$AJ$150,MATCH($A17,Sheet1!$E$69:$E$150,0),MATCH(G$1,Sheet1!$E$69:$AJ$69,0)) -> 0.33988003 | H17: =INDEX(Sheet1!$E$69:$AJ$150,MATCH($A17,Sheet1!$E$69:$E$150,0),MATCH(H$1,Sheet1!$E$69:$AJ$69,0)) -> -0.0048423869 | I17: =INDEX(Sheet1!$E$69:$AJ$150,MATCH($A17,Sheet1!$E$69:$E$150,0),MATCH(I$1,Sheet1!$E$69:$AJ$69,0)) -> 0.070827435 | J17: =INDEX(Sheet1!$E$69:$AJ$150,MATCH($A17,Sheet1!$E$69:$E$150,0),MATCH(J$1,Sheet1!$E$69:$AJ$69,0)) -> 0 | L17: =INDEX(Sheet1!$E$69:$AJ$150,MATCH($A17,Sheet1!$E$69:$E$150,0),MATCH(L$1,Sheet1!$E$69:$AJ$69,0)) -> 0.45011921 | M17: =INDEX(Sheet1!$E$69:$AJ$150,MATCH($A17,Sheet1!$E$69:$E$150,0),MATCH(M$1,Sheet1!$E$69:$AJ$69,0)) -> 0.27872871 | N17: =INDEX(Sheet1!$E$69:$AJ$150,MATCH($A17,Sheet1!$E$69:$E$150,0),MATCH(N$1,Sheet1!$E$69:$AJ$69,0)) -> 0.15465367 | O17: =INDEX(Sheet1!$E$69:$AJ$150,MATCH($A17,Sheet1!$E$69:$E$150,0),MATCH(O$1,Sheet1!$E$69:$AJ$69,0)) -> 0 | Q17: =INDEX(Sheet1!$E$69:$AJ$150,MATCH($A17,Sheet1!$E$69:$E$150,0),MATCH(Q$1,Sheet1!$E$69:$AJ$69,0)) -> 0.5603584 | R17: =INDEX(Sheet1!$E$69:$AJ$150,MATCH($A17,Sheet1!$E$69:$E$150,0),MATCH(R$1,Sheet1!$E$69:$AJ$69,0)) -> 0.5622998 | S17: =INDEX(Sheet1!$E$69:$AJ$150,MATCH($A17,Sheet1!$E$69:$E$150,0),MATCH(S$1,Sheet1!$E$69:$AJ$69,0)) -> 0.2384799 | T17: =INDEX(Sheet1!$E$69:$AJ$150,MATCH($A17,Sheet1!$E$69:$E$150,0),MATCH(T$1,Sheet1!$E$69:$AJ$69,0)) -> 0 | V17: =INDEX(Sheet1!$E$69:$AJ$150,MATCH($A17,Sheet1!$E$69:$E$150,0),MATCH(V$1,Sheet1!$E$69:$AJ$69,0)) -> 0.67059758 | W17: =INDEX(Sheet1!$E$69:$AJ$150,MATCH($A17,Sheet1!$E$69:$E$150,0),MATCH(W$1,Sheet1!$E$69:$AJ$69,0)) -> 0.84587089 | X17: =INDEX(Sheet1!$E$69:$AJ$150,MATCH($A17,Sheet1!$E$69:$E$150,0),MATCH(X$1,Sheet1!$E$69:$AJ$69,0)) -> 0.32230613 | Y17: =INDEX(Sheet1!$E$69:$AJ$150,MATCH($A17,Sheet1!$E$69:$E$150,0),MATCH(Y$1,Sheet1!$E$69:$AJ$69,0)) -> 0
A18: =_xlfn.TEXTJOIN("",TRUE,B18:C18) -> T2e^lambda-1 | B18: T2 | C18: e^lambda-1 | F18: Effect | G18: =INDEX(Sheet1!$E$69:$AJ$150,MATCH($A18,Sheet1!$E$69:$E$150,0),MATCH(G$1,Sheet1!$E$69:$AJ$69,0)) -> 0.40477904 | H18: =INDEX(Sheet1!$E$69:$AJ$150,MATCH($A18,Sheet1!$E$69:$E$150,0),MATCH(H$1,Sheet1!$E$69:$AJ$69,0)) -> -0.0048306815 | I18: =INDEX(Sheet1!$E$69:$AJ$150,MATCH($A18,Sheet1!$E$69:$E$150,0),MATCH(I$1,Sheet1!$E$69:$AJ$69,0)) -> 0.07339598 | J18: =INDEX(Sheet1!$E$69:$AJ$150,MATCH($A18,Sheet1!$E$69:$E$150,0),MATCH(J$1,Sheet1!$E$69:$AJ$69,0)) -> 0 | L18: =INDEX(Sheet1!$E$69:$AJ$150,MATCH($A18,Sheet1!$E$69:$E$150,0),MATCH(L$1,Sheet1!$E$69:$AJ$69,0)) -> 0.56849916 | M18: =INDEX(Sheet1!$E$69:$AJ$150,MATCH($A18,Sheet1!$E$69:$E$150,0),MATCH(M$1,Sheet1!$E$69:$AJ$69,0)) -> 0.32144879 | N18: =INDEX(Sheet1!$E$69:$AJ$150,MATCH($A18,Sheet1!$E$69:$E$150,0),MATCH(N$1,Sheet1!$E$69:$AJ$69,0)) -> 0.16725363 | O18: =INDEX(Sheet1!$E$69:$AJ$150,MATCH($A18,Sheet1!$E$69:$E$150,0),MATCH(O$1,Sheet1!$E$69:$AJ$69,0)) -> 0 | Q18: =INDEX(Sheet1!$E$69:$AJ$150,MATCH($A18,Sheet1!$E$69:$E$150,0),MATCH(Q$1,Sheet1!$E$69:$AJ$69,0)) -> 0.75130005 | R18: =INDEX(Sheet1!$E$69:$AJ$150,MATCH($A18,Sheet1!$E$69:$E$150,0),MATCH(R$1,Sheet1!$E$69:$AJ$69,0)) -> 0.75470333 | S18: =INDEX(Sheet1!$E$69:$AJ$150,MATCH($A18,Sheet1!$E$69:$E$150,0),MATCH(S$1,Sheet1!$E$69:$AJ$69,0)) -> 0.26931819 | T18: =INDEX(Sheet1!$E$69:$AJ$150,MATCH($A18,Sheet1!$E$69:$E$150,0),MATCH(T$1,Sheet1!$E$69:$AJ$69,0)) -> 0 | V18: =INDEX(Sheet1!$E$69:$AJ$150,MATCH($A18,Sheet1!$E$69:$E$150,0),MATCH(V$1,Sheet1!$E$69:$AJ$69,0)) -> 0.95540549 | W18: =INDEX(Sheet1!$E$69:$AJ$150,MATCH($A18,Sheet1!$E$69:$E$150,0),MATCH(W$1,Sheet1!$E$69:$AJ$69,0)) -> 1.3300061 | X18: =INDEX(Sheet1!$E$69:$AJ$150,MATCH($A18,Sheet1!$E$69:$E$150,0),MATCH(X$1,Sheet1!$E$69:$AJ$69,0)) -> 0.38030727 | Y18: =INDEX(Sheet1!$E$69:$AJ$150,MATCH($A18,Sheet1!$E$69:$E$150,0),MATCH(Y$1,Sheet1!$E$69:$AJ$69,0)) -> 0
A19: =_xlfn.TEXTJOIN("",TRUE,B19:C19) -> T2R | B19: T2 | C19: R | F19: At Risk | G19: =INDEX(Sheet1!$E$69:$AJ$150,MATCH($A19,Sheet1!$E$69:$E$150,0),MATCH(G$1,Sheet1!$E$69:$AJ$69,0)) -> 0.9840605 | H19: =INDEX(Sheet1!$E$69:$AJ$150,MATCH($A19,Sheet1!$E$69:$E$150,0),MATCH(H$1,Sheet1!$E$69:$AJ$69,0)) -> 0.9794203 | I19: =INDEX(Sheet1!$E$69:$AJ$150,MATCH($A19,Sheet1!$E$69:$E$150,0),MATCH(I$1,Sheet1!$E$69:$AJ$69,0)) -> 0.97724732 | J19: =INDEX(Sheet1!$E$69:$AJ$150,MATCH($A19,Sheet1!$E$69:$E$150,0),MATCH(J$1,Sheet1!$E$69:$AJ$69,0)) -> 0.97184465 | L19: =INDEX(Sheet1!$E$69:$AJ$150,MATCH($A19,Sheet1!$E$69:$E$150,0),MATCH(L$1,Sheet1!$E$69:$AJ$69,0)) -> 0.99144778 | M19: =INDEX(Sheet1!$E$69:$AJ$150,MATCH($A19,Sheet1!$E$69:$E$150,0),MATCH(M$1,Sheet1!$E$69:$AJ$69,0)) -> 0.98897369 | N19: =INDEX(Sheet1!$E$69:$AJ$150,MATCH($A19,Sheet1!$E$69:$E$150,0),MATCH(N$1,Sheet1!$E$69:$AJ$69,0)) -> 0.98741654 | O19: =INDEX(Sheet1!$E$69:$AJ$150,MATCH($A19,Sheet1!$E$69:$E$150,0),MATCH(O$1,Sheet1!$E$69:$AJ$69,0)) -> 0.98487052 | Q19: =INDEX(Sheet1!$E$69:$AJ$150,MATCH($A19,Sheet1!$E$69:$E$150,0),MATCH(Q$1,Sheet1!$E$69:$AJ$69,0)) -> 0.98836292 | R19: =INDEX(Sheet1!$E$69:$AJ$150,MATCH($A19,Sheet1!$E$69:$E$150,0),MATCH(R$1,Sheet1!$E$69:$AJ$69,0)) -> 0.98499795 | S19: =INDEX(Sheet1!$E$69:$AJ$150,MATCH($A19,Sheet1!$E$69:$E$150,0),MATCH(S$1,Sheet1!$E$69:$AJ$69,0)) -> 0.98231227 | T19: =INDEX(Sheet1!$E$69:$AJ$150,MATCH($A19,Sheet1!$E$69:$E$150,0),MATCH(T$1,Sheet1!$E$69:$AJ$69,0)) -> 0.9794211 | V19: =INDEX(Sheet1!$E$69:$AJ$150,MATCH($A19,Sheet1!$E$69:$E$150,0),MATCH(V$1,Sheet1!$E$69:$AJ$69,0)) -> 0.98811216 | W19: =INDEX(Sheet1!$E$69:$AJ$150,MATCH($A19,Sheet1!$E$69:$E$150,0),MATCH(W$1,Sheet1!$E$69:$AJ$69,0)) -> 0.98468167 | X19: =INDEX(Sheet1!$E$69:$AJ$150,MATCH($A19,Sheet1!$E$69:$E$150,0),MATCH(X$1,Sheet1!$E$69:$AJ$69,0)) -> 0.98131078 | Y19: =INDEX(Sheet1!$E$69:$AJ$150,MATCH($A19,Sheet1!$E$69:$E$150,0),MATCH(Y$1,Sheet1!$E$69:$AJ$69,0)) -> 0.97897499
A20: =_xlfn.TEXTJOIN("",TRUE,B20:C20) -> T2D | B20: T2 | C20: D | F20: Differenciate | G20: =INDEX(Sheet1!$E$69:$AJ$150,MATCH($A20,Sheet1!$E$69:$E$150,0),MATCH(G$1,Sheet1!$E$69:$AJ$69,0)) -> 0.098925706 | H20: =INDEX(Sheet1!$E$69:$AJ$150,MATCH($A20,Sheet1!$E$69:$E$150,0),MATCH(H$1,Sheet1!$E$69:$AJ$69,0)) -> 0.097728067 | I20: =INDEX(Sheet1!$E$69:$AJ$150,MATCH($A20,Sheet1!$E$69:$E$150,0),MATCH(I$1,Sheet1!$E$69:$AJ$69,0)) -> 0.095881573 | J20: =INDEX(Sheet1!$E$69:$AJ$150,MATCH($A20,Sheet1!$E$69:$E$150,0),MATCH(J$1,Sheet1!$E$69:$AJ$69,0)) -> 0.092134377 | L20: =INDEX(Sheet1!$E$69:$AJ$150,MATCH($A20,Sheet1!$E$69:$E$150,0),MATCH(L$1,Sheet1!$E$69:$AJ$69,0)) -> 0.13069999 | M20: =INDEX(Sheet1!$E$69:$AJ$150,MATCH($A20,Sheet1!$E$69:$E$150,0),MATCH(M$1,Sheet1!$E$69:$AJ$69,0)) -> 0.12676556 | N20: =INDEX(Sheet1!$E$69:$AJ$150,MATCH($A20,Sheet1!$E$69:$E$150,0),MATCH(N$1,Sheet1!$E$69:$AJ$69,0)) -> 0.12317339 | O20: =INDEX(Sheet1!$E$69:$AJ$150,MATCH($A20,Sheet1!$E$69:$E$150,0),MATCH(O$1,Sheet1!$E$69:$AJ$69,0)) -> 0.12041057 | Q20: =INDEX(Sheet1!$E$69:$AJ$150,MATCH($A20,Sheet1!$E$69:$E$150,0),MATCH(Q$1,Sheet1!$E$69:$AJ$69,0)) -> 0.18238776 | R20: =INDEX(Sheet1!$E$69:$AJ$150,MATCH($A20,Sheet1!$E$69:$E$150,0),MATCH(R$1,Sheet1!$E$69:$AJ$69,0)) -> 0.16890422 | S20: =INDEX(Sheet1!$E$69:$AJ$150,MATCH($A20,Sheet1!$E$69:$E$150,0),MATCH(S$1,Sheet1!$E$69:$AJ$69,0)) -> 0.16212335 | T20: =INDEX(Sheet1!$E$69:$AJ$150,MATCH($A20,Sheet1!$E$69:$E$150,0),MATCH(T$1,Sheet1!$E$69:$AJ$69,0)) -> 0.16484282 | V20: =INDEX(Sheet1!$E$69:$AJ$150,MATCH($A20,Sheet1!$E$69:$E$150,0),MATCH(V$1,Sheet1!$E$69:$AJ$69,0)) -> 0.14558358 | W20: =INDEX(Sheet1!$E$69:$AJ$150,MATCH($A20,Sheet1!$E$69:$E$150,0),MATCH(W$1,Sheet1!$E$69:$AJ$69,0)) -> 0.13322129 | X20: =INDEX(Sheet1!$E$69:$AJ$150,MATCH($A20,Sheet1!$E$69:$E$150,0),MATCH(X$1,Sheet1!$E$69:$AJ$69,0)) -> 0.12833852 | Y20: =INDEX(Sheet1!$E$69:$AJ$150,MATCH($A20,Sheet1!$E$69:$E$150,0),MATCH(Y$1,Sheet1!$E$69:$AJ$69,0)) -> 0.13599799
A21: =_xlfn.TEXTJOIN("",TRUE,B21:C21) -> T2G | B21: T2 | C21: G | F21: Gain | G21: =INDEX(Sheet1!$E$69:$AJ$150,MATCH($A21,Sheet1!$E$69:$E$150,0),MATCH(G$1,Sheet1!$E$69:$AJ$69,0)) -> -1.6892555 | H21: =INDEX(Sheet1!$E$69:$AJ$150,MATCH($A21,Sheet1!$E$69:$E$150,0),MATCH(H$1,Sheet1!$E$69:$AJ$69,0)) -> -1.414217 | I21: =INDEX(Sheet1!$E$69:$AJ$150,MATCH($A21,Sheet1!$E$69:$E$150,0),MATCH(I$1,Sheet1!$E$69:$AJ$69,0)) -> -1.2399103 | J21: =INDEX(Sheet1!$E$69:$AJ$150,MATCH($A21,Sheet1!$E$69:$E$150,0),MATCH(J$1,Sheet1!$E$69:$AJ$69,0)) -> -0.68273894 | L21: =INDEX(Sheet1!$E$69:$AJ$150,MATCH($A21,Sheet1!$E$69:$E$150,0),MATCH(L$1,Sheet1!$E$69:$AJ$69,0)) -> -1.5601281 | M21: =INDEX(Sheet1!$E$69:$AJ$150,MATCH($A21,Sheet1!$E$69:$E$150,0),MATCH(M$1,Sheet1!$E$69:$AJ$69,0)) -> -1.2343095 | N21: =INDEX(Sheet1!$E$69:$AJ$150,MATCH($A21,Sheet1!$E$69:$E$150,0),MATCH(N$1,Sheet1!$E$69:$AJ$69,0)) -> -0.86600564 | O21: =INDEX(Sheet1!$E$69:$AJ$150,MATCH($A21,Sheet1!$E$69:$E$150,0),MATCH(O$1,Sheet1!$E$69:$AJ$69,0)) -> -0.42384063 | Q21: =INDEX(Sheet1!$E$69:$AJ$150,MATCH($A21,Sheet1!$E$69:$E$150,0),MATCH(Q$1,Sheet1!$E$69:$AJ$69,0)) -> -1.5100776 | R21: =INDEX(Sheet1!$E$69:$AJ$150,MATCH($A21,Sheet1!$E$69:$E$150,0),MATCH(R$1,Sheet1!$E$69:$AJ$69,0)) -> -1.1959965 | S21: =INDEX(Sheet1!$E$69:$AJ$150,MATCH($A21,Sheet1!$E$69:$E$150,0),MATCH(S$1,Sheet1!$E$69:$AJ$69,0)) -> -0.64215933 | T21: =INDEX(Sheet1!$E$69:$AJ$150,MATCH($A21,Sheet1!$E$69:$E$150,0),MATCH(T$1,Sheet1!$E$69:$AJ$69,0)) -> -0.40498441 | V21: =INDEX(Sheet1!$E$69:$AJ$150,MATCH($A21,Sheet1!$E$69:$E$150,0),MATCH(V$1,Sheet1!$E$69:$AJ$69,0)) -> -1.6301737 | W21: =INDEX(Sheet1!$E$69:$AJ$150,MATCH($A21,Sheet1!$E$69:$E$150,0),MATCH(W$1,Sheet1!$E$69:$AJ$69,0)) -> -1.4108751 | X21: =INDEX(Sheet1!$E$69:$AJ$150,MATCH($A21,Sheet1!$E$69:$E$150,0),MATCH(X$1,Sheet1!$E$69:$AJ$69,0)) -> -0.79470839 | Y21: =INDEX(Sheet1!$E$69:$AJ$150,MATCH($A21,Sheet1!$E$69:$E$150,0),MATCH(Y$1,Sheet1!$E$69:$AJ$69,0)) -> -0.7835034
A22: =_xlfn.TEXTJOIN("",TRUE,B22:C22) -> T2Weight | B22: T2 | C22: Weight | F22: Weight | G22: =INDEX(Sheet1!$E$69:$AJ$150,MATCH($A22,Sheet1!$E$69:$E$150,0),MATCH(G$1,Sheet1!$E$69:$AJ$69,0)) -> -0.16444713 | H22: =INDEX(Sheet1!$E$69:$AJ$150,MATCH($A22,Sheet1!$E$69:$E$150,0),MATCH(H$1,Sheet1!$E$69:$AJ$69,0)) -> -0.1353644 | I22: =INDEX(Sheet1!$E$69:$AJ$150,MATCH($A22,Sheet1!$E$69:$E$150,0),MATCH(I$1,Sheet1!$E$69:$AJ$69,0)) -> -0.11617961 | J22: =INDEX(Sheet1!$E$69:$AJ$150,MATCH($A22,Sheet1!$E$69:$E$150,0),MATCH(J$1,Sheet1!$E$69:$AJ$69,0)) -> -0.06113265 | L22: =INDEX(Sheet1!$E$69:$AJ$150,MATCH($A22,Sheet1!$E$69:$E$150,0),MATCH(L$1,Sheet1!$E$69:$AJ$69,0)) -> -0.20216485 | M22: =INDEX(Sheet1!$E$69:$AJ$150,MATCH($A22,Sheet1!$E$69:$E$150,0),MATCH(M$1,Sheet1!$E$69:$AJ$69,0)) -> -0.15474267 | N22: =INDEX(Sheet1!$E$69:$AJ$150,MATCH($A22,Sheet1!$E$69:$E$150,0),MATCH(N$1,Sheet1!$E$69:$AJ$69,0)) -> -0.10532659 | O22: =INDEX(Sheet1!$E$69:$AJ$150,MATCH($A22,Sheet1!$E$69:$E$150,0),MATCH(O$1,Sheet1!$E$69:$AJ$69,0)) -> -0.050262762 | Q22: =INDEX(Sheet1!$E$69:$AJ$150,MATCH($A22,Sheet1!$E$69:$E$150,0),MATCH(Q$1,Sheet1!$E$69:$AJ$69,0)) -> -0.27221459 | R22: =INDEX(Sheet1!$E$69:$AJ$150,MATCH($A22,Sheet1!$E$69:$E$150,0),MATCH(R$1,Sheet1!$E$69:$AJ$69,0)) -> -0.19897831 | S22: =INDEX(Sheet1!$E$69:$AJ$150,MATCH($A22,Sheet1!$E$69:$E$150,0),MATCH(S$1,Sheet1!$E$69:$AJ$69,0)) -> -0.10226757 | T22: =INDEX(Sheet1!$E$69:$AJ$150,MATCH($A22,Sheet1!$E$69:$E$150,0),MATCH(T$1,Sheet1!$E$69:$AJ$69,0)) -> -0.06538495 | V22: =INDEX(Sheet1!$E$69:$AJ$150,MATCH($A22,Sheet1!$E$69:$E$150,0),MATCH(V$1,Sheet1!$E$69:$AJ$69,0)) -> -0.23450522 | W22: =INDEX(Sheet1!$E$69:$AJ$150,MATCH($A22,Sheet1!$E$69:$E$150,0),MATCH(W$1,Sheet1!$E$69:$AJ$69,0)) -> -0.1850794 | X22: =INDEX(Sheet1!$E$69:$AJ$150,MATCH($A22,Sheet1!$E$69:$E$150,0),MATCH(X$1,Sheet1!$E$69:$AJ$69,0)) -> -0.10008555 | Y22: =INDEX(Sheet1!$E$69:$AJ$150,MATCH($A22,Sheet1!$E$69:$E$150,0),MATCH(Y$1,Sheet1!$E$69:$AJ$69,0)) -> -0.10431457
A23: =_xlfn.TEXTJOIN("",TRUE,B23:C23) -> T2p | B23: T2 | C23: p | F23: p | G23: =INDEX(Sheet1!$E$69:$AJ$150,MATCH($A23,Sheet1!$E$69:$E$150,0),MATCH(G$1,Sheet1!$E$69:$AJ$69,0)) -> 0.036534223 | H23: =INDEX(Sheet1!$E$69:$AJ$150,MATCH($A23,Sheet1!$E$69:$E$150,0),MATCH(H$1,Sheet1!$E$69:$AJ$69,0)) -> 0.048198372 | I23: =INDEX(Sheet1!$E$69:$AJ$150,MATCH($A23,Sheet1!$E$69:$E$150,0),MATCH(I$1,Sheet1!$E$69:$AJ$69,0)) -> 0.066181909 | J23: =INDEX(Sheet1!$E$69:$AJ$150,MATCH($A23,Sheet1!$E$69:$E$150,0),MATCH(J$1,Sheet1!$E$69:$AJ$69,0)) -> 0.10267693 | L23: =INDEX(Sheet1!$E$69:$AJ$150,MATCH($A23,Sheet1!$E$69:$E$150,0),MATCH(L$1,Sheet1!$E$69:$AJ$69,0)) -> 0.066526539 | M23: =INDEX(Sheet1!$E$69:$AJ$150,MATCH($A23,Sheet1!$E$69:$E$150,0),MATCH(M$1,Sheet1!$E$69:$AJ$69,0)) -> 0.094626698 | N23: =INDEX(Sheet1!$E$69:$AJ$150,MATCH($A23,Sheet1!$E$69:$E$150,0),MATCH(N$1,Sheet1!$E$69:$AJ$69,0)) -> 0.12028234 | O23: =INDEX(Sheet1!$E$69:$AJ$150,MATCH($A23,Sheet1!$E$69:$E$150,0),MATCH(O$1,Sheet1!$E$69:$AJ$69,0)) -> 0.14001468 | Q23: =INDEX(Sheet1!$E$69:$AJ$150,MATCH($A23,Sheet1!$E$69:$E$150,0),MATCH(Q$1,Sheet1!$E$69:$AJ$69,0)) -> 0.12390641 | R23: =INDEX(Sheet1!$E$69:$AJ$150,MATCH($A23,Sheet1!$E$69:$E$150,0),MATCH(R$1,Sheet1!$E$69:$AJ$69,0)) -> 0.18867415 | S23: =INDEX(Sheet1!$E$69:$AJ$150,MATCH($A23,Sheet1!$E$69:$E$150,0),MATCH(S$1,Sheet1!$E$69:$AJ$69,0)) -> 0.22124584 | T23: =INDEX(Sheet1!$E$69:$AJ$150,MATCH($A23,Sheet1!$E$69:$E$150,0),MATCH(T$1,Sheet1!$E$69:$AJ$69,0)) -> 0.20818297 | V23: =INDEX(Sheet1!$E$69:$AJ$150,MATCH($A23,Sheet1!$E$69:$E$150,0),MATCH(V$1,Sheet1!$E$69:$AJ$69,0)) -> 0.10331842 | W23: =INDEX(Sheet1!$E$69:$AJ$150,MATCH($A23,Sheet1!$E$69:$E$150,0),MATCH(W$1,Sheet1!$E$69:$AJ$69,0)) -> 0.17946047 | X23: =INDEX(Sheet1!$E$69:$AJ$150,MATCH($A23,Sheet1!$E$69:$E$150,0),MATCH(X$1,Sheet1!$E$69:$AJ$69,0)) -> 0.20953456 | Y23: =INDEX(Sheet1!$E$69:$AJ$150,MATCH($A23,Sheet1!$E$69:$E$150,0),MATCH(Y$1,Sheet1!$E$69:$AJ$69,0)) -> 0.16235817
A24: =_xlfn.TEXTJOIN("",TRUE,B24:C24) -> T3lambda | B24: T3 | C24: lambda | E24: T3 | F24: coefficient | G24: =INDEX(Sheet1!$E$69:$AJ$150,MATCH($A24,Sheet1!$E$69:$E$150,0),MATCH(G$1,Sheet1!$E$69:$AJ$69,0)) -> 1.7629254 | H24: =INDEX(Sheet1!$E$69:$AJ$150,MATCH($A24,Sheet1!$E$69:$E$150,0),MATCH(H$1,Sheet1!$E$69:$AJ$69,0)) -> 1.0514704 | I24: =INDEX(Sheet1!$E$69:$AJ$150,MATCH($A24,Sheet1!$E$69:$E$150,0),MATCH(I$1,Sheet1!$E$69:$AJ$69,0)) -> 0.73858079 | J24: =INDEX(Sheet1!$E$69:$AJ$150,MATCH($A24,Sheet1!$E$69:$E$150,0),MATCH(J$1,Sheet1!$E$69:$AJ$69,0)) -> 0 | L24: =INDEX(Sheet1!$E$69:$AJ$150,MATCH($A24,Sheet1!$E$69:$E$150,0),MATCH(L$1,Sheet1!$E$69:$AJ$69,0)) -> 1.660706 | M24: =INDEX(Sheet1!$E$69:$AJ$150,MATCH($A24,Sheet1!$E$69:$E$150,0),MATCH(M$1,Sheet1!$E$69:$AJ$69,0)) -> 1.0104305 | N24: =INDEX(Sheet1!$E$69:$AJ$150,MATCH($A24,Sheet1!$E$69:$E$150,0),MATCH(N$1,Sheet1!$E$69:$AJ$69,0)) -> 0.49681085 | O24: =INDEX(Sheet1!$E$69:$AJ$150,MATCH($A24,Sheet1!$E$69:$E$150,0),MATCH(O$1,Sheet1!$E$69:$AJ$69,0)) -> 0 | Q24: =INDEX(Sheet1!$E$69:$AJ$150,MATCH($A24,Sheet1!$E$69:$E$150,0),MATCH(Q$1,Sheet1!$E$69:$AJ$69,0)) -> 1.5584865 | R24: =INDEX(Sheet1!$E$69:$AJ$150,MATCH($A24,Sheet1!$E$69:$E$150,0),MATCH(R$1,Sheet1!$E$69:$AJ$69,0)) -> 0.96939062 | S24: =INDEX(Sheet1!$E$69:$AJ$150,MATCH($A24,Sheet1!$E$69:$E$150,0),MATCH(S$1,Sheet1!$E$69:$AJ$69,0)) -> 0.25504091 | T24: =INDEX(Sheet1!$E$69:$AJ$150,MATCH($A24,Sheet1!$E$69:$E$150,0),MATCH(T$1,Sheet1!$E$69:$AJ$69,0)) -> 0 | V24: =INDEX(Sheet1!$E$69:$AJ$150,MATCH($A24,Sheet1!$E$69:$E$150,0),MATCH(V$1,Sheet1!$E$69:$AJ$69,0)) -> 1.456267 | W24: =INDEX(Sheet1!$E$69:$AJ$150,MATCH($A24,Sheet1!$E$69:$E$150,0),MATCH(W$1,Sheet1!$E$69:$AJ$69,0)) -> 0.92835074 | X24: =INDEX(Sheet1!$E$69:$AJ$150,MATCH($A24,Sheet1!$E$69:$E$150,0),MATCH(X$1,Sheet1!$E$69:$AJ$69,0)) -> 0.013270965 | Y24: =INDEX(Sheet1!$E$69:$AJ$150,MATCH($A24,Sheet1!$E$69:$E$150,0),MATCH(Y$1,Sheet1!$E$69:$AJ$69,0)) -> 0
A25: =_xlfn.TEXTJOIN("",TRUE,B25:C25) -> T3e^lambda-1 | B25: T3 | C25: e^lambda-1 | F25: Effect | G25: =INDEX(Sheet1!$E$69:$AJ$150,MATCH($A25,Sheet1!$E$69:$E$150,0),MATCH(G$1,Sheet1!$E$69:$AJ$69,0)) -> 4.8294662 | H25: =INDEX(Sheet1!$E$69:$AJ$150,MATCH($A25,Sheet1!$E$69:$E$150,0),MATCH(H$1,Sheet1!$E$69:$AJ$69,0)) -> 1.8618561 | I25: =INDEX(Sheet1!$E$69:$AJ$150,MATCH($A25,Sheet1!$E$69:$E$150,0),MATCH(I$1,Sheet1!$E$69:$AJ$69,0)) -> 1.092963 | J25: =INDEX(Sheet1!$E$69:$AJ$150,MATCH($A25,Sheet1!$E$69:$E$150,0),MATCH(J$1,Sheet1!$E$69:$AJ$69,0)) -> 0 | L25: =INDEX(Sheet1!$E$69:$AJ$150,MATCH($A25,Sheet1!$E$69:$E$150,0),MATCH(L$1,Sheet1!$E$69:$AJ$69,0)) -> 4.2630251 | M25: =INDEX(Sheet1!$E$69:$AJ$150,MATCH($A25,Sheet1!$E$69:$E$150,0),MATCH(M$1,Sheet1!$E$69:$AJ$69,0)) -> 1.7467833 | N25: =INDEX(Sheet1!$E$69:$AJ$150,MATCH($A25,Sheet1!$E$69:$E$150,0),MATCH(N$1,Sheet1!$E$69:$AJ$69,0)) -> 0.64347162 | O25: =INDEX(Sheet1!$E$69:$AJ$150,MATCH($A25,Sheet1!$E$69:$E$150,0),MATCH(O$1,Sheet1!$E$69:$AJ$69,0)) -> 0 | Q25: =INDEX(Sheet1!$E$69:$AJ$150,MATCH($A25,Sheet1!$E$69:$E$150,0),MATCH(Q$1,Sheet1!$E$69:$AJ$69,0)) -> 3.7516242 | R25: =INDEX(Sheet1!$E$69:$AJ$150,MATCH($A25,Sheet1!$E$69:$E$150,0),MATCH(R$1,Sheet1!$E$69:$AJ$69,0)) -> 1.6363375 | S25: =INDEX(Sheet1!$E$69:$AJ$150,MATCH($A25,Sheet1!$E$69:$E$150,0),MATCH(S$1,Sheet1!$E$69:$AJ$69,0)) -> 0.29051441 | T25: =INDEX(Sheet1!$E$69:$AJ$150,MATCH($A25,Sheet1!$E$69:$E$150,0),MATCH(T$1,Sheet1!$E$69:$AJ$69,0)) -> 0 | V25: =INDEX(Sheet1!$E$69:$AJ$150,MATCH($A25,Sheet1!$E$69:$E$150,0),MATCH(V$1,Sheet1!$E$69:$AJ$69,0)) -> 3.2899155 | W25: =INDEX(Sheet1!$E$69:$AJ$150,MATCH($A25,Sheet1!$E$69:$E$150,0),MATCH(W$1,Sheet1!$E$69:$AJ$69,0)) -> 1.5303326 | X25: =INDEX(Sheet1!$E$69:$AJ$150,MATCH($A25,Sheet1!$E$69:$E$150,0),MATCH(X$1,Sheet1!$E$69:$AJ$69,0)) -> 0.013359415 | Y25: =INDEX(Sheet1!$E$69:$AJ$150,MATCH($A25,Sheet1!$E$69:$E$150,0),MATCH(Y$1,Sheet1!$E$69:$AJ$69,0)) -> 0
A26: =_xlfn.TEXTJOIN("",TRUE,B26:C26) -> T3R | B26: T3 | C26: R | F26: At Risk | G26: =INDEX(Sheet1!$E$69:$AJ$150,MATCH($A26,Sheet1!$E$69:$E$150,0),MATCH(G$1,Sheet1!$E$69:$AJ$69,0)) -> 0.9840605 | H26: =INDEX(Sheet1!$E$69:$AJ$150,MATCH($A26,Sheet1!$E$69:$E$150,0),MATCH(H$1,Sheet1!$E$69:$AJ$69,0)) -> 0.9794203 | I26: =INDEX(Sheet1!$E$69:$AJ$150,MATCH($A26,Sheet1!$E$69:$E$150,0),MATCH(I$1,Sheet1!$E$69:$AJ$69,0)) -> 0.97724732 | J26: =INDEX(Sheet1!$E$69:$AJ$150,MATCH($A26,Sheet1!$E$69:$E$150,0),MATCH(J$1,Sheet1!$E$69:$AJ$69,0)) -> 0.97184465 | L26: =INDEX(Sheet1!$E$69:$AJ$150,MATCH($A26,Sheet1!$E$69:$E$150,0),MATCH(L$1,Sheet1!$E$69:$AJ$69,0)) -> 0.99144778 | M26: =INDEX(Sheet1!$E$69:$AJ$150,MATCH($A26,Sheet1!$E$69:$E$150,0),MATCH(M$1,Sheet1!$E$69:$AJ$69,0)) -> 0.98897369 | N26: =INDEX(Sheet1!$E$69:$AJ$150,MATCH($A26,Sheet1!$E$69:$E$150,0),MATCH(N$1,Sheet1!$E$69:$AJ$69,0)) -> 0.98741654 | O26: =INDEX(Sheet1!$E$69:$AJ$150,MATCH($A26,Sheet1!$E$69:$E$150,0),MATCH(O$1,Sheet1!$E$69:$AJ$69,0)) -> 0.98487052 | Q26: =INDEX(Sheet1!$E$69:$AJ$150,MATCH($A26,Sheet1!$E$69:$E$150,0),MATCH(Q$1,Sheet1!$E$69:$AJ$69,0)) -> 0.98836292 | R26: =INDEX(Sheet1!$E$69:$AJ$150,MATCH($A26,Sheet1!$E$69:$E$150,0),MATCH(R$1,Sheet1!$E$69:$AJ$69,0)) -> 0.98499795 | S26: =INDEX(Sheet1!$E$69:$AJ$150,MATCH($A26,Sheet1!$E$69:$E$150,0),MATCH(S$1,Sheet1!$E$69:$AJ$69,0)) -> 0.98231227 | T26: =INDEX(Sheet1!$E$69:$AJ$150,MATCH($A26,Sheet1!$E$69:$E$150,0),MATCH(T$1,Sheet1!$E$69:$AJ$69,0)) -> 0.9794211 | V26: =INDEX(Sheet1!$E$69:$AJ$150,MATCH($A26,Sheet1!$E$69:$E$150,0),MATCH(V$1,Sheet1!$E$69:$AJ$69,0)) -> 0.98811216 | W26: =INDEX(Sheet1!$E$69:$AJ$150,MATCH($A26,Sheet1!$E$69:$E$150,0),MATCH(W$1,Sheet1!$E$69:$AJ$69,0)) -> 0.98468167 | X26: =INDEX(Sheet1!$E$69:$AJ$150,MATCH($A26,Sheet1!$E$69:$E$150,0),MATCH(X$1,Sheet1!$E$69:$AJ$69,0)) -> 0.98131078 | Y26: =INDEX(Sheet1!$E$69:$AJ$150,MATCH($A26,Sheet1!$E$69:$E$150,0),MATCH(Y$1,Sheet1!$E$69:$AJ$69,0)) -> 0.97897499
A27: =_xlfn.TEXTJOIN("",TRUE,B27:C27) -> T3D | B27: T3 | C27: D | F27: Differenciate | G27: =INDEX(Sheet1!$E$69:$AJ$150,MATCH($A27,Sheet1!$E$69:$E$150,0),MATCH(G$1,Sheet1!$E$69:$AJ$69,0)) -> 0.067032096 | H27: =INDEX(Sheet1!$E$69:$AJ$150,MATCH($A27,Sheet1!$E$69:$E$150,0),MATCH(H$1,Sheet1!$E$69:$AJ$69,0)) -> 0.11289298 | I27: =INDEX(Sheet1!$E$69:$AJ$150,MATCH($A27,Sheet1!$E$69:$E$150,0),MATCH(I$1,Sheet1!$E$69:$AJ$69,0)) -> 0.1466206 | J27: =INDEX(Sheet1!$E$69:$AJ$150,MATCH($A27,Sheet1!$E$69:$E$150,0),MATCH(J$1,Sheet1!$E$69:$AJ$69,0)) -> 0.23963251 | L27: =INDEX(Sheet1!$E$69:$AJ$150,MATCH($A27,Sheet1!$E$69:$E$150,0),MATCH(L$1,Sheet1!$E$69:$AJ$69,0)) -> 0.088161886 | M27: =INDEX(Sheet1!$E$69:$AJ$150,MATCH($A27,Sheet1!$E$69:$E$150,0),MATCH(M$1,Sheet1!$E$69:$AJ$69,0)) -> 0.13962577 | N27: =INDEX(Sheet1!$E$69:$AJ$150,MATCH($A27,Sheet1!$E$69:$E$150,0),MATCH(N$1,Sheet1!$E$69:$AJ$69,0)) -> 0.19264702 | O27: =INDEX(Sheet1!$E$69:$AJ$150,MATCH($A27,Sheet1!$E$69:$E$150,0),MATCH(O$1,Sheet1!$E$69:$AJ$69,0)) -> 0.24955408 | Q27: =INDEX(Sheet1!$E$69:$AJ$150,MATCH($A27,Sheet1!$E$69:$E$150,0),MATCH(Q$1,Sheet1!$E$69:$AJ$69,0)) -> 0.11007416 | R27: =INDEX(Sheet1!$E$69:$AJ$150,MATCH($A27,Sheet1!$E$69:$E$150,0),MATCH(R$1,Sheet1!$E$69:$AJ$69,0)) -> 0.1674607 | S27: =INDEX(Sheet1!$E$69:$AJ$150,MATCH($A27,Sheet1!$E$69:$E$150,0),MATCH(S$1,Sheet1!$E$69:$AJ$69,0)) -> 0.23118383 | T27: =INDEX(Sheet1!$E$69:$AJ$150,MATCH($A27,Sheet1!$E$69:$E$150,0),MATCH(T$1,Sheet1!$E$69:$AJ$69,0)) -> 0.24942769 | V27: =INDEX(Sheet1!$E$69:$AJ$150,MATCH($A27,Sheet1!$E$69:$E$150,0),MATCH(V$1,Sheet1!$E$69:$AJ$69,0)) -> 0.10854813 | W27: =INDEX(Sheet1!$E$69:$AJ$150,MATCH($A27,Sheet1!$E$69:$E$150,0),MATCH(W$1,Sheet1!$E$69:$AJ$69,0)) -> 0.17504943 | X27: =INDEX(Sheet1!$E$69:$AJ$150,MATCH($A27,Sheet1!$E$69:$E$150,0),MATCH(X$1,Sheet1!$E$69:$AJ$69,0)) -> 0.26097357 | Y27: =INDEX(Sheet1!$E$69:$AJ$150,MATCH($A27,Sheet1!$E$69:$E$150,0),MATCH(Y$1,Sheet1!$E$69:$AJ$69,0)) -> 0.24312846
A28: =_xlfn.TEXTJOIN("",TRUE,B28:C28) -> T3G | B28: T3 | C28: G | F28: Gain | G28: =INDEX(Sheet1!$E$69:$AJ$150,MATCH($A28,Sheet1!$E$69:$E$150,0),MATCH(G$1,Sheet1!$E$69:$AJ$69,0)) -> 3.3439841 | H28: =INDEX(Sheet1!$E$69:$AJ$150,MATCH($A28,Sheet1!$E$69:$E$150,0),MATCH(H$1,Sheet1!$E$69:$AJ$69,0)) -> 3.4861188 | I28: =INDEX(Sheet1!$E$69:$AJ$150,MATCH($A28,Sheet1!$E$69:$E$150,0),MATCH(I$1,Sheet1!$E$69:$AJ$69,0)) -> 3.4566977 | J28: =INDEX(Sheet1!$E$69:$AJ$150,MATCH($A28,Sheet1!$E$69:$E$150,0),MATCH(J$1,Sheet1!$E$69:$AJ$69,0)) -> 3.4842676 | L28: =INDEX(Sheet1!$E$69:$AJ$150,MATCH($A28,Sheet1!$E$69:$E$150,0),MATCH(L$1,Sheet1!$E$69:$AJ$69,0)) -> 3.2135354 | M28: =INDEX(Sheet1!$E$69:$AJ$150,MATCH($A28,Sheet1!$E$69:$E$150,0),MATCH(M$1,Sheet1!$E$69:$AJ$69,0)) -> 3.293661 | N28: =INDEX(Sheet1!$E$69:$AJ$150,MATCH($A28,Sheet1!$E$69:$E$150,0),MATCH(N$1,Sheet1!$E$69:$AJ$69,0)) -> 3.3492643 | O28: =INDEX(Sheet1!$E$69:$AJ$150,MATCH($A28,Sheet1!$E$69:$E$150,0),MATCH(O$1,Sheet1!$E$69:$AJ$69,0)) -> 3.4152449 | Q28: =INDEX(Sheet1!$E$69:$AJ$150,MATCH($A28,Sheet1!$E$69:$E$150,0),MATCH(Q$1,Sheet1!$E$69:$AJ$69,0)) -> 2.9281957 | R28: =INDEX(Sheet1!$E$69:$AJ$150,MATCH($A28,Sheet1!$E$69:$E$150,0),MATCH(R$1,Sheet1!$E$69:$AJ$69,0)) -> 2.92723 | S28: =INDEX(Sheet1!$E$69:$AJ$150,MATCH($A28,Sheet1!$E$69:$E$150,0),MATCH(S$1,Sheet1!$E$69:$AJ$69,0)) -> 3.0887768 | T28: =INDEX(Sheet1!$E$69:$AJ$150,MATCH($A28,Sheet1!$E$69:$E$150,0),MATCH(T$1,Sheet1!$E$69:$AJ$69,0)) -> 3.2052919 | V28: =INDEX(Sheet1!$E$69:$AJ$150,MATCH($A28,Sheet1!$E$69:$E$150,0),MATCH(V$1,Sheet1!$E$69:$AJ$69,0)) -> 2.8903768 | W28: =INDEX(Sheet1!$E$69:$AJ$150,MATCH($A28,Sheet1!$E$69:$E$150,0),MATCH(W$1,Sheet1!$E$69:$AJ$69,0)) -> 2.804834 | X28: =INDEX(Sheet1!$E$69:$AJ$150,MATCH($A28,Sheet1!$E$69:$E$150,0),MATCH(X$1,Sheet1!$E$69:$AJ$69,0)) -> 3.0639926 | Y28: =INDEX(Sheet1!$E$69:$AJ$150,MATCH($A28,Sheet1!$E$69:$E$150,0),MATCH(Y$1,Sheet1!$E$69:$AJ$69,0)) -> 3.2215003
A29: =_xlfn.TEXTJOIN("",TRUE,B29:C29) -> T3Weight | B29: T3 | C29: Weight | F29: Weight | G29: =INDEX(Sheet1!$E$69:$AJ$150,MATCH($A29,Sheet1!$E$69:$E$150,0),MATCH(G$1,Sheet1!$E$69:$AJ$69,0)) -> 0.22058136 | H29: =INDEX(Sheet1!$E$69:$AJ$150,MATCH($A29,Sheet1!$E$69:$E$150,0),MATCH(H$1,Sheet1!$E$69:$AJ$69,0)) -> 0.38545903 | I29: =INDEX(Sheet1!$E$69:$AJ$150,MATCH($A29,Sheet1!$E$69:$E$150,0),MATCH(I$1,Sheet1!$E$69:$AJ$69,0)) -> 0.49529149 | J29: =INDEX(Sheet1!$E$69:$AJ$150,MATCH($A29,Sheet1!$E$69:$E$150,0),MATCH(J$1,Sheet1!$E$69:$AJ$69,0)) -> 0.81143565 | L29: =INDEX(Sheet1!$E$69:$AJ$150,MATCH($A29,Sheet1!$E$69:$E$150,0),MATCH(L$1,Sheet1!$E$69:$AJ$69,0)) -> 0.2808884 | M29: =INDEX(Sheet1!$E$69:$AJ$150,MATCH($A29,Sheet1!$E$69:$E$150,0),MATCH(M$1,Sheet1!$E$69:$AJ$69,0)) -> 0.45480916 | N29: =INDEX(Sheet1!$E$69:$AJ$150,MATCH($A29,Sheet1!$E$69:$E$150,0),MATCH(N$1,Sheet1!$E$69:$AJ$69,0)) -> 0.63710662 | O29: =INDEX(Sheet1!$E$69:$AJ$150,MATCH($A29,Sheet1!$E$69:$E$150,0),MATCH(O$1,Sheet1!$E$69:$AJ$69,0)) -> 0.83939362 | Q29: =INDEX(Sheet1!$E$69:$AJ$150,MATCH($A29,Sheet1!$E$69:$E$150,0),MATCH(Q$1,Sheet1!$E$69:$AJ$69,0)) -> 0.31856783 | R29: =INDEX(Sheet1!$E$69:$AJ$150,MATCH($A29,Sheet1!$E$69:$E$150,0),MATCH(R$1,Sheet1!$E$69:$AJ$69,0)) -> 0.48284204 | S29: =INDEX(Sheet1!$E$69:$AJ$150,MATCH($A29,Sheet1!$E$69:$E$150,0),MATCH(S$1,Sheet1!$E$69:$AJ$69,0)) -> 0.70144488 | T29: =INDEX(Sheet1!$E$69:$AJ$150,MATCH($A29,Sheet1!$E$69:$E$150,0),MATCH(T$1,Sheet1!$E$69:$AJ$69,0)) -> 0.78303595 | V29: =INDEX(Sheet1!$E$69:$AJ$150,MATCH($A29,Sheet1!$E$69:$E$150,0),MATCH(V$1,Sheet1!$E$69:$AJ$69,0)) -> 0.31001525 | W29: =INDEX(Sheet1!$E$69:$AJ$150,MATCH($A29,Sheet1!$E$69:$E$150,0),MATCH(W$1,Sheet1!$E$69:$AJ$69,0)) -> 0.48346351 | X29: =INDEX(Sheet1!$E$69:$AJ$150,MATCH($A29,Sheet1!$E$69:$E$150,0),MATCH(X$1,Sheet1!$E$69:$AJ$69,0)) -> 0.7846768 | Y29: =INDEX(Sheet1!$E$69:$AJ$150,MATCH($A29,Sheet1!$E$69:$E$150,0),MATCH(Y$1,Sheet1!$E$69:$AJ$69,0)) -> 0.76677082
