Workbook

Sheet table
J2: Sequential Logit regression (Mulieris)
K3: T1(high school) | O3: T2(Jr./Tech collage) | S3: T3(4-year collage/University)
K4: coef. | L4: s.e. | O4: coef. | P4: s.e. | S4: coef. | T4: s.e.
D5: {=Sheet1!I5:I25} -> 兄弟数 | E5: {=_xlfn.CHOOSECOLS(Sheet1!C5:F67,1,2,4)} -> -0.20293964 | F5: 0.025371019 | G5: 1.255599e-15 | H5: {=_xlfn.IFS(G5:G67=0,"",G5:G67<0.01,"**",G5:G67<0.05,"*",G5:G67<0.1,"†",G5:G67>=0.1,"")} -> ** | J5: sibs | K5: {=E5:F25} -> -0.20293964 | L5: 0.025371019 | M5: {=H5:H25} -> ** | O5: {=E26:F46} -> -0.10705059 | P5: 0.026622535 | Q5: {=H26:H46} -> ** | S5: {=E47:F67} -> -0.35423861 | T5: 0.045247729 | U5: {=H47:H67} -> **
D6: 父中卒ref | E6: 0 | F6: 0 | G6: 0 | J6: father's educ (ref. compulsory) | K6: 0 | L6: 0 | O6: 0 | P6: 0 | S6: 0 | T6: 0
D7: 父高卒 | E7: 1.0640685 | F7: 0.13351571 | G7: 1.5917172e-15 | H7: ** | J7: Jr.high | K7: 1.0640685 | L7: 0.13351571 | M7: ** | O7: 0.50504807 | P7: 0.07554872 | Q7: ** | S7: 0.89097273 | T7: 0.12334309 | U7: **
D8: 父大卒 | E8: 1.4580361 | F8: 0.23472685 | G8: 5.2438177e-10 | H8: ** | J8: Tertially | K8: 1.4580361 | L8: 0.23472685 | M8: ** | O8: 0.91744533 | P8: 0.10279621 | Q8: ** | S8: 2.0344063 | T8: 0.13738748 | U8: **
D9: 世代40s ref | E9: 0 | F9: 0 | G9: 0 | J9: Birth cohort (ref. 1940s) | K9: 0 | L9: 0 | O9: 0 | P9: 0 | S9: 0 | T9: 0
D10: 50s | E10: 1.629385 | F10: 0.14093583 | G10: 6.4808968e-31 | H10: ** | J10: 1950s | K10: 1.629385 | L10: 0.14093583 | M10: ** | O10: 0.67173992 | P10: 0.10785464 | Q10: ** | S10: 0.75076024 | T10: 0.1764832 | U10: **
D11: 60s | E11: 2.8741958 | F11: 0.28132582 | G11: 1.6708422e-24 | H11: ** | J11: 1960s | K11: 2.8741958 | L11: 0.28132582 | M11: ** | O11: 0.79861247 | P11: 0.12595448 | Q11: ** | S11: 0.80611368 | T11: 0.20563776 | U11: **
D12: 70s | E12: 2.3913043 | F12: 0.27660405 | G12: 5.3699209e-18 | H12: ** | J12: 1970s | K12: 2.3913043 | L12: 0.27660405 | M12: ** | O12: 1.0819615 | P12: 0.14607534 | Q12: ** | S12: 1.2960162 | T12: 0.24341605 | U12: **
D13: 80-90s | E13: 2.4848283 | F13: 0.3906858 | G13: 2.015301e-10 | H13: ** | J13: 1980s~ | K13: 2.4848283 | L13: 0.3906858 | M13: ** | O13: 1.0205309 | P13: 0.18033147 | Q13: ** | S13: 1.6595199 | T13: 0.29306539 | U13: **
D14: 0 | E14: 0 | F14: 0 | G14: 0 | K14: 0 | L14: 0 | O14: 0 | P14: 0 | S14: 0 | T14: 0
D15: EGP I+II | E15: 3.0025493 | F15: 1.3989822 | G15: 0.031853962 | H15: * | J15: Father's EGP I+II | K15: 3.0025493 | L15: 1.3989822 | M15: * | O15: 1.221553 | P15: 0.40084351 | Q15: ** | S15: 1.0874637 | T15: 0.58574701 | U15: †
D16: IIIab | E16: 0.25615819 | F16: 1.220349 | G16: 0.83374128 | J16: IIIab | K16: 0.25615819 | L16: 1.220349 | O16: 0.90053981 | P16: 0.48923714 | Q16: † | S16: 0.83038307 | T16: 0.70711391
D17: IVab | E17: 1.6322587 | F17: 0.58501282 | G17: 0.0052687737 | H17: ** | J17: Ivab | K17: 1.6322587 | L17: 0.58501282 | M17: ** | O17: 1.2391525 | P17: 0.39862913 | Q17: ** | S17: 1.4998775 | T17: 0.65679067 | U17: *
D18: V+VI+VIIab+IVc | E18: 0 | F18: 0 | G18: 0 | J18: V+VI+VIIab (ref.) | K18: 0 | L18: 0 | O18: 0 | P18: 0 | S18: 0 | T18: 0
D19: job+abs | E19: 0.75071677 | F19: 0.55866729 | G19: 0.17902484 | J19: nojob,abs | K19: 0.75071677 | L19: 0.55866729 | O19: 1.134172 | P19: 0.5015904 | Q19: * | S19: 1.5296554 | T19: 0.76778093 | U19: *
D20: 世代× I+II | E20: -0.15880867 | F20: 0.30548084 | G20: 0.60315795 | J20: cohort * I+II | K20: -0.15880867 | L20: 0.30548084 | O20: -0.065995648 | P20: 0.068573373 | S20: 0.063982224 | T20: 0.092258944
D21: IIIab | E21: 0.1659776 | F21: 0.27636959 | G21: 0.54813047 | J21: cohort * IIIab | K21: 0.1659776 | L21: 0.27636959 | O21: -0.054119504 | P21: 0.08083522 | S21: 0.050927532 | T21: 0.10920856
D22: IVab | E22: -0.25659291 | F22: 0.12826466 | G22: 0.045446758 | H22: * | J22: cohort *Ivab | K22: -0.25659291 | L22: 0.12826466 | M22: * | O22: -0.14001248 | P22: 0.068335421 | Q22: * | S22: -0.12572664 | T22: 0.10428177
D23: V+VI+VIIab+IVc | E23: 0 | F23: 0 | G23: 0 | J23: cohort *V+VI+VIIab (ref.) | K23: 0 | L23: 0 | O23: 0 | P23: 0 | S23: 0 | T23: 0
D24: job+abs | E24: -0.28396893 | F24: 0.12067339 | G24: 0.01861249 | H24: * | J24: cohort* nojob,abs | K24: -0.28396893 | L24: 0.12067339 | M24: * | O24: -0.23753407 | P24: 0.085642695 | Q24: ** | S24: -0.23558862 | T24: 0.12064671 | U24: †
D25: 定数 | E25: 1.2230767 | F25: 0.14145369 | G25: 5.3111876e-18 | H25: ** | J25: _cons | K25: 1.2230767 | L25: 0.14145369 | M25: ** | O25: -1.3405642 | P25: 0.1522716 | Q25: ** | S25: -2.5312384 | T25: 0.264643 | U25: **
D26: {=[1]Sheet1!I26:I46} -> 兄弟数 | E26: -0.10705059 | F26: 0.026622535 | G26: 5.7938923e-05 | H26: ** | J26: N of First Transition | L26: =Sheet1!C2 -> 6232
D27: 父中卒ref | E27: 0 | F27: 0 | G27: 0 | J27: N of Second Transition | L27: =Sheet1!D2 -> 5502
D28: 父高卒 | E28: 0.50504807 | F28: 0.07554872 | G28: 2.3082278e-11 | H28: ** | J28: Log-likelihood | L28: =Sheet1!C3+Sheet1!D3 -> -6399.7078
D29: 父大卒 | E29: 0.91744533 | F29: 0.10279621 | G29: 4.4612441e-19 | H29: ** | J29: BIC | L29: =L28*-2+LN(L27+L26) -> 12808.786
D30: 世代40s ref | E30: 0 | F30: 0 | G30: 0
D31: 50s | E31: 0.67173992 | F31: 0.10785464 | G31: 4.7183425e-10 | H31: **
D32: 60s | E32: 0.79861247 | F32: 0.12595448 | G32: 2.2904344e-10 | H32: **
D33: 70s | E33: 1.0819615 | F33: 0.14607534 | G33: 1.2931189e-13 | H33: **
D34: 80-90s | E34: 1.0205309 | F34: 0.18033147 | G34: 1.5208515e-08 | H34: **
D35: 0 | E35: 0 | F35: 0 | G35: 0
D36: EGP I+II | E36: 1.221553 | F36: 0.40084351 | G36: 0.0023078722 | H36: **
D37: IIIab | E37: 0.90053981 | F37: 0.48923714 | G37: 0.065665232 | H37: †
D38: IVab | E38: 1.2391525 | F38: 0.39862913 | G38: 0.001880176 | H38: **
D39: V+VI+VIIab+IVc | E39: 0 | F39: 0 | G39: 0
D40: job+abs | E40: 1.134172 | F40: 0.5015904 | G40: 0.023749867 | H40: *
D41: 世代× I+II | E41: -0.065995648 | F41: 0.068573373 | G41: 0.33584407
...

Sheet Sheet1
A1: FEMALE | H1: =C22*8+C17 -> -0.42048458 | J1: 1 | Q1: 2 | X1: 3 | AE1: 4
B2: N= | C2: 6232 | D2: 5502
B3: N= | C3: -1536.1391 | D3: -4863.5686 | J3: 4 | K3: 5 | L3: 6 | M3: 7 | N3: 8 | O3: 9 | Q3: 4 | R3: 5 | S3: 6 | T3: 7 | U3: 8 | V3: 9 | X3: 4 | Y3: 5 | Z3: 6 | AA3: 7 | AB3: 8 | AC3: 9 | AE3: 4 | AF3: 5 | AG3: 6 | AH3: 7 | AI3: 8 | AJ3: 9
C4: b | D4: se | E4: z | F4: pvalue
A5: trans1 | B5: sibs | C5: -0.20293964 | D5: 0.025371019 | E5: -7.9988762 | F5: 1.255599e-15 | I5: 兄弟数 | J5: 2 | K5: 2 | L5: 2 | M5: 2 | N5: 2 | O5: 2 | Q5: 2 | R5: 2 | S5: 2 | T5: 2 | U5: 2 | V5: 2 | X5: 2 | Y5: 2 | Z5: 2 | AA5: 2 | AB5: 2 | AC5: 2 | AE5: 2 | AF5: 2 | AG5: 2 | AH5: 2 | AI5: 2 | AJ5: 2
A6: trans1 | B6: 1b.mutate_edu | C6: 0 | I6: 父中卒ref | J6: 0 | K6: 0 | L6: 0 | M6: 0 | N6: 0 | O6: 0 | Q6: 0 | R6: 0 | S6: 0 | T6: 0 | U6: 0 | V6: 0 | X6: 0 | Y6: 0 | Z6: 0 | AA6: 0 | AB6: 0 | AC6: 0 | AE6: 0 | AF6: 0 | AG6: 0 | AH6: 0 | AI6: 0 | AJ6: 0
A7: trans1 | B7: 2.mutate_edu | C7: 1.0640685 | D7: 0.13351571 | E7: 7.9696132 | F7: 1.5917172e-15 | I7: 父高卒 | J7: 0 | K7: 0 | L7: 0 | M7: 0 | N7: 0 | O7: 0 | Q7: 0 | R7: 0 | S7: 0 | T7: 0 | U7: 0 | V7: 0 | X7: 0 | Y7: 0 | Z7: 0 | AA7: 0 | AB7: 0 | AC7: 0 | AE7: 0 | AF7: 0 | AG7: 0 | AH7: 0 | AI7: 0 | AJ7: 0
A8: trans1 | B8: 3.mutate_edu | C8: 1.4580361 | D8: 0.23472685 | E8: 6.2116288 | F8: 5.2438177e-10 | I8: 父大卒 | J8: 1 | K8: 1 | L8: 1 | M8: 1 | N8: 1 | O8: 1 | Q8: 1 | R8: 1 | S8: 1 | T8: 1 | U8: 1 | V8: 1 | X8: 1 | Y8: 1 | Z8: 1 | AA8: 1 | AB8: 1 | AC8: 1 | AE8: 1 | AF8: 1 | AG8: 1 | AH8: 1 | AI8: 1 | AJ8: 1
A9: trans1 | B9: 4b.pcoh5 | C9: 0 | I9: 世代40s ref | J9: {=_xlfn.MUNIT(5)} -> 1 | K9: 0 | L9: 0 | M9: 0 | N9: 0 | Q9: {=_xlfn.MUNIT(5)} -> 1 | R9: 0 | S9: 0 | T9: 0 | U9: 0 | X9: {=_xlfn.MUNIT(5)} -> 1 | Y9: 0 | Z9: 0 | AA9: 0 | AB9: 0 | AE9: {=_xlfn.MUNIT(5)} -> 1 | AF9: 0 | AG9: 0 | AH9: 0 | AI9: 0
A10: trans1 | B10: 5.pcoh5 | C10: 1.629385 | D10: 0.14093583 | E10: 11.561184 | F10: 6.4808968e-31 | I10: 50s | J10: 0 | K10: 1 | L10: 0 | M10: 0 | N10: 0 | Q10: 0 | R10: 1 | S10: 0 | T10: 0 | U10: 0 | X10: 0 | Y10: 1 | Z10: 0 | AA10: 0 | AB10: 0 | AE10: 0 | AF10: 1 | AG10: 0 | AH10: 0 | AI10: 0
A11: trans1 | B11: 6.pcoh5 | C11: 2.8741958 | D11: 0.28132582 | E11: 10.216609 | F11: 1.6708422e-24 | I11: 60s | J11: 0 | K11: 0 | L11: 1 | M11: 0 | N11: 0 | Q11: 0 | R11: 0 | S11: 1 | T11: 0 | U11: 0 | X11: 0 | Y11: 0 | Z11: 1 | AA11: 0 | AB11: 0 | AE11: 0 | AF11: 0 | AG11: 1 | AH11: 0 | AI11: 0
A12: trans1 | B12: 7.pcoh5 | C12: 2.3913043 | D12: 0.27660405 | E12: 8.6452254 | F12: 5.3699209e-18 | I12: 70s | J12: 0 | K12: 0 | L12: 0 | M12: 1 | N12: 0 | Q12: 0 | R12: 0 | S12: 0 | T12: 1 | U12: 0 | X12: 0 | Y12: 0 | Z12: 0 | AA12: 1 | AB12: 0 | AE12: 0 | AF12: 0 | AG12: 0 | AH12: 1 | AI12: 0
A13: trans1 | B13: 8.pcoh5 | C13: 2.4848283 | D13: 0.3906858 | E13: 6.3601704 | F13: 2.015301e-10 | I13: 80-90s | J13: 0 | K13: 0 | L13: 0 | M13: 0 | N13: 1 | O13: 1 | Q13: 0 | R13: 0 | S13: 0 | T13: 0 | U13: 1 | V13: 1 | X13: 0 | Y13: 0 | Z13: 0 | AA13: 0 | AB13: 1 | AC13: 1 | AE13: 0 | AF13: 0 | AG13: 0 | AH13: 0 | AI13: 1 | AJ13: 1
A14: trans1 | B14: o.pcoh5 | C14: 0
A15: trans1 | B15: 1.fegp4 | C15: 3.0025493 | D15: 1.3989822 | E15: 2.1462384 | F15: 0.031853962 | I15: EGP I+II | J15: 1 | K15: 1 | L15: 1 | M15: 1 | N15: 1 | O15: 1 | Q15: 0 | R15: 0 | S15: 0 | T15: 0 | U15: 0 | V15: 0 | X15: 0 | Y15: 0 | Z15: 0 | AA15: 0 | AB15: 0 | AC15: 0 | AE15: 0 | AF15: 0 | AG15: 0 | AH15: 0 | AI15: 0 | AJ15: 0
A16: trans1 | B16: 2.fegp4 | C16: 0.25615819 | D16: 1.220349 | E16: 0.20990569 | F16: 0.83374128 | I16: IIIab | J16: 0 | K16: 0 | L16: 0 | M16: 0 | N16: 0 | O16: 0 | Q16: 1 | R16: 1 | S16: 1 | T16: 1 | U16: 1 | V16: 1 | X16: 0 | Y16: 0 | Z16: 0 | AA16: 0 | AB16: 0 | AC16: 0 | AE16: 0 | AF16: 0 | AG16: 0 | AH16: 0 | AI16: 0 | AJ16: 0
A17: trans1 | B17: 3.fegp4 | C17: 1.6322587 | D17: 0.58501282 | E17: 2.7901247 | F17: 0.0052687737 | I17: IVab | J17: 0 | K17: 0 | L17: 0 | M17: 0 | N17: 0 | O17: 0 | Q17: 0 | R17: 0 | S17: 0 | T17: 0 | U17: 0 | V17: 0 | X17: 1 | Y17: 1 | Z17: 1 | AA17: 1 | AB17: 1 | AC17: 1 | AE17: 0 | AF17: 0 | AG17: 0 | AH17: 0 | AI17: 0 | AJ17: 0
A18: trans1 | B18: 4b.fegp4 | C18: 0 | I18: V+VI+VIIab+IVc | J18: 0 | K18: 0 | L18: 0 | M18: 0 | N18: 0 | O18: 0 | Q18: 0 | R18: 0 | S18: 0 | T18: 0 | U18: 0 | V18: 0 | X18: 0 | Y18: 0 | Z18: 0 | AA18: 0 | AB18: 0 | AC18: 0 | AE18: 1 | AF18: 1 | AG18: 1 | AH18: 1 | AI18: 1 | AJ18: 1
A19: trans1 | B19: 5.fegp4 | C19: 0.75071677 | D19: 0.55866729 | E19: 1.3437636 | F19: 0.17902484 | I19: job+abs | J19: 0 | K19: 0 | L19: 0 | M19: 0 | N19: 0 | O19: 0 | Q19: 0 | R19: 0 | S19: 0 | T19: 0 | U19: 0 | V19: 0 | X19: 0 | Y19: 0 | Z19: 0 | AA19: 0 | AB19: 0 | AC19: 0 | AE19: 0 | AF19: 0 | AG19: 0 | AH19: 0 | AI19: 0 | AJ19: 0
A20: trans1 | B20: 1.fegp4#c.pcoh5 | C20: -0.15880867 | D20: 0.30548084 | E20: -0.5198646 | F20: 0.60315795 | I20: 世代× I+II | J20: =J15*J$3 -> 4 | K20: =K15*K$3 -> 5 | L20: =L15*L$3 -> 6 | M20: =M15*M$3 -> 7 | N20: =N15*N$3 -> 8 | O20: =O15*O$3 -> 9 | Q20: =Q15*Q$3 -> 0 | R20: =R15*R$3 -> 0 | S20: =S15*S$3 -> 0 | T20: =T15*T$3 -> 0 | U20: =U15*U$3 -> 0 | V20: =V15*V$3 -> 0 | X20: =X15*X$3 -> 0 | Y20: =Y15*Y$3 -> 0 | Z20: =Z15*Z$3 -> 0 | AA20: =AA15*AA$3 -> 0 | AB20: =AB15*AB$3 -> 0 | AC20: =AC15*AC$3 -> 0 | AE20: =AE15*AE$3 -> 0 | AF20: =AF15*AF$3 -> 0 | AG20: =AG15*AG$3 -> 0 | AH20: =AH15*AH$3 -> 0 | AI20: =AI15*AI$3 -> 0 | AJ20: =AJ15*AJ$3 -> 0
A21: trans1 | B21: 2.fegp4#c.pcoh5 | C21: 0.1659776 | D21: 0.27636959 | E21: 0.60056393 | F21: 0.54813047 | I21: IIIab | J21: =J16*J$3 -> 0 | K21: =K16*K$3 -> 0 | L21: =L16*L$3 -> 0 | M21: =M16*M$3 -> 0 | N21: =N16*N$3 -> 0 | O21: =O16*O$3 -> 0 | Q21: =Q16*Q$3 -> 4 | R21: =R16*R$3 -> 5 | S21: =S16*S$3 -> 6 | T21: =T16*T$3 -> 7 | U21: =U16*U$3 -> 8 | V21: =V16*V$3 -> 9 | X21: =X16*X$3 -> 0 | Y21: =Y16*Y$3 -> 0 | Z21: =Z16*Z$3 -> 0 | AA21: =AA16*AA$3 -> 0 | AB21: =AB16*AB$3 -> 0 | AC21: =AC16*AC$3 -> 0 | AE21: =AE16*AE$3 -> 0 | AF21: =AF16*AF$3 -> 0 | AG21: =AG16*AG$3 -> 0 | AH21: =AH16*AH$3 -> 0 | AI21: =AI16*AI$3 -> 0 | AJ21: =AJ16*AJ$3 -> 0
A22: trans1 | B22: 3.fegp4#c.pcoh5 | C22: -0.25659291 | D22: 0.12826466 | E22: -2.0004958 | F22: 0.045446758 | I22: IVab | J22: =J17*J$3 -> 0 | K22: =K17*K$3 -> 0 | L22: =L17*L$3 -> 0 | M22: =M17*M$3 -> 0 | N22: =N17*N$3 -> 0 | O22: =O17*O$3 -> 0 | Q22: =Q17*Q$3 -> 0 | R22: =R17*R$3 -> 0 | S22: =S17*S$3 -> 0 | T22: =T17*T$3 -> 0 | U22: =U17*U$3 -> 0 | V22: =V17*V$3 -> 0 | X22: =X17*X$3 -> 4 | Y22: =Y17*Y$3 -> 5 | Z22: =Z17*Z$3 -> 6 | AA22: =AA17*AA$3 -> 7 | AB22: =AB17*AB$3 -> 8 | AC22: =AC17*AC$3 -> 9 | AE22: =AE17*AE$3 -> 0 | AF22: =AF17*AF$3 -> 0 | AG22: =AG17*AG$3 -> 0 | AH22: =AH17*AH$3 -> 0 | AI22: =AI17*AI$3 -> 0 | AJ22: =AJ17*AJ$3 -> 0
A23: trans1 | B23: 4b.fegp4#co.pcoh5 | C23: 0 | I23: V+VI+VIIab+IVc | J23: =J18*J$3 -> 0 | K23: =K18*K$3 -> 0 | L23: =L18*L$3 -> 0 | M23: =M18*M$3 -> 0 | N23: =N18*N$3 -> 0 | O23: =O18*O$3 -> 0 | Q23: =Q18*Q$3 -> 0 | R23: =R18*R$3 -> 0 | S23: =S18*S$3 -> 0 | T23: =T18*T$3 -> 0 | U23: =U18*U$3 -> 0 | V23: =V18*V$3 -> 0 | X23: =X18*X$3 -> 0 | Y23: =Y18*Y$3 -> 0 | Z23: =Z18*Z$3 -> 0 | AA23: =AA18*AA$3 -> 0 | AB23: =AB18*AB$3 -> 0 | AC23: =AC18*AC$3 -> 0 | AE23: =AE18*AE$3 -> 4 | AF23: =AF18*AF$3 -> 5 | AG23: =AG18*AG$3 -> 6 | AH23: =AH18*AH$3 -> 7 | AI23: =AI18*AI$3 -> 8 | AJ23: =AJ18*AJ$3 -> 9
A24: trans1 | B24: 5.fegp4#c.pcoh5 | C24: -0.28396893 | D24: 0.12067339 | E24: -2.3532026 | F24: 0.01861249 | I24: job+abs | J24: =J19*J$3 -> 0 | K24: =K19*K$3 -> 0 | L24: =L19*L$3 -> 0 | M24: =M19*M$3 -> 0 | N24: =N19*N$3 -> 0 | O24: =O19*O$3 -> 0 | Q24: =Q19*Q$3 -> 0 | R24: =R19*R$3 -> 0 | S24: =S19*S$3 -> 0 | T24: =T19*T$3 -> 0 | U24: =U19*U$3 -> 0 | V24: =V19*V$3 -> 0 | X24: =X19*X$3 -> 0 | Y24: =Y19*Y$3 -> 0 | Z24: =Z19*Z$3 -> 0 | AA24: =AA19*AA$3 -> 0 | AB24: =AB19*AB$3 -> 0 | AC24: =AC19*AC$3 -> 0 | AE24: =AE19*AE$3 -> 0 | AF24: =AF19*AF$3 -> 0 | AG24: =AG19*AG$3 -> 0 | AH24: =AH19*AH$3 -> 0 | AI24: =AI19*AI$3 -> 0 | AJ24: =AJ19*AJ$3 -> 0
A25: trans1 | B25: _cons | C25: 1.2230767 | D25: 0.14145369 | E25: 8.646481 | F25: 5.3111876e-18 | I25: 定数 | J25: 1 | K25: 1 | L25: 1 | M25: 1 | N25: 1 | O25: 1 | Q25: 1 | R25: 1 | S25: 1 | T25: 1 | U25: 1 | V25: 1 | X25: 1 | Y25: 1 | Z25: 1 | AA25: 1 | AB25: 1 | AC25: 1 | AE25: 1 | AF25: 1 | AG25: 1 | AH25: 1 | AI25: 1 | AJ25: 1
A26: Jrcol_Tech | B26: sibs | C26: -0.10705059 | D26: 0.026622535 | E26: -4.0210515 | F26: 5.7938923e-05 | I26: {=I$5:I$25} -> 兄弟数 | J26: {=J$5:O$25} -> 2 | K26: 2 | L26: 2 | M26: 2 | N26: 2 | O26: 2 | Q26: {=Q$5:V$25} -> 2 | R26: 2 | S26: 2 | T26: 2 | U26: 2 | V26: 2 | X26: {=X$5:AC$25} -> 2 | Y26: 2 | Z26: 2 | AA26: 2 | AB26: 2 | AC26: 2 | AE26: {=AE$5:AJ$25} -> 2 | AF26: 2 | AG26: 2 | AH26: 2 | AI26: 2 | AJ26: 2
A27: Jrcol_Tech | B27: 1b.mutate_edu | C27: 0 | I27: 父中卒ref | J27: 0 | K27: 0 | L27: 0 | M27: 0 | N27: 0 | O27: 0 | Q27: 0 | R27: 0 | S27: 0 | T27: 0 | U27: 0 | V27: 0 | X27: 0 | Y27: 0 | Z27: 0 | AA27: 0 | AB27: 0 | AC27: 0 | AE27: 0 | AF27: 0 | AG27: 0 | AH27: 0 | AI27: 0 | AJ27: 0
A28: Jrcol_Tech | B28: 2.mutate_edu | C28: 0.50504807 | D28: 0.07554872 | E28: 6.6850646 | F28: 2.3082278e-11 | I28: 父高卒 | J28: 0 | K28: 0 | L28: 0 | M28: 0 | N28: 0 | O28: 0 | Q28: 0 | R28: 0 | S28: 0 | T28: 0 | U28: 0 | V28: 0 | X28: 0 | Y28: 0 | Z28: 0 | AA28: 0 | AB28: 0 | AC28: 0 | AE28: 0 | AF28: 0 | AG28: 0 | AH28: 0 | AI28: 0 | AJ28: 0
A29: Jrcol_Tech | B29: 3.mutate_edu | C29: 0.91744533 | D29: 0.10279621 | E29: 8.9248945 | F29: 4.4612441e-19 | I29: 父大卒 | J29: 1 | K29: 1 | L29: 1 | M29: 1 | N29: 1 | O29: 1 | Q29: 1 | R29: 1 | S29: 1 | T29: 1 | U29: 1 | V29: 1 | X29: 1 | Y29: 1 | Z29: 1 | AA29: 1 | AB29: 1 | AC29: 1 | AE29: 1 | AF29: 1 | AG29: 1 | AH29: 1 | AI29: 1 | AJ29: 1
A30: Jrcol_Tech | B30: 4b.pcoh5 | C30: 0 | I30: 世代40s ref | J30: 1 | K30: 0 | L30: 0 | M30: 0 | N30: 0 | O30: 0 | Q30: 1 | R30: 0 | S30: 0 | T30: 0 | U30: 0 | V30: 0 | X30: 1 | Y30: 0 | Z30: 0 | AA30: 0 | AB30: 0 | AC30: 0 | AE30: 1 | AF30: 0 | AG30: 0 | AH30: 0 | AI30: 0 | AJ30: 0
A31: Jrcol_Tech | B31: 5.pcoh5 | C31: 0.67173992 | D31: 0.10785464 | E31: 6.2281968 | F31: 4.7183425e-10 | I31: 50s | J31: 0 | K31: 1 | L31: 0 | M31: 0 | N31: 0 | O31: 0 | Q31: 0 | R31: 1 | S31: 0 | T31: 0 | U31: 0 | V31: 0 | X31: 0 | Y31: 1 | Z31: 0 | AA31: 0 | AB31: 0 | AC31: 0 | AE31: 0 | AF31: 1 | AG31: 0 | AH31: 0 | AI31: 0 | AJ31: 0
A32: Jrcol_Tech | B32: 6.pcoh5 | C32: 0.79861247 | D32: 0.12595448 | E32: 6.3404847 | F32: 2.2904344e-10 | I32: 60s | J32: 0 | K32: 0 | L32: 1 | M32: 0 | N32: 0 | O32: 0 | Q32: 0 | R32: 0 | S32: 1 | T32: 0 | U32: 0 | V32: 0 | X32: 0 | Y32: 0 | Z32: 1 | AA32: 0 | AB32: 0 | AC32: 0 | AE32: 0 | AF32: 0 | AG32: 1 | AH32: 0 | AI32: 0 | AJ32: 0
A33: Jrcol_Tech | B33: 7.pcoh5 | C33: 1.0819615 | D33: 0.14607534 | E33: 7.4068733 | F33: 1.2931189e-13 | I33: 70s | J33: 0 | K33: 0 | L33: 0 | M33: 1 | N33: 0 | O33: 0 | Q33: 0 | R33: 0 | S33: 0 | T33: 1 | U33: 0 | V33: 0 | X33: 0 | Y33: 0 | Z33: 0 | AA33: 1 | AB33: 0 | AC33: 0 | AE33: 0 | AF33: 0 | AG33: 0 | AH33: 1 | AI33: 0 | AJ33: 0
A34: Jrcol_Tech | B34: 8.pcoh5 | C34: 1.0205309 | D34: 0.18033147 | E34: 5.6591945 | F34: 1.5208515e-08 | I34: 80-90s | J34: 0 | K34: 0 | L34: 0 | M34: 0 | N34: 1 | O34: 1 | Q34: 0 | R34: 0 | S34: 0 | T34: 0 | U34: 1 | V34: 1 | X34: 0 | Y34: 0 | Z34: 0 | AA34: 0 | AB34: 1 | AC34: 1 | AE34: 0 | AF34: 0 | AG34: 0 | AH34: 0 | AI34: 1 | AJ34: 1
A35: Jrcol_Tech | B35: o.pcoh5 | C35: 0 | I35: 0 | J35: 0 | K35: 0 | L35: 0 | M35: 0 | N35: 0 | O35: 0 | Q35: 0 | R35: 0 | S35: 0 | T35: 0 | U35: 0 | V35: 0 | X35: 0 | Y35: 0 | Z35: 0 | AA35: 0 | AB35: 0 | AC35: 0 | AE35: 0 | AF35: 0 | AG35: 0 | AH35: 0 | AI35: 0 | AJ35: 0
A36: Jrcol_Tech | B36: 1.fegp4 | C36: 1.221553 | D36: 0.40084351 | E36: 3.0474561 | F36: 0.0023078722 | I36: EGP I+II | J36: 1 | K36: 1 | L36: 1 | M36: 1 | N36: 1 | O36: 1 | Q36: 0 | R36: 0 | S36: 0 | T36: 0 | U36: 0 | V36: 0 | X36: 0 | Y36: 0 | Z36: 0 | AA36: 0 | AB36: 0 | AC36: 0 | AE36: 0 | AF36: 0 | AG36: 0 | AH36: 0 | AI36: 0 | AJ36: 0
A37: Jrcol_Tech | B37: 2.fegp4 | C37: 0.90053981 | D37: 0.48923714 | E37: 1.8407021 | F37: 0.065665232 | I37: IIIab | J37: 0 | K37: 0 | L37: 0 | M37: 0 | N37: 0 | O37: 0 | Q37: 1 | R37: 1 | S37: 1 | T37: 1 | U37: 1 | V37: 1 | X37: 0 | Y37: 0 | Z37: 0 | AA37: 0 | AB37: 0 | AC37: 0 | AE37: 0 | AF37: 0 | AG37: 0 | AH37: 0 | AI37: 0 | AJ37: 0
A38: Jrcol_Tech | B38: 3.fegp4 | C38: 1.2391525 | D38: 0.39862913 | E38: 3.1085346 | F38: 0.001880176 | I38: IVab | J38: 0 | K38: 0 | L38: 0 | M38: 0 | N38: 0 | O38: 0 | Q38: 0 | R38: 0 | S38: 0 | T38: 0 | U38: 0 | V38: 0 | X38: 1 | Y38: 1 | Z38: 1 | AA38: 1 | AB38: 1 | AC38: 1 | AE38: 0 | AF38: 0 | AG38: 0 | AH38: 0 | AI38: 0 | AJ38: 0
A39: Jrcol_Tech | B39: 4b.fegp4 | C39: 0 | I39: V+VI+VIIab+IVc | J39: 0 | K39: 0 | L39: 0 | M39: 0 | N39: 0 | O39: 0 | Q39: 0 | R39: 0 | S39: 0 | T39: 0 | U39: 0 | V39: 0 | X39: 0 | Y39: 0 | Z39: 0 | AA39: 0 | AB39: 0 | AC39: 0 | AE39: 1 | AF39: 1 | AG39: 1 | AH39: 1 | AI39: 1 | AJ39: 1
A40: Jrcol_Tech | B40: 5.fegp4 | C40: 1.134172 | D40: 0.5015904 | E40: 2.2611517 | F40: 0.023749867 | I40: job+abs | J40: 0 | K40: 0 | L40: 0 | M40: 0 | N40: 0 | O40: 0 | Q40: 0 | R40: 0 | S40: 0 | T40: 0 | U40: 0 | V40: 0 | X40: 0 | Y40: 0 | Z40: 0 | AA40: 0 | AB40: 0 | AC40: 0 | AE40: 0 | AF40: 0 | AG40: 0 | AH40: 0 | AI40: 0 | AJ40: 0
...

Sheet Sheet2
G1: =_xlfn.TEXTJOIN("",TRUE,G3:G4) -> I+II1950s | H1: =_xlfn.TEXTJOIN("",TRUE,H3:H4) -> IIIab1950s | I1: =_xlfn.TEXTJOIN("",TRUE,I3:I4) -> IVab1950s | J1: =_xlfn.TEXTJOIN("",TRUE,J3:J4) -> V+VI+VIIab1950s | K1: =_xlfn.TEXTJOIN("",TRUE,K3:K4) | L1: =_xlfn.TEXTJOIN("",TRUE,L3:L4) -> I+II1960s | M1: =_xlfn.TEXTJOIN("",TRUE,M3:M4) -> IIIab1960s | N1: =_xlfn.TEXTJOIN("",TRUE,N3:N4) -> IVab1960s | ... Y1: =_xlfn.TEXTJOIN("",TRUE,Y3:Y4) -> V+VI+VIIab1980s
G3: I+II | H3: IIIab | I3: IVab | J3: V+VI+VIIab | L3: I+II | M3: IIIab | N3: IVab | O3: V+VI+VIIab | Q3: I+II | R3: IIIab | S3: IVab | T3: V+VI+VIIab | V3: I+II | W3: IIIab | X3: IVab | Y3: V+VI+VIIab
G4: 1950s | H4: 1950s | I4: 1950s | J4: 1950s | L4: 1960s | M4: 1960s | N4: 1960s | O4: 1960s | Q4: 1970s | R4: 1970s | S4: 1970s | T4: 1970s | V4: 1980s | W4: 1980s | X4: 1980s | Y4: 1980s
E8: Men | G8: 1950s | L8: 1960s | Q8: 1970s | V8: 1980s
G9: I+II | H9: IIIab | I9: IVab | J9: V+VI+VIIab | L9: I+II | M9: IIIab | N9: IVab | O9: V+VI+VIIab | Q9: I+II | R9: IIIab | S9: IVab | T9: V+VI+VIIab | V9: I+II | W9: IIIab | X9: IVab | Y9: V+VI+VIIab
A10: =_xlfn.TEXTJOIN("",TRUE,B10:C10) -> T1lambda | B10: T1 | C10: lambda | E10: T1 | F10: coefficient | G10: =INDEX(Sheet1!$E$69:$AJ$150,MATCH($A10,Sheet1!$E$69:$E$150,0),MATCH(G$1,Sheet1!$E$69:$AJ$69,0)) -> 2.208506 | H10: =INDEX(Sheet1!$E$69:$AJ$150,MATCH($A10,Sheet1!$E$69:$E$150,0),MATCH(H$1,Sheet1!$E$69:$AJ$69,0)) -> 1.0860462 | I10: =INDEX(Sheet1!$E$69:$AJ$150,MATCH($A10,Sheet1!$E$69:$E$150,0),MATCH(I$1,Sheet1!$E$69:$AJ$69,0)) -> 0.34929416 | J10: =INDEX(Sheet1!$E$69:$AJ$150,MATCH($A10,Sheet1!$E$69:$E$150,0),MATCH(J$1,Sheet1!$E$69:$AJ$69,0)) -> 0 | L10: =INDEX(Sheet1!$E$69:$AJ$150,MATCH($A10,Sheet1!$E$69:$E$150,0),MATCH(L$1,Sheet1!$E$69:$AJ$69,0)) -> 2.0496973 | M10: =INDEX(Sheet1!$E$69:$AJ$150,MATCH($A10,Sheet1!$E$69:$E$150,0),MATCH(M$1,Sheet1!$E$69:$AJ$69,0)) -> 1.2520238 | N10: =INDEX(Sheet1!$E$69:$AJ$150,MATCH($A10,Sheet1!$E$69:$E$150,0),MATCH(N$1,Sheet1!$E$69:$AJ$69,0)) -> 0.092701248 | O10: =INDEX(Sheet1!$E$69:$AJ$150,MATCH($A10,Sheet1!$E$69:$E$150,0),MATCH(O$1,Sheet1!$E$69:$AJ$69,0)) -> 0 | Q10: =INDEX(Sheet1!$E$69:$AJ$150,MATCH($A10,Sheet1!$E$69:$E$150,0),MATCH(Q$1,Sheet1!$E$69:$AJ$69,0)) -> 1.8908886 | R10: =INDEX(Sheet1!$E$69:$AJ$150,MATCH($A10,Sheet1!$E$69:$E$150,0),MATCH(R$1,Sheet1!$E$69:$AJ$69,0)) -> 1.4180014 | S10: =INDEX(Sheet1!$E$69:$AJ$150,MATCH($A10,Sheet1!$E$69:$E$150,0),MATCH(S$1,Sheet1!$E$69:$AJ$69,0)) -> -0.16389167 | T10: =INDEX(Sheet1!$E$69:$AJ$150,MATCH($A10,Sheet1!$E$69:$E$150,0),MATCH(T$1,Sheet1!$E$69:$AJ$69,0)) -> 0 | V10: =INDEX(Sheet1!$E$69:$AJ$150,MATCH($A10,Sheet1!$E$69:$E$150,0),MATCH(V$1,Sheet1!$E$69:$AJ$69,0)) -> 1.7320799 | W10: =INDEX(Sheet1!$E$69:$AJ$150,MATCH($A10,Sheet1!$E$69:$E$150,0),MATCH(W$1,Sheet1!$E$69:$AJ$69,0)) -> 1.583979 | X10: =INDEX(Sheet1!$E$69:$AJ$150,MATCH($A10,Sheet1!$E$69:$E$150,0),MATCH(X$1,Sheet1!$E$69:$AJ$69,0)) -> -0.42048458 | Y10: =INDEX(Sheet1!$E$69:$AJ$150,MATCH($A10,Sheet1!$E$69:$E$150,0),MATCH(Y$1,Sheet1!$E$69:$AJ$69,0)) -> 0
A11: =_xlfn.TEXTJOIN("",TRUE,B11:C11) -> T1e^lambda-1 | B11: T1 | C11: e^lambda-1 | F11: Effect | G11: =INDEX(Sheet1!$E$69:$AJ$150,MATCH($A11,Sheet1!$E$69:$E$150,0),MATCH(G$1,Sheet1!$E$69:$AJ$69,0)) -> 8.1021073 | H11: =INDEX(Sheet1!$E$69:$AJ$150,MATCH($A11,Sheet1!$E$69:$E$150,0),MATCH(H$1,Sheet1!$E$69:$AJ$69,0)) -> 1.9625376 | I11: =INDEX(Sheet1!$E$69:$AJ$150,MATCH($A11,Sheet1!$E$69:$E$150,0),MATCH(I$1,Sheet1!$E$69:$AJ$69,0)) -> 0.41806627 | J11: =INDEX(Sheet1!$E$69:$AJ$150,MATCH($A11,Sheet1!$E$69:$E$150,0),MATCH(J$1,Sheet1!$E$69:$AJ$69,0)) -> 0 | L11: =INDEX(Sheet1!$E$69:$AJ$150,MATCH($A11,Sheet1!$E$69:$E$150,0),MATCH(L$1,Sheet1!$E$69:$AJ$69,0)) -> 6.76555 | M11: =INDEX(Sheet1!$E$69:$AJ$150,MATCH($A11,Sheet1!$E$69:$E$150,0),MATCH(M$1,Sheet1!$E$69:$AJ$69,0)) -> 2.4974139 | N11: =INDEX(Sheet1!$E$69:$AJ$150,MATCH($A11,Sheet1!$E$69:$E$150,0),MATCH(N$1,Sheet1!$E$69:$AJ$69,0)) -> 0.097133916 | O11: =INDEX(Sheet1!$E$69:$AJ$150,MATCH($A11,Sheet1!$E$69:$E$150,0),MATCH(O$1,Sheet1!$E$69:$AJ$69,0)) -> 0 | Q11: =INDEX(Sheet1!$E$69:$AJ$150,MATCH($A11,Sheet1!$E$69:$E$150,0),MATCH(Q$1,Sheet1!$E$69:$AJ$69,0)) -> 5.6252534 | R11: =INDEX(Sheet1!$E$69:$AJ$150,MATCH($A11,Sheet1!$E$69:$E$150,0),MATCH(R$1,Sheet1!$E$69:$AJ$69,0)) -> 3.1288603 | S11: =INDEX(Sheet1!$E$69:$AJ$150,MATCH($A11,Sheet1!$E$69:$E$150,0),MATCH(S$1,Sheet1!$E$69:$AJ$69,0)) -> -0.15116603 | T11: =INDEX(Sheet1!$E$69:$AJ$150,MATCH($A11,Sheet1!$E$69:$E$150,0),MATCH(T$1,Sheet1!$E$69:$AJ$69,0)) -> 0 | V11: =INDEX(Sheet1!$E$69:$AJ$150,MATCH($A11,Sheet1!$E$69:$E$150,0),MATCH(V$1,Sheet1!$E$69:$AJ$69,0)) -> 4.6523983 | W11: =INDEX(Sheet1!$E$69:$AJ$150,MATCH($A11,Sheet1!$E$69:$E$150,0),MATCH(W$1,Sheet1!$E$69:$AJ$69,0)) -> 3.8743123 | X11: =INDEX(Sheet1!$E$69:$AJ$150,MATCH($A11,Sheet1!$E$69:$E$150,0),MATCH(X$1,Sheet1!$E$69:$AJ$69,0)) -> -0.34327149 | Y11: =INDEX(Sheet1!$E$69:$AJ$150,MATCH($A11,Sheet1!$E$69:$E$150,0),MATCH(Y$1,Sheet1!$E$69:$AJ$69,0)) -> 0
A12: =_xlfn.TEXTJOIN("",TRUE,B12:C12) -> T1R | B12: T1 | C12: R | F12: At Risk | G12: =INDEX(Sheet1!$E$69:$AJ$150,MATCH($A12,Sheet1!$E$69:$E$150,0),MATCH(G$1,Sheet1!$E$69:$AJ$69,0)) -> 1 | H12: =INDEX(Sheet1!$E$69:$AJ$150,MATCH($A12,Sheet1!$E$69:$E$150,0),MATCH(H$1,Sheet1!$E$69:$AJ$69,0)) -> 1 | I12: =INDEX(Sheet1!$E$69:$AJ$150,MATCH($A12,Sheet1!$E$69:$E$150,0),MATCH(I$1,Sheet1!$E$69:$AJ$69,0)) -> 1 | J12: =INDEX(Sheet1!$E$69:$AJ$150,MATCH($A12,Sheet1!$E$69:$E$150,0),MATCH(J$1,Sheet1!$E$69:$AJ$69,0)) -> 1 | L12: =INDEX(Sheet1!$E$69:$AJ$150,MATCH($A12,Sheet1!$E$69:$E$150,0),MATCH(L$1,Sheet1!$E$69:$AJ$69,0)) -> 1 | M12: =INDEX(Sheet1!$E$69:$AJ$150,MATCH($A12,Sheet1!$E$69:$E$150,0),MATCH(M$1,Sheet1!$E$69:$AJ$69,0)) -> 1 | N12: =INDEX(Sheet1!$E$69:$AJ$150,MATCH($A12,Sheet1!$E$69:$E$150,0),MATCH(N$1,Sheet1!$E$69:$AJ$69,0)) -> 1 | O12: =INDEX(Sheet1!$E$69:$AJ$150,MATCH($A12,Sheet1!$E$69:$E$150,0),MATCH(O$1,Sheet1!$E$69:$AJ$69,0)) -> 1 | Q12: =INDEX(Sheet1!$E$69:$AJ$150,MATCH($A12,Sheet1!$E$69:$E$150,0),MATCH(Q$1,Sheet1!$E$69:$AJ$69,0)) -> 1 | R12: =INDEX(Sheet1!$E$69:$AJ$150,MATCH($A12,Sheet1!$E$69:$E$150,0),MATCH(R$1,Sheet1!$E$69:$AJ$69,0)) -> 1 | S12: =INDEX(Sheet1!$E$69:$AJ$150,MATCH($A12,Sheet1!$E$69:$E$150,0),MATCH(S$1,Sheet1!$E$69:$AJ$69,0)) -> 1 | T12: =INDEX(Sheet1!$E$69:$AJ$150,MATCH($A12,Sheet1!$E$69:$E$150,0),MATCH(T$1,Sheet1!$E$69:$AJ$69,0)) -> 1 | V12: =INDEX(Sheet1!$E$69:$AJ$150,MATCH($A12,Sheet1!$E$69:$E$150,0),MATCH(V$1,Sheet1!$E$69:$AJ$69,0)) -> 1 | W12: =INDEX(Sheet1!$E$69:$AJ$150,MATCH($A12,Sheet1!$E$69:$E$150,0),MATCH(W$1,Sheet1!$E$69:$AJ$69,0)) -> 1 | X12: =INDEX(Sheet1!$E$69:$AJ$150,MATCH($A12,Sheet1!$E$69:$E$150,0),MATCH(X$1,Sheet1!$E$69:$AJ$69,0)) -> 1 | Y12: =INDEX(Sheet1!$E$69:$AJ$150,MATCH($A12,Sheet1!$E$69:$E$150,0),MATCH(Y$1,Sheet1!$E$69:$AJ$69,0)) -> 1
A13: =_xlfn.TEXTJOIN("",TRUE,B13:C13) -> T1D | B13: T1 | C13: D | F13: Differenciate | G13: =INDEX(Sheet1!$E$69:$AJ$150,MATCH($A13,Sheet1!$E$69:$E$150,0),MATCH(G$1,Sheet1!$E$69:$AJ$69,0)) -> 0.0021651104 | H13: =INDEX(Sheet1!$E$69:$AJ$150,MATCH($A13,Sheet1!$E$69:$E$150,0),MATCH(H$1,Sheet1!$E$69:$AJ$69,0)) -> 0.0066217796 | I13: =INDEX(Sheet1!$E$69:$AJ$150,MATCH($A13,Sheet1!$E$69:$E$150,0),MATCH(I$1,Sheet1!$E$69:$AJ$69,0)) -> 0.013732782 | J13: =INDEX(Sheet1!$E$69:$AJ$150,MATCH($A13,Sheet1!$E$69:$E$150,0),MATCH(J$1,Sheet1!$E$69:$AJ$69,0)) -> 0.019360601 | L13: =INDEX(Sheet1!$E$69:$AJ$150,MATCH($A13,Sheet1!$E$69:$E$150,0),MATCH(L$1,Sheet1!$E$69:$AJ$69,0)) -> 0.00074237247 | M13: =INDEX(Sheet1!$E$69:$AJ$150,MATCH($A13,Sheet1!$E$69:$E$150,0),MATCH(M$1,Sheet1!$E$69:$AJ$69,0)) -> 0.0016468403 | N13: =INDEX(Sheet1!$E$69:$AJ$150,MATCH($A13,Sheet1!$E$69:$E$150,0),MATCH(N$1,Sheet1!$E$69:$AJ$69,0)) -> 0.0052307976 | O13: =INDEX(Sheet1!$E$69:$AJ$150,MATCH($A13,Sheet1!$E$69:$E$150,0),MATCH(O$1,Sheet1!$E$69:$AJ$69,0)) -> 0.0057359542 | Q13: =INDEX(Sheet1!$E$69:$AJ$150,MATCH($A13,Sheet1!$E$69:$E$150,0),MATCH(Q$1,Sheet1!$E$69:$AJ$69,0)) -> 0.0014043149 | R13: =INDEX(Sheet1!$E$69:$AJ$150,MATCH($A13,Sheet1!$E$69:$E$150,0),MATCH(R$1,Sheet1!$E$69:$AJ$69,0)) -> 0.0022514626 | S13: =INDEX(Sheet1!$E$69:$AJ$150,MATCH($A13,Sheet1!$E$69:$E$150,0),MATCH(S$1,Sheet1!$E$69:$AJ$69,0)) -> 0.010856127 | T13: =INDEX(Sheet1!$E$69:$AJ$150,MATCH($A13,Sheet1!$E$69:$E$150,0),MATCH(T$1,Sheet1!$E$69:$AJ$69,0)) -> 0.00923034 | V13: =INDEX(Sheet1!$E$69:$AJ$150,MATCH($A13,Sheet1!$E$69:$E$150,0),MATCH(V$1,Sheet1!$E$69:$AJ$69,0)) -> 0.0015001587 | W13: =INDEX(Sheet1!$E$69:$AJ$150,MATCH($A13,Sheet1!$E$69:$E$150,0),MATCH(W$1,Sheet1!$E$69:$AJ$69,0)) -> 0.0017392088 | X13: =INDEX(Sheet1!$E$69:$AJ$150,MATCH($A13,Sheet1!$E$69:$E$150,0),MATCH(X$1,Sheet1!$E$69:$AJ$69,0)) -> 0.012764806 | Y13: =INDEX(Sheet1!$E$69:$AJ$150,MATCH($A13,Sheet1!$E$69:$E$150,0),MATCH(Y$1,Sheet1!$E$69:$AJ$69,0)) -> 0.0084202234
A14: =_xlfn.TEXTJOIN("",TRUE,B14:C14) -> T1G | B14: T1 | C14: G | F14: Gain | G14: =INDEX(Sheet1!$E$69:$AJ$150,MATCH($A14,Sheet1!$E$69:$E$150,0),MATCH(G$1,Sheet1!$E$69:$AJ$69,0)) -> 5.1235871 | H14: =INDEX(Sheet1!$E$69:$AJ$150,MATCH($A14,Sheet1!$E$69:$E$150,0),MATCH(H$1,Sheet1!$E$69:$AJ$69,0)) -> 5.0453762 | I14: =INDEX(Sheet1!$E$69:$AJ$150,MATCH($A14,Sheet1!$E$69:$E$150,0),MATCH(I$1,Sheet1!$E$69:$AJ$69,0)) -> 4.9836428 | J14: =INDEX(Sheet1!$E$69:$AJ$150,MATCH($A14,Sheet1!$E$69:$E$150,0),MATCH(J$1,Sheet1!$E$69:$AJ$69,0)) -> 4.7263779 | L14: =INDEX(Sheet1!$E$69:$AJ$150,MATCH($A14,Sheet1!$E$69:$E$150,0),MATCH(L$1,Sheet1!$E$69:$AJ$69,0)) -> 5.1753039 | M14: =INDEX(Sheet1!$E$69:$AJ$150,MATCH($A14,Sheet1!$E$69:$E$150,0),MATCH(M$1,Sheet1!$E$69:$AJ$69,0)) -> 5.0946393 | N14: =INDEX(Sheet1!$E$69:$AJ$150,MATCH($A14,Sheet1!$E$69:$E$150,0),MATCH(N$1,Sheet1!$E$69:$AJ$69,0)) -> 4.9837072 | O14: =INDEX(Sheet1!$E$69:$AJ$150,MATCH($A14,Sheet1!$E$69:$E$150,0),MATCH(O$1,Sheet1!$E$69:$AJ$69,0)) -> 4.7687 | Q14: =INDEX(Sheet1!$E$69:$AJ$150,MATCH($A14,Sheet1!$E$69:$E$150,0),MATCH(Q$1,Sheet1!$E$69:$AJ$69,0)) -> 5.4595757 | R14: =INDEX(Sheet1!$E$69:$AJ$150,MATCH($A14,Sheet1!$E$69:$E$150,0),MATCH(R$1,Sheet1!$E$69:$AJ$69,0)) -> 5.3845919 | S14: =INDEX(Sheet1!$E$69:$AJ$150,MATCH($A14,Sheet1!$E$69:$E$150,0),MATCH(S$1,Sheet1!$E$69:$AJ$69,0)) -> 5.2306677 | T14: =INDEX(Sheet1!$E$69:$AJ$150,MATCH($A14,Sheet1!$E$69:$E$150,0),MATCH(T$1,Sheet1!$E$69:$AJ$69,0)) -> 5.0519546 | V14: =INDEX(Sheet1!$E$69:$AJ$150,MATCH($A14,Sheet1!$E$69:$E$150,0),MATCH(V$1,Sheet1!$E$69:$AJ$69,0)) -> 5.7215067 | W14: =INDEX(Sheet1!$E$69:$AJ$150,MATCH($A14,Sheet1!$E$69:$E$150,0),MATCH(W$1,Sheet1!$E$69:$AJ$69,0)) -> 5.6472905 | X14: =INDEX(Sheet1!$E$69:$AJ$150,MATCH($A14,Sheet1!$E$69:$E$150,0),MATCH(X$1,Sheet1!$E$69:$AJ$69,0)) -> 5.4443556 | Y14: =INDEX(Sheet1!$E$69:$AJ$150,MATCH($A14,Sheet1!$E$69:$E$150,0),MATCH(Y$1,Sheet1!$E$69:$AJ$69,0)) -> 5.2844733
A15: =_xlfn.TEXTJOIN("",TRUE,B15:C15) -> T1Weight | B15: T1 | C15: Weight | F15: Weight | G15: =INDEX(Sheet1!$E$69:$AJ$150,MATCH($A15,Sheet1!$E$69:$E$150,0),MATCH(G$1,Sheet1!$E$69:$AJ$69,0)) -> 0.011093132 | H15: =INDEX(Sheet1!$E$69:$AJ$150,MATCH($A15,Sheet1!$E$69:$E$150,0),MATCH(H$1,Sheet1!$E$69:$AJ$69,0)) -> 0.033409369 | I15: =INDEX(Sheet1!$E$69:$AJ$150,MATCH($A15,Sheet1!$E$69:$E$150,0),MATCH(I$1,Sheet1!$E$69:$AJ$69,0)) -> 0.068439278 | J15: =INDEX(Sheet1!$E$69:$AJ$150,MATCH($A15,Sheet1!$E$69:$E$150,0),MATCH(J$1,Sheet1!$E$69:$AJ$69,0)) -> 0.091505518 | L15: =INDEX(Sheet1!$E$69:$AJ$150,MATCH($A15,Sheet1!$E$69:$E$150,0),MATCH(L$1,Sheet1!$E$69:$AJ$69,0)) -> 0.0038420031 | M15: =INDEX(Sheet1!$E$69:$AJ$150,MATCH($A15,Sheet1!$E$69:$E$150,0),MATCH(M$1,Sheet1!$E$69:$AJ$69,0)) -> 0.0083900572 | N15: =INDEX(Sheet1!$E$69:$AJ$150,MATCH($A15,Sheet1!$E$69:$E$150,0),MATCH(N$1,Sheet1!$E$69:$AJ$69,0)) -> 0.026068764 | O15: =INDEX(Sheet1!$E$69:$AJ$150,MATCH($A15,Sheet1!$E$69:$E$150,0),MATCH(O$1,Sheet1!$E$69:$AJ$69,0)) -> 0.027353045 | Q15: =INDEX(Sheet1!$E$69:$AJ$150,MATCH($A15,Sheet1!$E$69:$E$150,0),MATCH(Q$1,Sheet1!$E$69:$AJ$69,0)) -> 0.0076669635 | R15: =INDEX(Sheet1!$E$69:$AJ$150,MATCH($A15,Sheet1!$E$69:$E$150,0),MATCH(R$1,Sheet1!$E$69:$AJ$69,0)) -> 0.012123207 | S15: =INDEX(Sheet1!$E$69:$AJ$150,MATCH($A15,Sheet1!$E$69:$E$150,0),MATCH(S$1,Sheet1!$E$69:$AJ$69,0)) -> 0.056784796 | T15: =INDEX(Sheet1!$E$69:$AJ$150,MATCH($A15,Sheet1!$E$69:$E$150,0),MATCH(T$1,Sheet1!$E$69:$AJ$69,0)) -> 0.046631259 | V15: =INDEX(Sheet1!$E$69:$AJ$150,MATCH($A15,Sheet1!$E$69:$E$150,0),MATCH(V$1,Sheet1!$E$69:$AJ$69,0)) -> 0.0085831678 | W15: =INDEX(Sheet1!$E$69:$AJ$150,MATCH($A15,Sheet1!$E$69:$E$150,0),MATCH(W$1,Sheet1!$E$69:$AJ$69,0)) -> 0.0098218173 | X15: =INDEX(Sheet1!$E$69:$AJ$150,MATCH($A15,Sheet1!$E$69:$E$150,0),MATCH(X$1,Sheet1!$E$69:$AJ$69,0)) -> 0.069496141 | Y15: =INDEX(Sheet1!$E$69:$AJ$150,MATCH($A15,Sheet1!$E$69:$E$150,0),MATCH(Y$1,Sheet1!$E$69:$AJ$69,0)) -> 0.044496446
A16: =_xlfn.TEXTJOIN("",TRUE,B16:C16) -> T1p | B16: T1 | C16: p | F16: p | G16: =INDEX(Sheet1!$E$69:$AJ$150,MATCH($A16,Sheet1!$E$69:$E$150,0),MATCH(G$1,Sheet1!$E$69:$AJ$69,0)) -> 0.99779127 | H16: =INDEX(Sheet1!$E$69:$AJ$150,MATCH($A16,Sheet1!$E$69:$E$150,0),MATCH(H$1,Sheet1!$E$69:$AJ$69,0)) -> 0.9932448 | I16: =INDEX(Sheet1!$E$69:$AJ$150,MATCH($A16,Sheet1!$E$69:$E$150,0),MATCH(I$1,Sheet1!$E$69:$AJ$69,0)) -> 0.98599052 | J16: =INDEX(Sheet1!$E$69:$AJ$150,MATCH($A16,Sheet1!$E$69:$E$150,0),MATCH(J$1,Sheet1!$E$69:$AJ$69,0)) -> 0.98024931 | L16: =INDEX(Sheet1!$E$69:$AJ$150,MATCH($A16,Sheet1!$E$69:$E$150,0),MATCH(L$1,Sheet1!$E$69:$AJ$69,0)) -> 0.99925332 | M16: =INDEX(Sheet1!$E$69:$AJ$150,MATCH($A16,Sheet1!$E$69:$E$150,0),MATCH(M$1,Sheet1!$E$69:$AJ$69,0)) -> 0.9983436 | N16: =INDEX(Sheet1!$E$69:$AJ$150,MATCH($A16,Sheet1!$E$69:$E$150,0),MATCH(N$1,Sheet1!$E$69:$AJ$69,0)) -> 0.99473885 | O16: =INDEX(Sheet1!$E$69:$AJ$150,MATCH($A16,Sheet1!$E$69:$E$150,0),MATCH(O$1,Sheet1!$E$69:$AJ$69,0)) -> 0.99423076 | Q16: =INDEX(Sheet1!$E$69:$AJ$150,MATCH($A16,Sheet1!$E$69:$E$150,0),MATCH(Q$1,Sheet1!$E$69:$AJ$69,0)) -> 0.99858248 | R16: =INDEX(Sheet1!$E$69:$AJ$150,MATCH($A16,Sheet1!$E$69:$E$150,0),MATCH(R$1,Sheet1!$E$69:$AJ$69,0)) -> 0.99772736 | S16: =INDEX(Sheet1!$E$69:$AJ$150,MATCH($A16,Sheet1!$E$69:$E$150,0),MATCH(S$1,Sheet1!$E$69:$AJ$69,0)) -> 0.98904177 | T16: =INDEX(Sheet1!$E$69:$AJ$150,MATCH($A16,Sheet1!$E$69:$E$150,0),MATCH(T$1,Sheet1!$E$69:$AJ$69,0)) -> 0.99068285 | V16: =INDEX(Sheet1!$E$69:$AJ$150,MATCH($A16,Sheet1!$E$69:$E$150,0),MATCH(V$1,Sheet1!$E$69:$AJ$69,0)) -> 0.99848699 | W16: =INDEX(Sheet1!$E$69:$AJ$150,MATCH($A16,Sheet1!$E$69:$E$150,0),MATCH(W$1,Sheet1!$E$69:$AJ$69,0)) -> 0.99824589 | X16: =INDEX(Sheet1!$E$69:$AJ$150,MATCH($A16,Sheet1!$E$69:$E$150,0),MATCH(X$1,Sheet1!$E$69:$AJ$69,0)) -> 0.98712586 | Y16: =INDEX(Sheet1!$E$69:$AJ$150,MATCH($A16,Sheet1!$E$69:$E$150,0),MATCH(Y$1,Sheet1!$E$69:$AJ$69,0)) -> 0.99150766
A17: =_xlfn.TEXTJOIN("",TRUE,B17:C17) -> T2lambda | B17: T2 | C17: lambda | E17: T2 | F17: coefficient | G17: =INDEX(Sheet1!$E$69:$AJ$150,MATCH($A17,Sheet1!$E$69:$E$150,0),MATCH(G$1,Sheet1!$E$69:$AJ$69,0)) -> 0.89157476 | H17: =INDEX(Sheet1!$E$69:$AJ$150,MATCH($A17,Sheet1!$E$69:$E$150,0),MATCH(H$1,Sheet1!$E$69:$AJ$69,0)) -> 0.62994229 | I17: =INDEX(Sheet1!$E$69:$AJ$150,MATCH($A17,Sheet1!$E$69:$E$150,0),MATCH(I$1,Sheet1!$E$69:$AJ$69,0)) -> 0.53909006 | J17: =INDEX(Sheet1!$E$69:$AJ$150,MATCH($A17,Sheet1!$E$69:$E$150,0),MATCH(J$1,Sheet1!$E$69:$AJ$69,0)) -> 0 | L17: =INDEX(Sheet1!$E$69:$AJ$150,MATCH($A17,Sheet1!$E$69:$E$150,0),MATCH(L$1,Sheet1!$E$69:$AJ$69,0)) -> 0.82557911 | M17: =INDEX(Sheet1!$E$69:$AJ$150,MATCH($A17,Sheet1!$E$69:$E$150,0),MATCH(M$1,Sheet1!$E$69:$AJ$69,0)) -> 0.57582279 | N17: =INDEX(Sheet1!$E$69:$AJ$150,MATCH($A17,Sheet1!$E$69:$E$150,0),MATCH(N$1,Sheet1!$E$69:$AJ$69,0)) -> 0.39907758 | O17: =INDEX(Sheet1!$E$69:$AJ$150,MATCH($A17,Sheet1!$E$69:$E$150,0),MATCH(O$1,Sheet1!$E$69:$AJ$69,0)) -> 0 | Q17: =INDEX(Sheet1!$E$69:$AJ$150,MATCH($A17,Sheet1!$E$69:$E$150,0),MATCH(Q$1,Sheet1!$E$69:$AJ$69,0)) -> 0.75958346 | R17: =INDEX(Sheet1!$E$69:$AJ$150,MATCH($A17,Sheet1!$E$69:$E$150,0),MATCH(R$1,Sheet1!$E$69:$AJ$69,0)) -> 0.52170328 | S17: =INDEX(Sheet1!$E$69:$AJ$150,MATCH($A17,Sheet1!$E$69:$E$150,0),MATCH(S$1,Sheet1!$E$69:$AJ$69,0)) -> 0.2590651 | T17: =INDEX(Sheet1!$E$69:$AJ$150,MATCH($A17,Sheet1!$E$69:$E$150,0),MATCH(T$1,Sheet1!$E$69:$AJ$69,0)) -> 0 | V17: =INDEX(Sheet1!$E$69:$AJ$150,MATCH($A17,Sheet1!$E$69:$E$150,0),MATCH(V$1,Sheet1!$E$69:$AJ$69,0)) -> 0.69358781 | W17: =INDEX(Sheet1!$E$69:$AJ$150,MATCH($A17,Sheet1!$E$69:$E$150,0),MATCH(W$1,Sheet1!$E$69:$AJ$69,0)) -> 0.46758378 | X17: =INDEX(Sheet1!$E$69:$AJ$150,MATCH($A17,Sheet1!$E$69:$E$150,0),MATCH(X$1,Sheet1!$E$69:$AJ$69,0)) -> 0.11905261 | Y17: =INDEX(Sheet1!$E$69:$AJ$150,MATCH($A17,Sheet1!$E$69:$E$150,0),MATCH(Y$1,Sheet1!$E$69:$AJ$69,0)) -> 0
A18: =_xlfn.TEXTJOIN("",TRUE,B18:C18) -> T2e^lambda-1 | B18: T2 | C18: e^lambda-1 | F18: Effect | G18: =INDEX(Sheet1!$E$69:$AJ$150,MATCH($A18,Sheet1!$E$69:$E$150,0),MATCH(G$1,Sheet1!$E$69:$AJ$69,0)) -> 1.4389674 | H18: =INDEX(Sheet1!$E$69:$AJ$150,MATCH($A18,Sheet1!$E$69:$E$150,0),MATCH(H$1,Sheet1!$E$69:$AJ$69,0)) -> 0.87750222 | I18: =INDEX(Sheet1!$E$69:$AJ$150,MATCH($A18,Sheet1!$E$69:$E$150,0),MATCH(I$1,Sheet1!$E$69:$AJ$69,0)) -> 0.71444611 | J18: =INDEX(Sheet1!$E$69:$AJ$150,MATCH($A18,Sheet1!$E$69:$E$150,0),MATCH(J$1,Sheet1!$E$69:$AJ$69,0)) -> 0 | L18: =INDEX(Sheet1!$E$69:$AJ$150,MATCH($A18,Sheet1!$E$69:$E$150,0),MATCH(L$1,Sheet1!$E$69:$AJ$69,0)) -> 1.2832026 | M18: =INDEX(Sheet1!$E$69:$AJ$150,MATCH($A18,Sheet1!$E$69:$E$150,0),MATCH(M$1,Sheet1!$E$69:$AJ$69,0)) -> 0.77859333 | N18: =INDEX(Sheet1!$E$69:$AJ$150,MATCH($A18,Sheet1!$E$69:$E$150,0),MATCH(N$1,Sheet1!$E$69:$AJ$69,0)) -> 0.49044924 | O18: =INDEX(Sheet1!$E$69:$AJ$150,MATCH($A18,Sheet1!$E$69:$E$150,0),MATCH(O$1,Sheet1!$E$69:$AJ$69,0)) -> 0 | Q18: =INDEX(Sheet1!$E$69:$AJ$150,MATCH($A18,Sheet1!$E$69:$E$150,0),MATCH(Q$1,Sheet1!$E$69:$AJ$69,0)) -> 1.1373857 | R18: =INDEX(Sheet1!$E$69:$AJ$150,MATCH($A18,Sheet1!$E$69:$E$150,0),MATCH(R$1,Sheet1!$E$69:$AJ$69,0)) -> 0.68489506 | S18: =INDEX(Sheet1!$E$69:$AJ$150,MATCH($A18,Sheet1!$E$69:$E$150,0),MATCH(S$1,Sheet1!$E$69:$AJ$69,0)) -> 0.29571815 | T18: =INDEX(Sheet1!$E$69:$AJ$150,MATCH($A18,Sheet1!$E$69:$E$150,0),MATCH(T$1,Sheet1!$E$69:$AJ$69,0)) -> 0 | V18: =INDEX(Sheet1!$E$69:$AJ$150,MATCH($A18,Sheet1!$E$69:$E$150,0),MATCH(V$1,Sheet1!$E$69:$AJ$69,0)) -> 1.0008815 | W18: =INDEX(Sheet1!$E$69:$AJ$150,MATCH($A18,Sheet1!$E$69:$E$150,0),MATCH(W$1,Sheet1!$E$69:$AJ$69,0)) -> 0.59613292 | X18: =INDEX(Sheet1!$E$69:$AJ$150,MATCH($A18,Sheet1!$E$69:$E$150,0),MATCH(X$1,Sheet1!$E$69:$AJ$69,0)) -> 0.12642918 | Y18: =INDEX(Sheet1!$E$69:$AJ$150,MATCH($A18,Sheet1!$E$69:$E$150,0),MATCH(Y$1,Sheet1!$E$69:$AJ$69,0)) -> 0
A19: =_xlfn.TEXTJOIN("",TRUE,B19:C19) -> T2R | B19: T2 | C19: R | F19: At Risk | G19: =INDEX(Sheet1!$E$69:$AJ$150,MATCH($A19,Sheet1!$E$69:$E$150,0),MATCH(G$1,Sheet1!$E$69:$AJ$69,0)) -> 0.98902029 | H19: =INDEX(Sheet1!$E$69:$AJ$150,MATCH($A19,Sheet1!$E$69:$E$150,0),MATCH(H$1,Sheet1!$E$69:$AJ$69,0)) -> 0.98674705 | I19: =INDEX(Sheet1!$E$69:$AJ$150,MATCH($A19,Sheet1!$E$69:$E$150,0),MATCH(I$1,Sheet1!$E$69:$AJ$69,0)) -> 0.98311992 | J19: =INDEX(Sheet1!$E$69:$AJ$150,MATCH($A19,Sheet1!$E$69:$E$150,0),MATCH(J$1,Sheet1!$E$69:$AJ$69,0)) -> 0.98024931 | L19: =INDEX(Sheet1!$E$69:$AJ$150,MATCH($A19,Sheet1!$E$69:$E$150,0),MATCH(L$1,Sheet1!$E$69:$AJ$69,0)) -> 0.99674204 | M19: =INDEX(Sheet1!$E$69:$AJ$150,MATCH($A19,Sheet1!$E$69:$E$150,0),MATCH(M$1,Sheet1!$E$69:$AJ$69,0)) -> 0.99628718 | N19: =INDEX(Sheet1!$E$69:$AJ$150,MATCH($A19,Sheet1!$E$69:$E$150,0),MATCH(N$1,Sheet1!$E$69:$AJ$69,0)) -> 0.99448481 | O19: =INDEX(Sheet1!$E$69:$AJ$150,MATCH($A19,Sheet1!$E$69:$E$150,0),MATCH(O$1,Sheet1!$E$69:$AJ$69,0)) -> 0.99423076 | Q19: =INDEX(Sheet1!$E$69:$AJ$150,MATCH($A19,Sheet1!$E$69:$E$150,0),MATCH(Q$1,Sheet1!$E$69:$AJ$69,0)) -> 0.99463266 | R19: =INDEX(Sheet1!$E$69:$AJ$150,MATCH($A19,Sheet1!$E$69:$E$150,0),MATCH(R$1,Sheet1!$E$69:$AJ$69,0)) -> 0.99420511 | S19: =INDEX(Sheet1!$E$69:$AJ$150,MATCH($A19,Sheet1!$E$69:$E$150,0),MATCH(S$1,Sheet1!$E$69:$AJ$69,0)) -> 0.98986231 | T19: =INDEX(Sheet1!$E$69:$AJ$150,MATCH($A19,Sheet1!$E$69:$E$150,0),MATCH(T$1,Sheet1!$E$69:$AJ$69,0)) -> 0.99068285 | V19: =INDEX(Sheet1!$E$69:$AJ$150,MATCH($A19,Sheet1!$E$69:$E$150,0),MATCH(V$1,Sheet1!$E$69:$AJ$69,0)) -> 0.99499732 | W19: =INDEX(Sheet1!$E$69:$AJ$150,MATCH($A19,Sheet1!$E$69:$E$150,0),MATCH(W$1,Sheet1!$E$69:$AJ$69,0)) -> 0.99487678 | X19: =INDEX(Sheet1!$E$69:$AJ$150,MATCH($A19,Sheet1!$E$69:$E$150,0),MATCH(X$1,Sheet1!$E$69:$AJ$69,0)) -> 0.98931676 | Y19: =INDEX(Sheet1!$E$69:$AJ$150,MATCH($A19,Sheet1!$E$69:$E$150,0),MATCH(Y$1,Sheet1!$E$69:$AJ$69,0)) -> 0.99150766
A20: =_xlfn.TEXTJOIN("",TRUE,B20:C20) -> T2D | B20: T2 | C20: D | F20: Differenciate | G20: =INDEX(Sheet1!$E$69:$AJ$150,MATCH($A20,Sheet1!$E$69:$E$150,0),MATCH(G$1,Sheet1!$E$69:$AJ$69,0)) -> 0.22770845 | H20: =INDEX(Sheet1!$E$69:$AJ$150,MATCH($A20,Sheet1!$E$69:$E$150,0),MATCH(H$1,Sheet1!$E$69:$AJ$69,0)) -> 0.23144489 | I20: =INDEX(Sheet1!$E$69:$AJ$150,MATCH($A20,Sheet1!$E$69:$E$150,0),MATCH(I$1,Sheet1!$E$69:$AJ$69,0)) -> 0.22738262 | J20: =INDEX(Sheet1!$E$69:$AJ$150,MATCH($A20,Sheet1!$E$69:$E$150,0),MATCH(J$1,Sheet1!$E$69:$AJ$69,0)) -> 0.23739032 | L20: =INDEX(Sheet1!$E$69:$AJ$150,MATCH($A20,Sheet1!$E$69:$E$150,0),MATCH(L$1,Sheet1!$E$69:$AJ$69,0)) -> 0.24517178 | M20: =INDEX(Sheet1!$E$69:$AJ$150,MATCH($A20,Sheet1!$E$69:$E$150,0),MATCH(M$1,Sheet1!$E$69:$AJ$69,0)) -> 0.24627884 | N20: =INDEX(Sheet1!$E$69:$AJ$150,MATCH($A20,Sheet1!$E$69:$E$150,0),MATCH(N$1,Sheet1!$E$69:$AJ$69,0)) -> 0.23928526 | O20: =INDEX(Sheet1!$E$69:$AJ$150,MATCH($A20,Sheet1!$E$69:$E$150,0),MATCH(O$1,Sheet1!$E$69:$AJ$69,0)) -> 0.24241545 | Q20: =INDEX(Sheet1!$E$69:$AJ$150,MATCH($A20,Sheet1!$E$69:$E$150,0),MATCH(Q$1,Sheet1!$E$69:$AJ$69,0)) -> 0.27571327 | R20: =INDEX(Sheet1!$E$69:$AJ$150,MATCH($A20,Sheet1!$E$69:$E$150,0),MATCH(R$1,Sheet1!$E$69:$AJ$69,0)) -> 0.27136108 | S20: =INDEX(Sheet1!$E$69:$AJ$150,MATCH($A20,Sheet1!$E$69:$E$150,0),MATCH(S$1,Sheet1!$E$69:$AJ$69,0)) -> 0.25619576 | T20: =INDEX(Sheet1!$E$69:$AJ$150,MATCH($A20,Sheet1!$E$69:$E$150,0),MATCH(T$1,Sheet1!$E$69:$AJ$69,0)) -> 0.24464648 | V20: =INDEX(Sheet1!$E$69:$AJ$150,MATCH($A20,Sheet1!$E$69:$E$150,0),MATCH(V$1,Sheet1!$E$69:$AJ$69,0)) -> 0.27213754 | W20: =INDEX(Sheet1!$E$69:$AJ$150,MATCH($A20,Sheet1!$E$69:$E$150,0),MATCH(W$1,Sheet1!$E$69:$AJ$69,0)) -> 0.26607198 | X20: =INDEX(Sheet1!$E$69:$AJ$150,MATCH($A20,Sheet1!$E$69:$E$150,0),MATCH(X$1,Sheet1!$E$69:$AJ$69,0)) -> 0.24835805 | Y20: =INDEX(Sheet1!$E$69:$AJ$150,MATCH($A20,Sheet1!$E$69:$E$150,0),MATCH(Y$1,Sheet1!$E$69:$AJ$69,0)) -> 0.23122184
A21: =_xlfn.TEXTJOIN("",TRUE,B21:C21) -> T2G | B21: T2 | C21: G | F21: Gain | G21: =INDEX(Sheet1!$E$69:$AJ$150,MATCH($A21,Sheet1!$E$69:$E$150,0),MATCH(G$1,Sheet1!$E$69:$AJ$69,0)) -> -0.88673238 | H21: =INDEX(Sheet1!$E$69:$AJ$150,MATCH($A21,Sheet1!$E$69:$E$150,0),MATCH(H$1,Sheet1!$E$69:$AJ$69,0)) -> -0.61038559 | I21: =INDEX(Sheet1!$E$69:$AJ$150,MATCH($A21,Sheet1!$E$69:$E$150,0),MATCH(I$1,Sheet1!$E$69:$AJ$69,0)) -> -0.41076866 | J21: =INDEX(Sheet1!$E$69:$AJ$150,MATCH($A21,Sheet1!$E$69:$E$150,0),MATCH(J$1,Sheet1!$E$69:$AJ$69,0)) -> 0.4468811 | L21: =INDEX(Sheet1!$E$69:$AJ$150,MATCH($A21,Sheet1!$E$69:$E$150,0),MATCH(L$1,Sheet1!$E$69:$AJ$69,0)) -> -0.98003092 | M21: =INDEX(Sheet1!$E$69:$AJ$150,MATCH($A21,Sheet1!$E$69:$E$150,0),MATCH(M$1,Sheet1!$E$69:$AJ$69,0)) -> -0.70514134 | N21: =INDEX(Sheet1!$E$69:$AJ$150,MATCH($A21,Sheet1!$E$69:$E$150,0),MATCH(N$1,Sheet1!$E$69:$AJ$69,0)) -> -0.34290154 | O21: =INDEX(Sheet1!$E$69:$AJ$150,MATCH($A21,Sheet1!$E$69:$E$150,0),MATCH(O$1,Sheet1!$E$69:$AJ$69,0)) -> 0.39397756 | Q21: =INDEX(Sheet1!$E$69:$AJ$150,MATCH($A21,Sheet1!$E$69:$E$150,0),MATCH(Q$1,Sheet1!$E$69:$AJ$69,0)) -> -1.3425091 | R21: =INDEX(Sheet1!$E$69:$AJ$150,MATCH($A21,Sheet1!$E$69:$E$150,0),MATCH(R$1,Sheet1!$E$69:$AJ$69,0)) -> -1.1281521 | S21: =INDEX(Sheet1!$E$69:$AJ$150,MATCH($A21,Sheet1!$E$69:$E$150,0),MATCH(S$1,Sheet1!$E$69:$AJ$69,0)) -> -0.68204464 | T21: =INDEX(Sheet1!$E$69:$AJ$150,MATCH($A21,Sheet1!$E$69:$E$150,0),MATCH(T$1,Sheet1!$E$69:$AJ$69,0)) -> -0.090644735 | V21: =INDEX(Sheet1!$E$69:$AJ$150,MATCH($A21,Sheet1!$E$69:$E$150,0),MATCH(V$1,Sheet1!$E$69:$AJ$69,0)) -> -1.5452161 | W21: =INDEX(Sheet1!$E$69:$AJ$150,MATCH($A21,Sheet1!$E$69:$E$150,0),MATCH(W$1,Sheet1!$E$69:$AJ$69,0)) -> -1.3779553 | X21: =INDEX(Sheet1!$E$69:$AJ$150,MATCH($A21,Sheet1!$E$69:$E$150,0),MATCH(X$1,Sheet1!$E$69:$AJ$69,0)) -> -0.8830725 | Y21: =INDEX(Sheet1!$E$69:$AJ$150,MATCH($A21,Sheet1!$E$69:$E$150,0),MATCH(Y$1,Sheet1!$E$69:$AJ$69,0)) -> -0.44655949
A22: =_xlfn.TEXTJOIN("",TRUE,B22:C22) -> T2Weight | B22: T2 | C22: Weight | F22: Weight | G22: =INDEX(Sheet1!$E$69:$AJ$150,MATCH($A22,Sheet1!$E$69:$E$150,0),MATCH(G$1,Sheet1!$E$69:$AJ$69,0)) -> -0.19969947 | H22: =INDEX(Sheet1!$E$69:$AJ$150,MATCH($A22,Sheet1!$E$69:$E$150,0),MATCH(H$1,Sheet1!$E$69:$AJ$69,0)) -> -0.13939837 | I22: =INDEX(Sheet1!$E$69:$AJ$150,MATCH($A22,Sheet1!$E$69:$E$150,0),MATCH(I$1,Sheet1!$E$69:$AJ$69,0)) -> -0.091825028 | J22: =INDEX(Sheet1!$E$69:$AJ$150,MATCH($A22,Sheet1!$E$69:$E$150,0),MATCH(J$1,Sheet1!$E$69:$AJ$69,0)) -> 0.10398999 | L22: =INDEX(Sheet1!$E$69:$AJ$150,MATCH($A22,Sheet1!$E$69:$E$150,0),MATCH(L$1,Sheet1!$E$69:$AJ$69,0)) -> -0.23949312 | M22: =INDEX(Sheet1!$E$69:$AJ$150,MATCH($A22,Sheet1!$E$69:$E$150,0),MATCH(M$1,Sheet1!$E$69:$AJ$69,0)) -> -0.17301662 | N22: =INDEX(Sheet1!$E$69:$AJ$150,MATCH($A22,Sheet1!$E$69:$E$150,0),MATCH(N$1,Sheet1!$E$69:$AJ$69,0)) -> -0.081598756 | O22: =INDEX(Sheet1!$E$69:$AJ$150,MATCH($A22,Sheet1!$E$69:$E$150,0),MATCH(O$1,Sheet1!$E$69:$AJ$69,0)) -> 0.09495525 | Q22: =INDEX(Sheet1!$E$69:$AJ$150,MATCH($A22,Sheet1!$E$69:$E$150,0),MATCH(Q$1,Sheet1!$E$69:$AJ$69,0)) -> -0.36816087 | R22: =INDEX(Sheet1!$E$69:$AJ$150,MATCH($A22,Sheet1!$E$69:$E$150,0),MATCH(R$1,Sheet1!$E$69:$AJ$69,0)) -> -0.30436253 | S22: =INDEX(Sheet1!$E$69:$AJ$150,MATCH($A22,Sheet1!$E$69:$E$150,0),MATCH(S$1,Sheet1!$E$69:$AJ$69,0)) -> -0.17296552 | T22: =INDEX(Sheet1!$E$69:$AJ$150,MATCH($A22,Sheet1!$E$69:$E$150,0),MATCH(T$1,Sheet1!$E$69:$AJ$69,0)) -> -0.021969299 | V22: =INDEX(Sheet1!$E$69:$AJ$150,MATCH($A22,Sheet1!$E$69:$E$150,0),MATCH(V$1,Sheet1!$E$69:$AJ$69,0)) -> -0.41840764 | W22: =INDEX(Sheet1!$E$69:$AJ$150,MATCH($A22,Sheet1!$E$69:$E$150,0),MATCH(W$1,Sheet1!$E$69:$AJ$69,0)) -> -0.36475694 | X22: =INDEX(Sheet1!$E$69:$AJ$150,MATCH($A22,Sheet1!$E$69:$E$150,0),MATCH(X$1,Sheet1!$E$69:$AJ$69,0)) -> -0.21697514 | Y22: =INDEX(Sheet1!$E$69:$AJ$150,MATCH($A22,Sheet1!$E$69:$E$150,0),MATCH(Y$1,Sheet1!$E$69:$AJ$69,0)) -> -0.10237744
A23: =_xlfn.TEXTJOIN("",TRUE,B23:C23) -> T2p | B23: T2 | C23: p | F23: p | G23: =INDEX(Sheet1!$E$69:$AJ$150,MATCH($A23,Sheet1!$E$69:$E$150,0),MATCH(G$1,Sheet1!$E$69:$AJ$69,0)) -> 0.4126793 | H23: =INDEX(Sheet1!$E$69:$AJ$150,MATCH($A23,Sheet1!$E$69:$E$150,0),MATCH(H$1,Sheet1!$E$69:$AJ$69,0)) -> 0.40304202 | I23: =INDEX(Sheet1!$E$69:$AJ$150,MATCH($A23,Sheet1!$E$69:$E$150,0),MATCH(I$1,Sheet1!$E$69:$AJ$69,0)) -> 0.41351969 | J23: =INDEX(Sheet1!$E$69:$AJ$150,MATCH($A23,Sheet1!$E$69:$E$150,0),MATCH(J$1,Sheet1!$E$69:$AJ$69,0)) -> 0.38770717 | L23: =INDEX(Sheet1!$E$69:$AJ$150,MATCH($A23,Sheet1!$E$69:$E$150,0),MATCH(L$1,Sheet1!$E$69:$AJ$69,0)) -> 0.40623531 | M23: =INDEX(Sheet1!$E$69:$AJ$150,MATCH($A23,Sheet1!$E$69:$E$150,0),MATCH(M$1,Sheet1!$E$69:$AJ$69,0)) -> 0.40355419 | N23: =INDEX(Sheet1!$E$69:$AJ$150,MATCH($A23,Sheet1!$E$69:$E$150,0),MATCH(N$1,Sheet1!$E$69:$AJ$69,0)) -> 0.42049147 | O23: =INDEX(Sheet1!$E$69:$AJ$150,MATCH($A23,Sheet1!$E$69:$E$150,0),MATCH(O$1,Sheet1!$E$69:$AJ$69,0)) -> 0.41291068 | Q23: =INDEX(Sheet1!$E$69:$AJ$150,MATCH($A23,Sheet1!$E$69:$E$150,0),MATCH(Q$1,Sheet1!$E$69:$AJ$69,0)) -> 0.35404776 | R23: =INDEX(Sheet1!$E$69:$AJ$150,MATCH($A23,Sheet1!$E$69:$E$150,0),MATCH(R$1,Sheet1!$E$69:$AJ$69,0)) -> 0.36424424 | S23: =INDEX(Sheet1!$E$69:$AJ$150,MATCH($A23,Sheet1!$E$69:$E$150,0),MATCH(S$1,Sheet1!$E$69:$AJ$69,0)) -> 0.39977416 | T23: =INDEX(Sheet1!$E$69:$AJ$150,MATCH($A23,Sheet1!$E$69:$E$150,0),MATCH(T$1,Sheet1!$E$69:$AJ$69,0)) -> 0.42683228 | V23: =INDEX(Sheet1!$E$69:$AJ$150,MATCH($A23,Sheet1!$E$69:$E$150,0),MATCH(V$1,Sheet1!$E$69:$AJ$69,0)) -> 0.25024076 | W23: =INDEX(Sheet1!$E$69:$AJ$150,MATCH($A23,Sheet1!$E$69:$E$150,0),MATCH(W$1,Sheet1!$E$69:$AJ$69,0)) -> 0.26695185 | X23: =INDEX(Sheet1!$E$69:$AJ$150,MATCH($A23,Sheet1!$E$69:$E$150,0),MATCH(X$1,Sheet1!$E$69:$AJ$69,0)) -> 0.31575503 | Y23: =INDEX(Sheet1!$E$69:$AJ$150,MATCH($A23,Sheet1!$E$69:$E$150,0),MATCH(Y$1,Sheet1!$E$69:$AJ$69,0)) -> 0.36296657
A24: =_xlfn.TEXTJOIN("",TRUE,B24:C24) -> T3lambda | B24: T3 | C24: lambda | E24: T3 | F24: coefficient | G24: =INDEX(Sheet1!$E$69:$AJ$150,MATCH($A24,Sheet1!$E$69:$E$150,0),MATCH(G$1,Sheet1!$E$69:$AJ$69,0)) -> 1.4073748 | H24: =INDEX(Sheet1!$E$69:$AJ$150,MATCH($A24,Sheet1!$E$69:$E$150,0),MATCH(H$1,Sheet1!$E$69:$AJ$69,0)) -> 1.0850207 | I24: =INDEX(Sheet1!$E$69:$AJ$150,MATCH($A24,Sheet1!$E$69:$E$150,0),MATCH(I$1,Sheet1!$E$69:$AJ$69,0)) -> 0.87124427 | J24: =INDEX(Sheet1!$E$69:$AJ$150,MATCH($A24,Sheet1!$E$69:$E$150,0),MATCH(J$1,Sheet1!$E$69:$AJ$69,0)) -> 0 | L24: =INDEX(Sheet1!$E$69:$AJ$150,MATCH($A24,Sheet1!$E$69:$E$150,0),MATCH(L$1,Sheet1!$E$69:$AJ$69,0)) -> 1.471357 | M24: =INDEX(Sheet1!$E$69:$AJ$150,MATCH($A24,Sheet1!$E$69:$E$150,0),MATCH(M$1,Sheet1!$E$69:$AJ$69,0)) -> 1.1359483 | N24: =INDEX(Sheet1!$E$69:$AJ$150,MATCH($A24,Sheet1!$E$69:$E$150,0),MATCH(N$1,Sheet1!$E$69:$AJ$69,0)) -> 0.74551763 | O24: =INDEX(Sheet1!$E$69:$AJ$150,MATCH($A24,Sheet1!$E$69:$E$150,0),MATCH(O$1,Sheet1!$E$69:$AJ$69,0)) -> 0 | Q24: =INDEX(Sheet1!$E$69:$AJ$150,MATCH($A24,Sheet1!$E$69:$E$150,0),MATCH(Q$1,Sheet1!$E$69:$AJ$69,0)) -> 1.5353392 | R24: =INDEX(Sheet1!$E$69:$AJ$150,MATCH($A24,Sheet1!$E$69:$E$150,0),MATCH(R$1,Sheet1!$E$69:$AJ$69,0)) -> 1.1868758 | S24: =INDEX(Sheet1!$E$69:$AJ$150,MATCH($A24,Sheet1!$E$69:$E$150,0),MATCH(S$1,Sheet1!$E$69:$AJ$69,0)) -> 0.61979099 | T24: =INDEX(Sheet1!$E$69:$AJ$150,MATCH($A24,Sheet1!$E$69:$E$150,0),MATCH(T$1,Sheet1!$E$69:$AJ$69,0)) -> 0 | V24: =INDEX(Sheet1!$E$69:$AJ$150,MATCH($A24,Sheet1!$E$69:$E$150,0),MATCH(V$1,Sheet1!$E$69:$AJ$69,0)) -> 1.5993215 | W24: =INDEX(Sheet1!$E$69:$AJ$150,MATCH($A24,Sheet1!$E$69:$E$150,0),MATCH(W$1,Sheet1!$E$69:$AJ$69,0)) -> 1.2378033 | X24: =INDEX(Sheet1!$E$69:$AJ$150,MATCH($A24,Sheet1!$E$69:$E$150,0),MATCH(X$1,Sheet1!$E$69:$AJ$69,0)) -> 0.49406435 | Y24: =INDEX(Sheet1!$E$69:$AJ$150,MATCH($A24,Sheet1!$E$69:$E$150,0),MATCH(Y$1,Sheet1!$E$69:$AJ$69,0)) -> 0
A25: =_xlfn.TEXTJOIN("",TRUE,B25:C25) -> T3e^lambda-1 | B25: T3 | C25: e^lambda-1 | F25: Effect | G25: =INDEX(Sheet1!$E$69:$AJ$150,MATCH($A25,Sheet1!$E$69:$E$150,0),MATCH(G$1,Sheet1!$E$69:$AJ$69,0)) -> 3.0852168 | H25: =INDEX(Sheet1!$E$69:$AJ$150,MATCH($A25,Sheet1!$E$69:$E$150,0),MATCH(H$1,Sheet1!$E$69:$AJ$69,0)) -> 1.9595012 | I25: =INDEX(Sheet1!$E$69:$AJ$150,MATCH($A25,Sheet1!$E$69:$E$150,0),MATCH(I$1,Sheet1!$E$69:$AJ$69,0)) -> 1.3898827 | J25: =INDEX(Sheet1!$E$69:$AJ$150,MATCH($A25,Sheet1!$E$69:$E$150,0),MATCH(J$1,Sheet1!$E$69:$AJ$69,0)) -> 0 | L25: =INDEX(Sheet1!$E$69:$AJ$150,MATCH($A25,Sheet1!$E$69:$E$150,0),MATCH(L$1,Sheet1!$E$69:$AJ$69,0)) -> 3.3551411 | M25: =INDEX(Sheet1!$E$69:$AJ$150,MATCH($A25,Sheet1!$E$69:$E$150,0),MATCH(M$1,Sheet1!$E$69:$AJ$69,0)) -> 2.1141252 | N25: =INDEX(Sheet1!$E$69:$AJ$150,MATCH($A25,Sheet1!$E$69:$E$150,0),MATCH(N$1,Sheet1!$E$69:$AJ$69,0)) -> 1.1075321 | O25: =INDEX(Sheet1!$E$69:$AJ$150,MATCH($A25,Sheet1!$E$69:$E$150,0),MATCH(O$1,Sheet1!$E$69:$AJ$69,0)) -> 0 | Q25: =INDEX(Sheet1!$E$69:$AJ$150,MATCH($A25,Sheet1!$E$69:$E$150,0),MATCH(Q$1,Sheet1!$E$69:$AJ$69,0)) -> 3.6429003 | R25: =INDEX(Sheet1!$E$69:$AJ$150,MATCH($A25,Sheet1!$E$69:$E$150,0),MATCH(R$1,Sheet1!$E$69:$AJ$69,0)) -> 2.2768277 | S25: =INDEX(Sheet1!$E$69:$AJ$150,MATCH($A25,Sheet1!$E$69:$E$150,0),MATCH(S$1,Sheet1!$E$69:$AJ$69,0)) -> 0.85853955 | T25: =INDEX(Sheet1!$E$69:$AJ$150,MATCH($A25,Sheet1!$E$69:$E$150,0),MATCH(T$1,Sheet1!$E$69:$AJ$69,0)) -> 0 | V25: =INDEX(Sheet1!$E$69:$AJ$150,MATCH($A25,Sheet1!$E$69:$E$150,0),MATCH(V$1,Sheet1!$E$69:$AJ$69,0)) -> 3.9496728 | W25: =INDEX(Sheet1!$E$69:$AJ$150,MATCH($A25,Sheet1!$E$69:$E$150,0),MATCH(W$1,Sheet1!$E$69:$AJ$69,0)) -> 2.4480309 | X25: =INDEX(Sheet1!$E$69:$AJ$150,MATCH($A25,Sheet1!$E$69:$E$150,0),MATCH(X$1,Sheet1!$E$69:$AJ$69,0)) -> 0.63896403 | Y25: =INDEX(Sheet1!$E$69:$AJ$150,MATCH($A25,Sheet1!$E$69:$E$150,0),MATCH(Y$1,Sheet1!$E$69:$AJ$69,0)) -> 0
A26: =_xlfn.TEXTJOIN("",TRUE,B26:C26) -> T3R | B26: T3 | C26: R | F26: At Risk | G26: =INDEX(Sheet1!$E$69:$AJ$150,MATCH($A26,Sheet1!$E$69:$E$150,0),MATCH(G$1,Sheet1!$E$69:$AJ$69,0)) -> 0.98902029 | H26: =INDEX(Sheet1!$E$69:$AJ$150,MATCH($A26,Sheet1!$E$69:$E$150,0),MATCH(H$1,Sheet1!$E$69:$AJ$69,0)) -> 0.98674705 | I26: =INDEX(Sheet1!$E$69:$AJ$150,MATCH($A26,Sheet1!$E$69:$E$150,0),MATCH(I$1,Sheet1!$E$69:$AJ$69,0)) -> 0.98311992 | J26: =INDEX(Sheet1!$E$69:$AJ$150,MATCH($A26,Sheet1!$E$69:$E$150,0),MATCH(J$1,Sheet1!$E$69:$AJ$69,0)) -> 0.98024931 | L26: =INDEX(Sheet1!$E$69:$AJ$150,MATCH($A26,Sheet1!$E$69:$E$150,0),MATCH(L$1,Sheet1!$E$69:$AJ$69,0)) -> 0.99674204 | M26: =INDEX(Sheet1!$E$69:$AJ$150,MATCH($A26,Sheet1!$E$69:$E$150,0),MATCH(M$1,Sheet1!$E$69:$AJ$69,0)) -> 0.99628718 | N26: =INDEX(Sheet1!$E$69:$AJ$150,MATCH($A26,Sheet1!$E$69:$E$150,0),MATCH(N$1,Sheet1!$E$69:$AJ$69,0)) -> 0.99448481 | O26: =INDEX(Sheet1!$E$69:$AJ$150,MATCH($A26,Sheet1!$E$69:$E$150,0),MATCH(O$1,Sheet1!$E$69:$AJ$69,0)) -> 0.99423076 | Q26: =INDEX(Sheet1!$E$69:$AJ$150,MATCH($A26,Sheet1!$E$69:$E$150,0),MATCH(Q$1,Sheet1!$E$69:$AJ$69,0)) -> 0.99463266 | R26: =INDEX(Sheet1!$E$69:$AJ$150,MATCH($A26,Sheet1!$E$69:$E$150,0),MATCH(R$1,Sheet1!$E$69:$AJ$69,0)) -> 0.99420511 | S26: =INDEX(Sheet1!$E$69:$AJ$150,MATCH($A26,Sheet1!$E$69:$E$150,0),MATCH(S$1,Sheet1!$E$69:$AJ$69,0)) -> 0.98986231 | T26: =INDEX(Sheet1!$E$69:$AJ$150,MATCH($A26,Sheet1!$E$69:$E$150,0),MATCH(T$1,Sheet1!$E$69:$AJ$69,0)) -> 0.99068285 | V26: =INDEX(Sheet1!$E$69:$AJ$150,MATCH($A26,Sheet1!$E$69:$E$150,0),MATCH(V$1,Sheet1!$E$69:$AJ$69,0)) -> 0.99499732 | W26: =INDEX(Sheet1!$E$69:$AJ$150,MATCH($A26,Sheet1!$E$69:$E$150,0),MATCH(W$1,Sheet1!$E$69:$AJ$69,0)) -> 0.99487678 | X26: =INDEX(Sheet1!$E$69:$AJ$150,MATCH($A26,Sheet1!$E$69:$E$150,0),MATCH(X$1,Sheet1!$E$69:$AJ$69,0)) -> 0.98931676 | Y26: =INDEX(Sheet1!$E$69:$AJ$150,MATCH($A26,Sheet1!$E$69:$E$150,0),MATCH(Y$1,Sheet1!$E$69:$AJ$69,0)) -> 0.99150766
A27: =_xlfn.TEXTJOIN("",TRUE,B27:C27) -> T3D | B27: T3 | C27: D | F27: Differenciate | G27: =INDEX(Sheet1!$E$69:$AJ$150,MATCH($A27,Sheet1!$E$69:$E$150,0),MATCH(G$1,Sheet1!$E$69:$AJ$69,0)) -> 0.13697217 | H27: =INDEX(Sheet1!$E$69:$AJ$150,MATCH($A27,Sheet1!$E$69:$E$150,0),MATCH(H$1,Sheet1!$E$69:$AJ$69,0)) -> 0.14512355 | I27: =INDEX(Sheet1!$E$69:$AJ$150,MATCH($A27,Sheet1!$E$69:$E$150,0),MATCH(I$1,Sheet1!$E$69:$AJ$69,0)) -> 0.15370731 | J27: =INDEX(Sheet1!$E$69:$AJ$150,MATCH($A27,Sheet1!$E$69:$E$150,0),MATCH(J$1,Sheet1!$E$69:$AJ$69,0)) -> 0.18122016 | L27: =INDEX(Sheet1!$E$69:$AJ$150,MATCH($A27,Sheet1!$E$69:$E$150,0),MATCH(L$1,Sheet1!$E$69:$AJ$69,0)) -> 0.13144688 | M27: =INDEX(Sheet1!$E$69:$AJ$150,MATCH($A27,Sheet1!$E$69:$E$150,0),MATCH(M$1,Sheet1!$E$69:$AJ$69,0)) -> 0.140638 | N27: =INDEX(Sheet1!$E$69:$AJ$150,MATCH($A27,Sheet1!$E$69:$E$150,0),MATCH(N$1,Sheet1!$E$69:$AJ$69,0)) -> 0.15570866 | O27: =INDEX(Sheet1!$E$69:$AJ$150,MATCH($A27,Sheet1!$E$69:$E$150,0),MATCH(O$1,Sheet1!$E$69:$AJ$69,0)) -> 0.1801559 | Q27: =INDEX(Sheet1!$E$69:$AJ$150,MATCH($A27,Sheet1!$E$69:$E$150,0),MATCH(Q$1,Sheet1!$E$69:$AJ$69,0)) -> 0.13787067 | R27: =INDEX(Sheet1!$E$69:$AJ$150,MATCH($A27,Sheet1!$E$69:$E$150,0),MATCH(R$1,Sheet1!$E$69:$AJ$69,0)) -> 0.15062951 | S27: =INDEX(Sheet1!$E$69:$AJ$150,MATCH($A27,Sheet1!$E$69:$E$150,0),MATCH(S$1,Sheet1!$E$69:$AJ$69,0)) -> 0.17900712 | T27: =INDEX(Sheet1!$E$69:$AJ$150,MATCH($A27,Sheet1!$E$69:$E$150,0),MATCH(T$1,Sheet1!$E$69:$AJ$69,0)) -> 0.20982883 | V27: =INDEX(Sheet1!$E$69:$AJ$150,MATCH($A27,Sheet1!$E$69:$E$150,0),MATCH(V$1,Sheet1!$E$69:$AJ$69,0)) -> 0.13071685 | W27: =INDEX(Sheet1!$E$69:$AJ$150,MATCH($A27,Sheet1!$E$69:$E$150,0),MATCH(W$1,Sheet1!$E$69:$AJ$69,0)) -> 0.14843109 | X27: =INDEX(Sheet1!$E$69:$AJ$150,MATCH($A27,Sheet1!$E$69:$E$150,0),MATCH(X$1,Sheet1!$E$69:$AJ$69,0)) -> 0.19747407 | Y27: =INDEX(Sheet1!$E$69:$AJ$150,MATCH($A27,Sheet1!$E$69:$E$150,0),MATCH(Y$1,Sheet1!$E$69:$AJ$69,0)) -> 0.23781958
A28: =_xlfn.TEXTJOIN("",TRUE,B28:C28) -> T3G | B28: T3 | C28: G | F28: Gain | G28: =INDEX(Sheet1!$E$69:$AJ$150,MATCH($A28,Sheet1!$E$69:$E$150,0),MATCH(G$1,Sheet1!$E$69:$AJ$69,0)) -> 2.5674354 | H28: =INDEX(Sheet1!$E$69:$AJ$150,MATCH($A28,Sheet1!$E$69:$E$150,0),MATCH(H$1,Sheet1!$E$69:$AJ$69,0)) -> 2.6794759 | I28: =INDEX(Sheet1!$E$69:$AJ$150,MATCH($A28,Sheet1!$E$69:$E$150,0),MATCH(I$1,Sheet1!$E$69:$AJ$69,0)) -> 2.7208085 | J28: =INDEX(Sheet1!$E$69:$AJ$150,MATCH($A28,Sheet1!$E$69:$E$150,0),MATCH(J$1,Sheet1!$E$69:$AJ$69,0)) -> 2.9827418 | L28: =INDEX(Sheet1!$E$69:$AJ$150,MATCH($A28,Sheet1!$E$69:$E$150,0),MATCH(L$1,Sheet1!$E$69:$AJ$69,0)) -> 2.5430213 | M28: =INDEX(Sheet1!$E$69:$AJ$150,MATCH($A28,Sheet1!$E$69:$E$150,0),MATCH(M$1,Sheet1!$E$69:$AJ$69,0)) -> 2.6472268 | N28: =INDEX(Sheet1!$E$69:$AJ$150,MATCH($A28,Sheet1!$E$69:$E$150,0),MATCH(N$1,Sheet1!$E$69:$AJ$69,0)) -> 2.7268774 | O28: =INDEX(Sheet1!$E$69:$AJ$150,MATCH($A28,Sheet1!$E$69:$E$150,0),MATCH(O$1,Sheet1!$E$69:$AJ$69,0)) -> 2.9194785 | Q28: =INDEX(Sheet1!$E$69:$AJ$150,MATCH($A28,Sheet1!$E$69:$E$150,0),MATCH(Q$1,Sheet1!$E$69:$AJ$69,0)) -> 2.4614134 | R28: =INDEX(Sheet1!$E$69:$AJ$150,MATCH($A28,Sheet1!$E$69:$E$150,0),MATCH(R$1,Sheet1!$E$69:$AJ$69,0)) -> 2.5511794 | S28: =INDEX(Sheet1!$E$69:$AJ$150,MATCH($A28,Sheet1!$E$69:$E$150,0),MATCH(S$1,Sheet1!$E$69:$AJ$69,0)) -> 2.6619376 | T28: =INDEX(Sheet1!$E$69:$AJ$150,MATCH($A28,Sheet1!$E$69:$E$150,0),MATCH(T$1,Sheet1!$E$69:$AJ$69,0)) -> 2.7812235 | V28: =INDEX(Sheet1!$E$69:$AJ$150,MATCH($A28,Sheet1!$E$69:$E$150,0),MATCH(V$1,Sheet1!$E$69:$AJ$69,0)) -> 2.5081867 | W28: =INDEX(Sheet1!$E$69:$AJ$150,MATCH($A28,Sheet1!$E$69:$E$150,0),MATCH(W$1,Sheet1!$E$69:$AJ$69,0)) -> 2.5984905 | X28: =INDEX(Sheet1!$E$69:$AJ$150,MATCH($A28,Sheet1!$E$69:$E$150,0),MATCH(X$1,Sheet1!$E$69:$AJ$69,0)) -> 2.7539708 | Y28: =INDEX(Sheet1!$E$69:$AJ$150,MATCH($A28,Sheet1!$E$69:$E$150,0),MATCH(Y$1,Sheet1!$E$69:$AJ$69,0)) -> 2.8106572
A29: =_xlfn.TEXTJOIN("",TRUE,B29:C29) -> T3Weight | B29: T3 | C29: Weight | F29: Weight | G29: =INDEX(Sheet1!$E$69:$AJ$150,MATCH($A29,Sheet1!$E$69:$E$150,0),MATCH(G$1,Sheet1!$E$69:$AJ$69,0)) -> 0.347806 | H29: =INDEX(Sheet1!$E$69:$AJ$150,MATCH($A29,Sheet1!$E$69:$E$150,0),MATCH(H$1,Sheet1!$E$69:$AJ$69,0)) -> 0.38370158 | I29: =INDEX(Sheet1!$E$69:$AJ$150,MATCH($A29,Sheet1!$E$69:$E$150,0),MATCH(I$1,Sheet1!$E$69:$AJ$69,0)) -> 0.41114877 | J29: =INDEX(Sheet1!$E$69:$AJ$150,MATCH($A29,Sheet1!$E$69:$E$150,0),MATCH(J$1,Sheet1!$E$69:$AJ$69,0)) -> 0.52985704 | L29: =INDEX(Sheet1!$E$69:$AJ$150,MATCH($A29,Sheet1!$E$69:$E$150,0),MATCH(L$1,Sheet1!$E$69:$AJ$69,0)) -> 0.33318317 | M29: =INDEX(Sheet1!$E$69:$AJ$150,MATCH($A29,Sheet1!$E$69:$E$150,0),MATCH(M$1,Sheet1!$E$69:$AJ$69,0)) -> 0.37091839 | N29: =INDEX(Sheet1!$E$69:$AJ$150,MATCH($A29,Sheet1!$E$69:$E$150,0),MATCH(N$1,Sheet1!$E$69:$AJ$69,0)) -> 0.42225669 | O29: =INDEX(Sheet1!$E$69:$AJ$150,MATCH($A29,Sheet1!$E$69:$E$150,0),MATCH(O$1,Sheet1!$E$69:$AJ$69,0)) -> 0.52292688 | Q29: =INDEX(Sheet1!$E$69:$AJ$150,MATCH($A29,Sheet1!$E$69:$E$150,0),MATCH(Q$1,Sheet1!$E$69:$AJ$69,0)) -> 0.33753528 | R29: =INDEX(Sheet1!$E$69:$AJ$150,MATCH($A29,Sheet1!$E$69:$E$150,0),MATCH(R$1,Sheet1!$E$69:$AJ$69,0)) -> 0.38205601 | S29: =INDEX(Sheet1!$E$69:$AJ$150,MATCH($A29,Sheet1!$E$69:$E$150,0),MATCH(S$1,Sheet1!$E$69:$AJ$69,0)) -> 0.47167513 | T29: =INDEX(Sheet1!$E$69:$AJ$150,MATCH($A29,Sheet1!$E$69:$E$150,0),MATCH(T$1,Sheet1!$E$69:$AJ$69,0)) -> 0.57814355 | V29: =INDEX(Sheet1!$E$69:$AJ$150,MATCH($A29,Sheet1!$E$69:$E$150,0),MATCH(V$1,Sheet1!$E$69:$AJ$69,0)) -> 0.32622209 | W29: =INDEX(Sheet1!$E$69:$AJ$150,MATCH($A29,Sheet1!$E$69:$E$150,0),MATCH(W$1,Sheet1!$E$69:$AJ$69,0)) -> 0.38372076 | X29: =INDEX(Sheet1!$E$69:$AJ$150,MATCH($A29,Sheet1!$E$69:$E$150,0),MATCH(X$1,Sheet1!$E$69:$AJ$69,0)) -> 0.53802787 | Y29: =INDEX(Sheet1!$E$69:$AJ$150,MATCH($A29,Sheet1!$E$69:$E$150,0),MATCH(Y$1,Sheet1!$E$69:$AJ$69,0)) -> 0.66275278
